<!-- seed: 1715067726 -->
<sdf version='1.11'>
  <world name='world_0'>
    <gravity>0 0 -9.8066499999999994</gravity>
    <magnetic_field>5.5644999999999998e-06 2.2875799999999999e-05 -4.2388400000000002e-05</magnetic_field>
    <wind>
      <linear_velocity>6 9 6</linear_velocity>
    </wind>
    <physics default='false' type='ode'>
      <max_step_size>0.001</max_step_size>
      <real_time_factor>1</real_time_factor>
      <max_contacts>20</max_contacts>
    </physics>
    <model name='model_0'>
      <static>false</static>
      <self_collide>false</self_collide>
      <allow_auto_disable>true</allow_auto_disable>
      <enable_wind>true</enable_wind>
      <pose>-0.85421336598814968 5.3050545212617983 2.4990793843396664 0 0 0</pose>
      <link name='link_2508'>
        <pose>-3.0704216833967806 7.4078099744333308 6.4295280410307312 0 0 0</pose>
        <inertial>
          <pose>0 0 0 0 0 0</pose>
          <mass>1</mass>
          <inertia>
            <ixx>1</ixx>
            <ixy>0</ixy>
            <ixz>0</ixz>
            <iyy>1</iyy>
            <iyz>0</iyz>
            <izz>1</izz>
          </inertia>
        </inertial>
        <enable_wind>false</enable_wind>
        <collision name='collision_2508'>
          <pose>0 0 0 0 0 0</pose>
          <geometry>
            <sphere>
              <radius>2.1439304567141244</radius>
            </sphere>
          </geometry>
          <surface>
            <contact>
              <collide_bitmask>255</collide_bitmask>
            </contact>
            <friction>
              <ode>
                <mu>1</mu>
                <mu2>1</mu2>
                <slip1>0</slip1>
                <slip2>0</slip2>
                <fdir1>0 0 0</fdir1>
              </ode>
            </friction>
          </surface>
        </collision>
        <visual name='visual_2508'>
          <pose>0 0 0 0 0 0</pose>
          <geometry>
            <sphere>
              <radius>2.1439304567141244</radius>
            </sphere>
          </geometry>
          <cast_shadows>true</cast_shadows>
          <laser_retro>0</laser_retro>
          <transparency>0</transparency>
          <visibility_flags>4294967295</visibility_flags>
          <material>
            <ambient>0.80909884 0.461338699 0.685169935 1</ambient>
            <diffuse>0.80909884 0.461338699 0.685169935 1</diffuse>
            <specular>0 0 0 1</specular>
            <emissive>0 0 0 1</emissive>
            <render_order>0</render_order>
            <lighting>true</lighting>
            <double_sided>false</double_sided>
            <shader type='pixel'/>
          </material>
        </visual>
      </link>
      <link name='link_2509'>
        <pose>-7.2677559017650477 1.1218457633467604 4.7995241435558871 0 0 0</pose>
        <inertial>
          <pose>0 0 0 0 0 0</pose>
          <mass>1</mass>
          <inertia>
            <ixx>1</ixx>
            <ixy>0</ixy>
            <ixz>0</ixz>
            <iyy>1</iyy>
            <iyz>0</iyz>
            <izz>1</izz>
          </inertia>
        </inertial>
        <enable_wind>false</enable_wind>
        <collision name='collision_2509'>
          <pose>0 0 0 0 0 0</pose>
          <geometry>
            <sphere>
              <radius>1.9669158075776854</radius>
            </sphere>
          </geometry>
          <surface>
            <contact>
              <collide_bitmask>255</collide_bitmask>
            </contact>
            <friction>
              <ode>
                <mu>1</mu>
                <mu2>1</mu2>
                <slip1>0</slip1>
                <slip2>0</slip2>
                <fdir1>0 0 0</fdir1>
              </ode>
            </friction>
          </surface>
        </collision>
        <visual name='visual_2509'>
          <pose>0 0 0 0 0 0</pose>
          <geometry>
            <sphere>
              <radius>1.9669158075776854</radius>
            </sphere>
          </geometry>
          <cast_shadows>true</cast_shadows>
          <laser_retro>0</laser_retro>
          <transparency>0</transparency>
          <visibility_flags>4294967295</visibility_flags>
          <material>
            <ambient>0.985397577 0.466973871 0.870913267 1</ambient>
            <diffuse>0.985397577 0.466973871 0.870913267 1</diffuse>
            <specular>0 0 0 1</specular>
            <emissive>0 0 0 1</emissive>
            <render_order>0</render_order>
            <lighting>true</lighting>
            <double_sided>false</double_sided>
            <shader type='pixel'/>
          </material>
        </visual>
      </link>
      <link name='link_2510'>
        <pose>3.8002262871006707 -4.1919449166705629 7.8548641400256134 0 0 0</pose>
        <inertial>
          <pose>0 0 0 0 0 0</pose>
          <mass>1</mass>
          <inertia>
            <ixx>1</ixx>
            <ixy>0</ixy>
            <ixz>0</ixz>
            <iyy>1</iyy>
            <iyz>0</iyz>
            <izz>1</izz>
          </inertia>
        </inertial>
        <enable_wind>false</enable_wind>
        <collision name='collision_2510'>
          <pose>0 0 0 0 0 0</pose>
          <geometry>
            <capsule>
              <radius>1.4114252777019025</radius>
              <length>1.7534789944401725</length>
            </capsule>
          </geometry>
          <surface>
            <contact>
              <collide_bitmask>255</collide_bitmask>
            </contact>
            <friction>
              <ode>
                <mu>1</mu>
                <mu2>1</mu2>
                <slip1>0</slip1>
                <slip2>0</slip2>
                <fdir1>0 0 0</fdir1>
              </ode>
            </friction>
          </surface>
        </collision>
        <visual name='visual_2510'>
          <pose>0 0 0 0 0 0</pose>
          <geometry>
            <capsule>
              <radius>1.4114252777019025</radius>
              <length>1.7534789944401725</length>
            </capsule>
          </geometry>
          <cast_shadows>true</cast_shadows>
          <laser_retro>0</laser_retro>
          <transparency>0</transparency>
          <visibility_flags>4294967295</visibility_flags>
          <material>
            <ambient>0.00188824499 0.52092731 0.984089553 1</ambient>
            <diffuse>0.00188824499 0.52092731 0.984089553 1</diffuse>
            <specular>0 0 0 1</specular>
            <emissive>0 0 0 1</emissive>
            <render_order>0</render_order>
            <lighting>true</lighting>
            <double_sided>false</double_sided>
            <shader type='pixel'/>
          </material>
        </visual>
      </link>
      <joint name='joint_1672' type='universal'>
        <pose>0 0 0 0 0 0</pose>
        <parent>link_2509</parent>
        <child>link_2510</child>
        <axis>
          <xyz>0.75989588291169996 0.57861014478140405 0.29625756950648613</xyz>
          <limit>
            <lower>-inf</lower>
            <upper>inf</upper>
            <effort>inf</effort>
            <velocity>4.4558878286376311</velocity>
            <stiffness>100000000</stiffness>
            <dissipation>1</dissipation>
          </limit>
          <dynamics>
            <spring_reference>0</spring_reference>
            <spring_stiffness>0</spring_stiffness>
            <damping>0</damping>
            <friction>0</friction>
          </dynamics>
        </axis>
        <axis2>
          <xyz>0.62178771173441971 0.67653499824477858 0.39456360410713476</xyz>
          <limit>
            <lower>-inf</lower>
            <upper>inf</upper>
            <effort>inf</effort>
            <velocity>5.9685613871394407</velocity>
            <stiffness>100000000</stiffness>
            <dissipation>1</dissipation>
          </limit>
          <dynamics>
            <spring_reference>0</spring_reference>
            <spring_stiffness>0</spring_stiffness>
            <damping>0</damping>
            <friction>0</friction>
          </dynamics>
        </axis2>
      </joint>
      <joint name='joint_1673' type='gearbox'>
        <pose>0 0 0 0 0 0</pose>
        <parent>link_2508</parent>
        <child>link_2509</child>
        <axis>
          <xyz>0.8072376449830031 0.20102017981787584 0.55493988127389415</xyz>
          <limit>
            <lower>-inf</lower>
            <upper>inf</upper>
            <effort>inf</effort>
            <velocity>5.8971263180056734</velocity>
            <stiffness>100000000</stiffness>
            <dissipation>1</dissipation>
          </limit>
          <dynamics>
            <spring_reference>0</spring_reference>
            <spring_stiffness>0</spring_stiffness>
            <damping>0</damping>
            <friction>0</friction>
          </dynamics>
        </axis>
        <axis2>
          <xyz>0.88774467020736358 0.24819631746604834 0.38769574219316866</xyz>
          <limit>
            <lower>-inf</lower>
            <upper>inf</upper>
            <effort>inf</effort>
            <velocity>4.2094399942044136</velocity>
            <stiffness>100000000</stiffness>
            <dissipation>1</dissipation>
          </limit>
          <dynamics>
            <spring_reference>0</spring_reference>
            <spring_stiffness>0</spring_stiffness>
            <damping>0</damping>
            <friction>0</friction>
          </dynamics>
        </axis2>
      </joint>
    </model>
    <model name='model_1'>
      <static>false</static>
      <self_collide>false</self_collide>
      <allow_auto_disable>true</allow_auto_disable>
      <enable_wind>true</enable_wind>
      <pose>-5.4977740928482906 -4.5858444784099106 7.2499578993712044 0 0 0</pose>
      <link name='link_2511'>
        <pose>3.9569674075221588 9.9938475350261413 9.6342913178008214 0 0 0</pose>
        <inertial>
          <pose>0 0 0 0 0 0</pose>
          <mass>1</mass>
          <inertia>
            <ixx>1</ixx>
            <ixy>0</ixy>
            <ixz>0</ixz>
            <iyy>1</iyy>
            <iyz>0</iyz>
            <izz>1</izz>
          </inertia>
        </inertial>
        <enable_wind>false</enable_wind>
        <collision name='collision_2511'>
          <pose>0 0 0 0 0 0</pose>
          <geometry>
            <capsule>
              <radius>2.4987527399674554</radius>
              <length>1.7828179925116336</length>
            </capsule>
          </geometry>
          <surface>
            <contact>
              <collide_bitmask>255</collide_bitmask>
            </contact>
            <friction>
              <ode>
                <mu>1</mu>
                <mu2>1</mu2>
                <slip1>0</slip1>
                <slip2>0</slip2>
                <fdir1>0 0 0</fdir1>
              </ode>
            </friction>
          </surface>
        </collision>
        <visual name='visual_2511'>
          <pose>0 0 0 0 0 0</pose>
          <geometry>
            <capsule>
              <radius>2.4987527399674554</radius>
              <length>1.7828179925116336</length>
            </capsule>
          </geometry>
          <cast_shadows>true</cast_shadows>
          <laser_retro>0</laser_retro>
          <transparency>0</transparency>
          <visibility_flags>4294967295</visibility_flags>
          <material>
            <ambient>0.972819388 0.796370268 0.0768915787 1</ambient>
            <diffuse>0.972819388 0.796370268 0.0768915787 1</diffuse>
            <specular>0 0 0 1</specular>
            <emissive>0 0 0 1</emissive>
            <render_order>0</render_order>
            <lighting>true</lighting>
            <double_sided>false</double_sided>
            <shader type='pixel'/>
          </material>
        </visual>
      </link>
      <link name='link_2512'>
        <pose>7.0285328874836424 -4.9057294571489702 0.88696356656840836 0 0 0</pose>
        <inertial>
          <pose>0 0 0 0 0 0</pose>
          <mass>1</mass>
          <inertia>
            <ixx>1</ixx>
            <ixy>0</ixy>
            <ixz>0</ixz>
            <iyy>1</iyy>
            <iyz>0</iyz>
            <izz>1</izz>
          </inertia>
        </inertial>
        <enable_wind>false</enable_wind>
        <collision name='collision_2512'>
          <pose>0 0 0 0 0 0</pose>
          <geometry>
            <sphere>
              <radius>2.966795899018229</radius>
            </sphere>
          </geometry>
          <surface>
            <contact>
              <collide_bitmask>255</collide_bitmask>
            </contact>
            <friction>
              <ode>
                <mu>1</mu>
                <mu2>1</mu2>
                <slip1>0</slip1>
                <slip2>0</slip2>
                <fdir1>0 0 0</fdir1>
              </ode>
            </friction>
          </surface>
        </collision>
        <visual name='visual_2512'>
          <pose>0 0 0 0 0 0</pose>
          <geometry>
            <sphere>
              <radius>2.966795899018229</radius>
            </sphere>
          </geometry>
          <cast_shadows>true</cast_shadows>
          <laser_retro>0</laser_retro>
          <transparency>0</transparency>
          <visibility_flags>4294967295</visibility_flags>
          <material>
            <ambient>0.743033171 0.264583945 0.582406938 1</ambient>
            <diffuse>0.743033171 0.264583945 0.582406938 1</diffuse>
            <specular>0 0 0 1</specular>
            <emissive>0 0 0 1</emissive>
            <render_order>0</render_order>
            <lighting>true</lighting>
            <double_sided>false</double_sided>
            <shader type='pixel'/>
          </material>
        </visual>
      </link>
      <link name='link_2513'>
        <pose>3.3748812055149564 -9.5186425917408251 0.06739245101911151 0 0 0</pose>
        <inertial>
          <pose>0 0 0 0 0 0</pose>
          <mass>1</mass>
          <inertia>
            <ixx>1</ixx>
            <ixy>0</ixy>
            <ixz>0</ixz>
            <iyy>1</iyy>
            <iyz>0</iyz>
            <izz>1</izz>
          </inertia>
        </inertial>
        <enable_wind>false</enable_wind>
        <collision name='collision_2513'>
          <pose>0 0 0 0 0 0</pose>
          <geometry>
            <cylinder>
              <radius>1.1735613574014352</radius>
              <length>1.6897167253197458</length>
            </cylinder>
          </geometry>
          <surface>
            <contact>
              <collide_bitmask>255</collide_bitmask>
            </contact>
            <friction>
              <ode>
                <mu>1</mu>
                <mu2>1</mu2>
                <slip1>0</slip1>
                <slip2>0</slip2>
                <fdir1>0 0 0</fdir1>
              </ode>
            </friction>
          </surface>
        </collision>
        <visual name='visual_2513'>
          <pose>0 0 0 0 0 0</pose>
          <geometry>
            <cylinder>
              <radius>1.1735613574014352</radius>
              <length>1.6897167253197458</length>
            </cylinder>
          </geometry>
          <cast_shadows>true</cast_shadows>
          <laser_retro>0</laser_retro>
          <transparency>0</transparency>
          <visibility_flags>4294967295</visibility_flags>
          <material>
            <ambient>0.682385445 0.347219586 0.892649353 1</ambient>
            <diffuse>0.682385445 0.347219586 0.892649353 1</diffuse>
            <specular>0 0 0 1</specular>
            <emissive>0 0 0 1</emissive>
            <render_order>0</render_order>
            <lighting>true</lighting>
            <double_sided>false</double_sided>
            <shader type='pixel'/>
          </material>
        </visual>
      </link>
      <joint name='joint_1674' type='screw'>
        <pose>0 0 0 0 0 0</pose>
        <parent>link_2512</parent>
        <child>link_2513</child>
        <axis>
          <xyz>0.45708148038758367 0.44732961423513457 0.76874751155040544</xyz>
          <limit>
            <lower>-inf</lower>
            <upper>inf</upper>
            <effort>inf</effort>
            <velocity>6.060051880524135</velocity>
            <stiffness>100000000</stiffness>
            <dissipation>1</dissipation>
          </limit>
          <dynamics>
            <spring_reference>0</spring_reference>
            <spring_stiffness>0</spring_stiffness>
            <damping>0</damping>
            <friction>0</friction>
          </dynamics>
        </axis>
        <axis2>
          <xyz>0.51037388124522032 0.62766402904811669 0.58784042731150654</xyz>
          <limit>
            <lower>-inf</lower>
            <upper>inf</upper>
            <effort>inf</effort>
            <velocity>6.2450311152478077</velocity>
            <stiffness>100000000</stiffness>
            <dissipation>1</dissipation>
          </limit>
          <dynamics>
            <spring_reference>0</spring_reference>
            <spring_stiffness>0</spring_stiffness>
            <damping>0</damping>
            <friction>0</friction>
          </dynamics>
        </axis2>
        <thread_pitch>-6.2831853071795862</thread_pitch>
      </joint>
      <joint name='joint_1675' type='gearbox'>
        <pose>0 0 0 0 0 0</pose>
        <parent>link_2512</parent>
        <child>link_2513</child>
        <axis>
          <xyz>0.28507691366867949 0.19288432072815101 0.93889658222318606</xyz>
          <limit>
            <lower>-inf</lower>
            <upper>inf</upper>
            <effort>inf</effort>
            <velocity>1.2786320525810091</velocity>
            <stiffness>100000000</stiffness>
            <dissipation>1</dissipation>
          </limit>
          <dynamics>
            <spring_reference>0</spring_reference>
            <spring_stiffness>0</spring_stiffness>
            <damping>0</damping>
            <friction>0</friction>
          </dynamics>
        </axis>
        <axis2>
          <xyz>0.38216453500772224 0.74136798062757681 0.55165549528897151</xyz>
          <limit>
            <lower>-inf</lower>
            <upper>inf</upper>
            <effort>inf</effort>
            <velocity>4.3695291142757071</velocity>
            <stiffness>100000000</stiffness>
            <dissipation>1</dissipation>
          </limit>
          <dynamics>
            <spring_reference>0</spring_reference>
            <spring_stiffness>0</spring_stiffness>
            <damping>0</damping>
            <friction>0</friction>
          </dynamics>
        </axis2>
      </joint>
    </model>
    <model name='red_box'>
      <static>false</static>
      <self_collide>false</self_collide>
      <allow_auto_disable>true</allow_auto_disable>
      <enable_wind>false</enable_wind>
      <pose>0 0 0.5 0 0 0</pose>
      <link name='box_link'>
        <pose>0 0 0 0 0 0</pose>
        <inertial>
          <pose>0 0 0 0 0 0</pose>
          <mass>1</mass>
          <inertia>
            <ixx>1</ixx>
            <ixy>0</ixy>
            <ixz>0</ixz>
            <iyy>1</iyy>
            <iyz>0</iyz>
            <izz>1</izz>
          </inertia>
        </inertial>
        <enable_wind>false</enable_wind>
        <collision name='box_collision'>
          <pose>0 0 0 0 0 0</pose>
          <geometry>
            <box>
              <size>1 1 1</size>
            </box>
          </geometry>
          <surface>
            <contact>
              <collide_bitmask>255</collide_bitmask>
            </contact>
            <friction>
              <ode>
                <mu>1</mu>
                <mu2>1</mu2>
                <slip1>0</slip1>
                <slip2>0</slip2>
                <fdir1>0 0 0</fdir1>
              </ode>
            </friction>
          </surface>
        </collision>
        <visual name='box_visual'>
          <pose>0 0 0 0 0 0</pose>
          <geometry>
            <box>
              <size>1 1 1</size>
            </box>
          </geometry>
          <cast_shadows>true</cast_shadows>
          <laser_retro>0</laser_retro>
          <transparency>0</transparency>
          <visibility_flags>4294967295</visibility_flags>
          <material>
            <ambient>1 0 0 1</ambient>
            <diffuse>1 0 0 1</diffuse>
            <specular>1 0 0 1</specular>
            <emissive>0 0 0 1</emissive>
            <render_order>0</render_order>
            <lighting>true</lighting>
            <double_sided>false</double_sided>
            <shader type='pixel'/>
          </material>
        </visual>
      </link>
      <plugin name='gz::sim::systems::LogicalAudioSensorPlugin' filename='gz-sim-logicalaudiosensorplugin-system'>
        <source>
          <id>1</id>
          <pose>.5 0 0 0 0 0</pose>
          <attenuation_function>linear</attenuation_function>
          <attenuation_shape>sphere</attenuation_shape>
          <inner_radius>1.0</inner_radius>
          <falloff_distance>5.0</falloff_distance>
          <volume_level>.8</volume_level>
          <playing>true</playing>
          <play_duration>10</play_duration>
        </source>
      </plugin>
    </model>
    <model name='ground_model'>
      <static>true</static>
      <self_collide>false</self_collide>
      <allow_auto_disable>true</allow_auto_disable>
      <enable_wind>false</enable_wind>
      <pose>0 0 0 0 0 0</pose>
      <link name='ground_link'>
        <pose>0 0 0 0 0 0</pose>
        <inertial>
          <pose>0 0 0 0 0 0</pose>
          <mass>1</mass>
          <inertia>
            <ixx>1</ixx>
            <ixy>0</ixy>
            <ixz>0</ixz>
            <iyy>1</iyy>
            <iyz>0</iyz>
            <izz>1</izz>
          </inertia>
        </inertial>
        <enable_wind>false</enable_wind>
        <collision name='ground_collision'>
          <pose>0 0 0 0 0 0</pose>
          <geometry>
            <plane>
              <normal>0 0 1</normal>
              <size>100 100</size>
            </plane>
          </geometry>
          <surface>
            <contact>
              <collide_bitmask>255</collide_bitmask>
            </contact>
            <friction>
              <ode>
                <mu>1</mu>
                <mu2>1</mu2>
                <slip1>0</slip1>
                <slip2>0</slip2>
                <fdir1>0 0 0</fdir1>
              </ode>
            </friction>
          </surface>
        </collision>
      </link>
    </model>
    <model name='ceiling_model'>
      <static>true</static>
      <self_collide>false</self_collide>
      <allow_auto_disable>true</allow_auto_disable>
      <enable_wind>false</enable_wind>
      <pose>0 0 100 0 0 0</pose>
      <link name='ceiling_link'>
        <pose>0 0 0 0 0 0</pose>
        <inertial>
          <pose>0 0 0 0 0 0</pose>
          <mass>1</mass>
          <inertia>
            <ixx>1</ixx>
            <ixy>0</ixy>
            <ixz>0</ixz>
            <iyy>1</iyy>
            <iyz>0</iyz>
            <izz>1</izz>
          </inertia>
        </inertial>
        <enable_wind>false</enable_wind>
        <collision name='ceiling_collision'>
          <pose>0 0 0 0 0 0</pose>
          <geometry>
            <box>
              <size>102 102 3</size>
            </box>
          </geometry>
          <surface>
            <contact>
              <collide_bitmask>255</collide_bitmask>
            </contact>
            <friction>
              <ode>
                <mu>1</mu>
                <mu2>1</mu2>
                <slip1>0</slip1>
                <slip2>0</slip2>
                <fdir1>0 0 0</fdir1>
              </ode>
            </friction>
          </surface>
        </collision>
        <visual name='ceiling_visual'>
          <pose>0 0 0 0 0 0</pose>
          <geometry>
            <box>
              <size>102 102 3</size>
            </box>
          </geometry>
          <cast_shadows>true</cast_shadows>
          <laser_retro>0</laser_retro>
          <transparency>0</transparency>
          <visibility_flags>4294967295</visibility_flags>
          <material>
            <ambient>0.200000003 0.200000003 0.200000003 0.200000003</ambient>
            <diffuse>0.200000003 0.200000003 0.200000003 0.200000003</diffuse>
            <specular>0 0 0 1</specular>
            <emissive>0 0 0 1</emissive>
            <render_order>0</render_order>
            <lighting>true</lighting>
            <double_sided>false</double_sided>
            <shader type='pixel'/>
          </material>
        </visual>
      </link>
    </model>
    <model name='west_model'>
      <static>true</static>
      <self_collide>false</self_collide>
      <allow_auto_disable>true</allow_auto_disable>
      <enable_wind>false</enable_wind>
      <pose>0 50 50 0 0 0</pose>
      <link name='west_link'>
        <pose>0 0 0 0 0 0</pose>
        <inertial>
          <pose>0 0 0 0 0 0</pose>
          <mass>1</mass>
          <inertia>
            <ixx>1</ixx>
            <ixy>0</ixy>
            <ixz>0</ixz>
            <iyy>1</iyy>
            <iyz>0</iyz>
            <izz>1</izz>
          </inertia>
        </inertial>
        <enable_wind>false</enable_wind>
        <collision name='west_collision'>
          <pose>0 0 0 0 0 0</pose>
          <geometry>
            <box>
              <size>102 3 102</size>
            </box>
          </geometry>
          <surface>
            <contact>
              <collide_bitmask>255</collide_bitmask>
            </contact>
            <friction>
              <ode>
                <mu>1</mu>
                <mu2>1</mu2>
                <slip1>0</slip1>
                <slip2>0</slip2>
                <fdir1>0 0 0</fdir1>
              </ode>
            </friction>
          </surface>
        </collision>
        <visual name='west_visual'>
          <pose>0 0 0 0 0 0</pose>
          <geometry>
            <box>
              <size>102 3 102</size>
            </box>
          </geometry>
          <cast_shadows>true</cast_shadows>
          <laser_retro>0</laser_retro>
          <transparency>0</transparency>
          <visibility_flags>4294967295</visibility_flags>
          <material>
            <ambient>0.200000003 0.200000003 0.200000003 0.200000003</ambient>
            <diffuse>0.200000003 0.200000003 0.200000003 0.200000003</diffuse>
            <specular>0 0 0 1</specular>
            <emissive>0 0 0 1</emissive>
            <render_order>0</render_order>
            <lighting>true</lighting>
            <double_sided>false</double_sided>
            <shader type='pixel'/>
          </material>
        </visual>
      </link>
    </model>
    <model name='east_model'>
      <static>true</static>
      <self_collide>false</self_collide>
      <allow_auto_disable>true</allow_auto_disable>
      <enable_wind>false</enable_wind>
      <pose>0 -50 50 0 0 0</pose>
      <link name='east_link'>
        <pose>0 0 0 0 0 0</pose>
        <inertial>
          <pose>0 0 0 0 0 0</pose>
          <mass>1</mass>
          <inertia>
            <ixx>1</ixx>
            <ixy>0</ixy>
            <ixz>0</ixz>
            <iyy>1</iyy>
            <iyz>0</iyz>
            <izz>1</izz>
          </inertia>
        </inertial>
        <enable_wind>false</enable_wind>
        <collision name='east_collision'>
          <pose>0 0 0 0 0 0</pose>
          <geometry>
            <box>
              <size>102 3 102</size>
            </box>
          </geometry>
          <surface>
            <contact>
              <collide_bitmask>255</collide_bitmask>
            </contact>
            <friction>
              <ode>
                <mu>1</mu>
                <mu2>1</mu2>
                <slip1>0</slip1>
                <slip2>0</slip2>
                <fdir1>0 0 0</fdir1>
              </ode>
            </friction>
          </surface>
        </collision>
        <visual name='east_visual'>
          <pose>0 0 0 0 0 0</pose>
          <geometry>
            <box>
              <size>102 3 102</size>
            </box>
          </geometry>
          <cast_shadows>true</cast_shadows>
          <laser_retro>0</laser_retro>
          <transparency>0</transparency>
          <visibility_flags>4294967295</visibility_flags>
          <material>
            <ambient>0.200000003 0.200000003 0.200000003 0.200000003</ambient>
            <diffuse>0.200000003 0.200000003 0.200000003 0.200000003</diffuse>
            <specular>0 0 0 1</specular>
            <emissive>0 0 0 1</emissive>
            <render_order>0</render_order>
            <lighting>true</lighting>
            <double_sided>false</double_sided>
            <shader type='pixel'/>
          </material>
        </visual>
      </link>
    </model>
    <model name='north_model'>
      <static>true</static>
      <self_collide>false</self_collide>
      <allow_auto_disable>true</allow_auto_disable>
      <enable_wind>false</enable_wind>
      <pose>50 0 50 0 0 0</pose>
      <link name='north_link'>
        <pose>0 0 0 0 0 0</pose>
        <inertial>
          <pose>0 0 0 0 0 0</pose>
          <mass>1</mass>
          <inertia>
            <ixx>1</ixx>
            <ixy>0</ixy>
            <ixz>0</ixz>
            <iyy>1</iyy>
            <iyz>0</iyz>
            <izz>1</izz>
          </inertia>
        </inertial>
        <enable_wind>false</enable_wind>
        <collision name='north_collision'>
          <pose>0 0 0 0 0 0</pose>
          <geometry>
            <box>
              <size>3 102 102</size>
            </box>
          </geometry>
          <surface>
            <contact>
              <collide_bitmask>255</collide_bitmask>
            </contact>
            <friction>
              <ode>
                <mu>1</mu>
                <mu2>1</mu2>
                <slip1>0</slip1>
                <slip2>0</slip2>
                <fdir1>0 0 0</fdir1>
              </ode>
            </friction>
          </surface>
        </collision>
        <visual name='north_visual'>
          <pose>0 0 0 0 0 0</pose>
          <geometry>
            <box>
              <size>3 102 102</size>
            </box>
          </geometry>
          <cast_shadows>true</cast_shadows>
          <laser_retro>0</laser_retro>
          <transparency>0</transparency>
          <visibility_flags>4294967295</visibility_flags>
          <material>
            <ambient>0.200000003 0.200000003 0.200000003 0.200000003</ambient>
            <diffuse>0.200000003 0.200000003 0.200000003 0.200000003</diffuse>
            <specular>0 0 0 1</specular>
            <emissive>0 0 0 1</emissive>
            <render_order>0</render_order>
            <lighting>true</lighting>
            <double_sided>false</double_sided>
            <shader type='pixel'/>
          </material>
        </visual>
      </link>
    </model>
    <model name='south_model'>
      <static>true</static>
      <self_collide>false</self_collide>
      <allow_auto_disable>true</allow_auto_disable>
      <enable_wind>false</enable_wind>
      <pose>-50 0 50 0 0 0</pose>
      <link name='south_link'>
        <pose>0 0 0 0 0 0</pose>
        <inertial>
          <pose>0 0 0 0 0 0</pose>
          <mass>1</mass>
          <inertia>
            <ixx>1</ixx>
            <ixy>0</ixy>
            <ixz>0</ixz>
            <iyy>1</iyy>
            <iyz>0</iyz>
            <izz>1</izz>
          </inertia>
        </inertial>
        <enable_wind>false</enable_wind>
        <collision name='south_collision'>
          <pose>0 0 0 0 0 0</pose>
          <geometry>
            <box>
              <size>3 102 102</size>
            </box>
          </geometry>
          <surface>
            <contact>
              <collide_bitmask>255</collide_bitmask>
            </contact>
            <friction>
              <ode>
                <mu>1</mu>
                <mu2>1</mu2>
                <slip1>0</slip1>
                <slip2>0</slip2>
                <fdir1>0 0 0</fdir1>
              </ode>
            </friction>
          </surface>
        </collision>
        <visual name='south_visual'>
          <pose>0 0 0 0 0 0</pose>
          <geometry>
            <box>
              <size>3 102 102</size>
            </box>
          </geometry>
          <cast_shadows>true</cast_shadows>
          <laser_retro>0</laser_retro>
          <transparency>0</transparency>
          <visibility_flags>4294967295</visibility_flags>
          <material>
            <ambient>0.200000003 0.200000003 0.200000003 0.200000003</ambient>
            <diffuse>0.200000003 0.200000003 0.200000003 0.200000003</diffuse>
            <specular>0 0 0 1</specular>
            <emissive>0 0 0 1</emissive>
            <render_order>0</render_order>
            <lighting>true</lighting>
            <double_sided>false</double_sided>
            <shader type='pixel'/>
          </material>
        </visual>
      </link>
    </model>
    <atmosphere type='adiabatic'>
      <temperature>288.14999999999998</temperature>
      <pressure>101325</pressure>
      <temperature_gradient>-0.0064999999999999997</temperature_gradient>
    </atmosphere>
    <scene>
      <ambient>0.400000006 0.400000006 0.400000006 1</ambient>
      <background>0.699999988 0.699999988 0.699999988 1</background>
      <grid>true</grid>
      <origin_visual>true</origin_visual>
      <shadows>true</shadows>
    </scene>
  </world>
</sdf>
