Warning: Ignoring XDG_SESSION_TYPE=wayland on Gnome. Use QT_QPA_PLATFORM=wayland to run on Wayland anyway.
[1;31m[Err] [UserCommands.cc:1145] [0m[1;31mError Code [0m[1;31m30[0m[1;31m: [0m[1;31mMsg: [0m[1;31mError parsing XML from string: Error=XML_ERROR_PARSING_TEXT ErrorID=8 (0x8) Line number=1[0m[1;31m[0m
[1;31m[Err] [UserCommands.cc:1145] [0m[1;31mError Code [0m[1;31m30[0m[1;31m: [0m[1;31mMsg: [0m[1;31mUnable to read SDF string: b"<sdf version="1.11">\n  <model name="model">\n    <static>true</static>\n    <self_collide>false</self_collide>\n    <allow_auto_disable>true</allow_auto_disable>\n    <enable_wind>true</enable_wind>\n    <pose>-6.6073057085576048 5.5016382839360354 3.429377523062044 0 0 0</pose>\n    <link name="link_1026">\n      <pose>2.457054109120369 8.6111093393853295 7.1833221476963764 0 0 0</pose>\n      <inertial>\n        <pose>0 0 0 0 0 0</pose>\n        <mass>1</mass>\n        <inertia>\n          <ixx>1</ixx>\n          <ixy>0</ixy>\n          <ixz>0</ixz>\n          <iyy>1</iyy>\n          <iyz>0</iyz>\n          <izz>1</izz>\n        </inertia>\n      </inertial>\n      <enable_wind>false</enable_wind>\n      <collision name="collision_1026">\n        <pose>0 0 0 0 0 0</pose>\n        <geometry>\n          <sphere>\n            <radius>1.7751583657727685</radius>\n          </sphere>\n        </geometry>\n        <surface>\n          <contact>\n            <collide_bitmask>255</collide_bitmask>\n          </contact>\n          <friction>\n            <ode>\n              <mu>1</mu>\n              <mu2>1</mu2>\n              <slip1>0</slip1>\n              <slip2>0</slip2>\n              <fdir1>0 0 0</fdir1>\n            </ode>\n          </friction>\n        </surface>\n      </collision>\n      <visual name="visual_1026">\n        <pose>0 0 0 0 0 0</pose>\n        <geometry>\n          <sphere>\n            <radius>1.7751583657727685</radius>\n          </sphere>\n        </geometry>\n        <cast_shadows>true</cast_shadows>\n        <laser_retro>0</laser_retro>\n        <transparency>0</transparency>\n        <visibility_flags>4294967295</visibility_flags>\n        <material>\n          <ambient>0.665827513 0.518196642 0.140903905 1</ambient>\n          <diffuse>0.665827513 0.518196642 0.140903905 1</diffuse>\n          <specular>0 0 0 1</specular>\n          <emissive>0 0 0 1</emissive>\n          <render_order>0</render_order>\n          <lighting>true</lighting>\n          <double_sided>false</double_sided>\n          <shader type="pixel"/>\n        </material>\n      </visual>\n    </link>\n    <link name="link_1027">\n      <pose>9.4433996157071576 9.5816761188171178 5.7447551974365041 0 0 0</pose>\n      <inertial>\n        <pose>0 0 0 0 0 0</pose>\n        <mass>1</mass>\n        <inertia>\n          <ixx>1</ixx>\n          <ixy>0</ixy>\n          <ixz>0</ixz>\n          <iyy>1</iyy>\n          <iyz>0</iyz>\n          <izz>1</izz>\n        </inertia>\n      </inertial>\n      <enable_wind>false</enable_wind>\n      <collision name="collision_1027">\n        <pose>0 0 0 0 0 0</pose>\n        <geometry>\n          <box>\n            <size>1.4732508480329138 2.123601946780699 2.800899543591346</size>\n          </box>\n        </geometry>\n        <surface>\n          <contact>\n            <collide_bitmask>255</collide_bitmask>\n          </contact>\n          <friction>\n            <ode>\n              <mu>1</mu>\n              <mu2>1</mu2>\n              <slip1>0</slip1>\n              <slip2>0</slip2>\n              <fdir1>0 0 0</fdir1>\n            </ode>\n          </friction>\n        </surface>\n      </collision>\n      <visual name="visual_1027">\n        <pose>0 0 0 0 0 0</pose>\n        <geometry>\n          <box>\n            <size>1.4732508480329138 2.123601946780699 2.800899543591346</size>\n          </box>\n        </geometry>\n        <cast_shadows>true</cast_shadows>\n        <laser_retro>0</laser_retro>\n        <transparency>0</transparency>\n        <visibility_flags>4294967295</visibility_flags>\n        <material>\n          <ambient>0.62508136 0.738441646 0.221863374 1</ambient>\n          <diffuse>0.62508136 0.738441646 0.221863374 1</diffuse>\n          <specular>0 0 0 1</specular>\n          <emissive>0 0 0 1</emissive>\n          <render_order>0</render_order>\n          <lighting>true</lighting>\n          <double_sided>false</double_sided>\n          <shader type="pixel"/>\n        </material>\n      </visual>\n    </link>\n    <link name="link_1028">\n      <pose>2.1054158411700818 -1.1917648641063483 2.1107236669000837 0 0 0</pose>\n      <inertial>\n        <pose>0 0 0 0 0 0</pose>\n        <mass>1</mass>\n        <inertia>\n          <ixx>1</ixx>\n          <ixy>0</ixy>\n          <ixz>0</ixz>\n          <iyy>1</iyy>\n          <iyz>0</iyz>\n          <izz>1</izz>\n        </inertia>\n      </inertial>\n      <enable_wind>false</enable_wind>\n      <collision name="collision_1028">\n        <pose>0 0 0 0 0 0</pose>\n        <geometry>\n          <box>\n            <size>1.1853625425938532 1.4461948741123969 1.0486381404917355</size>\n          </box>\n        </geometry>\n        <surface>\n          <contact>\n            <collide_bitmask>255</collide_bitmask>\n          </contact>\n          <friction>\n            <ode>\n              <mu>1</mu>\n              <mu2>1</mu2>\n              <slip1>0</slip1>\n              <slip2>0</slip2>\n              <fdir1>0 0 0</fdir1>\n            </ode>\n          </friction>\n        </surface>\n      </collision>\n      <visual name="visual_1028">\n        <pose>0 0 0 0 0 0</pose>\n        <geometry>\n          <box>\n            <size>1.1853625425938532 1.4461948741123969 1.0486381404917355</size>\n          </box>\n        </geometry>\n        <cast_shadows>true</cast_shadows>\n        <laser_retro>0</laser_retro>\n        <transparency>0</transparency>\n        <visibility_flags>4294967295</visibility_flags>\n        <material>\n          <ambient>0.510134518 0.559609652 0.786846101 1</ambient>\n          <diffuse>0.510134518 0.559609652 0.786846101 1</diffuse>\n          <specular>0 0 0 1</specular>\n          <emissive>0 0 0 1</emissive>\n          <render_order>0</render_order>\n          <lighting>true</lighting>\n          <double_sided>false</double_sided>\n          <shader type="pixel"/>\n        </material>\n      </visual>\n    </link>\n    <joint name="joint_684" type="universal">\n      <pose>0 0 0 0 0 0</pose>\n      <parent>link_1026</parent>\n      <child>link_1027</child>\n      <axis>\n        <xyz>0.49605469730419383 0.48079987272511465 0.72302228158609205</xyz>\n        <limit>\n          <lower>-inf</lower>\n          <upper>inf</upper>\n          <effort>inf</effort>\n          <velocity>1.9141207399656324</velocity>\n          <stiffness>100000000</stiffness>\n          <dissipation>1</dissipation>\n        </limit>\n        <dynamics>\n          <spring_reference>0</spring_reference>\n          <spring_stiffness>0</spring_stiffness>\n          <damping>0</damping>\n          <friction>0</friction>\n        </dynamics>\n      </axis>\n      <axis2>\n        <xyz>0.31856990807416419 0.66066911242033377 0.67972754656799583</xyz>\n        <limit>\n          <lower>-inf</lower>\n          <upper>inf</upper>\n          <effort>inf</effort>\n          <velocity>9.5135707020467937</velocity>\n          <stiffness>100000000</stiffness>\n          <dissipation>1</dissipation>\n        </limit>\n        <dynamics>\n          <spring_reference>0</spring_reference>\n          <spring_stiffness>0</spring_stiffness>\n          <damping>0</damping>\n          <friction>0</friction>\n        </dynamics>\n      </axis2>\n    </joint>\n    <joint name="joint_685" type="screw">\n      <pose>0 0 0 0 0 0</pose>\n      <parent>link_1028</parent>\n      <child>link_1026</child>\n      <axis>\n        <xyz>0.3487738346437832 0.15060446854677506 0.92502708410165724</xyz>\n        <limit>\n          <lower>-inf</lower>\n          <upper>inf</upper>\n          <effort>inf</effort>\n          <velocity>2.636031642408434</velocity>\n          <stiffness>100000000</stiffness>\n          <dissipation>1</dissipation>\n        </limit>\n        <dynamics>\n          <spring_reference>0</spring_reference>\n          <spring_stiffness>0</spring_stiffness>\n          <damping>0</damping>\n          <friction>0</friction>\n        </dynamics>\n      </axis>\n      <axis2>\n        <xyz>0.6360557220775459 0.74043536727617254 0.21722933802553282</xyz>\n        <limit>\n          <lower>-inf</lower>\n          <upper>inf</upper>\n          <effort>inf</effort>\n          <velocity>9.1229273216458679</velocity>\n          <stiffness>100000000</stiffness>\n          <dissipation>1</dissipation>\n        </limit>\n        <dynamics>\n          <spring_reference>0</spring_reference>\n          <spring_stiffness>0</spring_stiffness>\n          <damping>0</damping>\n          <friction>0</friction>\n        </dynamics>\n      </axis2>\n      <thread_pitch>-6.2831853071795862</thread_pitch>\n    </joint>\n  </model>\n</sdf>\n"[0m[1;31m[0m
[1;31m[Err] [UserCommands.cc:1145] [0m[1;31mError Code [0m[1;31m30[0m[1;31m: [0m[1;31mMsg: [0m[1;31mError parsing XML from string: Error=XML_ERROR_PARSING_TEXT ErrorID=8 (0x8) Line number=1[0m[1;31m[0m
[1;31m[Err] [UserCommands.cc:1145] [0m[1;31mError Code [0m[1;31m30[0m[1;31m: [0m[1;31mMsg: [0m[1;31mUnable to read SDF string: b"<sdf version="1.11">\n  <model name="model">\n    <static>true</static>\n    <self_collide>true</self_collide>\n    <allow_auto_disable>true</allow_auto_disable>\n    <enable_wind>false</enable_wind>\n    <pose>7.6025703087121705 1.1491622939980832 1.6779432547469186 0 0 0</pose>\n    <link name="link_1029">\n      <pose>6.506483403030817 2.831638722569048 5.7329906533466923 0 0 0</pose>\n      <inertial>\n        <pose>0 0 0 0 0 0</pose>\n        <mass>1</mass>\n        <inertia>\n          <ixx>1</ixx>\n          <ixy>0</ixy>\n          <ixz>0</ixz>\n          <iyy>1</iyy>\n          <iyz>0</iyz>\n          <izz>1</izz>\n        </inertia>\n      </inertial>\n      <enable_wind>false</enable_wind>\n      <collision name="collision_1029">\n        <pose>0 0 0 0 0 0</pose>\n        <geometry>\n          <cylinder>\n            <radius>1.9564257537870555</radius>\n            <length>2.980724583693025</length>\n          </cylinder>\n        </geometry>\n        <surface>\n          <contact>\n            <collide_bitmask>255</collide_bitmask>\n          </contact>\n          <friction>\n            <ode>\n              <mu>1</mu>\n              <mu2>1</mu2>\n              <slip1>0</slip1>\n              <slip2>0</slip2>\n              <fdir1>0 0 0</fdir1>\n            </ode>\n          </friction>\n        </surface>\n      </collision>\n      <visual name="visual_1029">\n        <pose>0 0 0 0 0 0</pose>\n        <geometry>\n          <cylinder>\n            <radius>1.9564257537870555</radius>\n            <length>2.980724583693025</length>\n          </cylinder>\n        </geometry>\n        <cast_shadows>true</cast_shadows>\n        <laser_retro>0</laser_retro>\n        <transparency>0</transparency>\n        <visibility_flags>4294967295</visibility_flags>\n        <material>\n          <ambient>0.556703627 0.289882779 0.183181673 1</ambient>\n          <diffuse>0.556703627 0.289882779 0.183181673 1</diffuse>\n          <specular>0 0 0 1</specular>\n          <emissive>0 0 0 1</emissive>\n          <render_order>0</render_order>\n          <lighting>true</lighting>\n          <double_sided>false</double_sided>\n          <shader type="pixel"/>\n        </material>\n      </visual>\n    </link>\n    <link name="link_1030">\n      <pose>-8.7865407832220317 1.9268587048114494 3.8064159120313237 0 0 0</pose>\n      <inertial>\n        <pose>0 0 0 0 0 0</pose>\n        <mass>1</mass>\n        <inertia>\n          <ixx>1</ixx>\n          <ixy>0</ixy>\n          <ixz>0</ixz>\n          <iyy>1</iyy>\n          <iyz>0</iyz>\n          <izz>1</izz>\n        </inertia>\n      </inertial>\n      <enable_wind>false</enable_wind>\n      <collision name="collision_1030">\n        <pose>0 0 0 0 0 0</pose>\n        <geometry>\n          <box>\n            <size>2.2545134167875767 2.8441510297709982 2.4277955972413787</size>\n          </box>\n        </geometry>\n        <surface>\n          <contact>\n            <collide_bitmask>255</collide_bitmask>\n          </contact>\n          <friction>\n            <ode>\n              <mu>1</mu>\n              <mu2>1</mu2>\n              <slip1>0</slip1>\n              <slip2>0</slip2>\n              <fdir1>0 0 0</fdir1>\n            </ode>\n          </friction>\n        </surface>\n      </collision>\n      <visual name="visual_1030">\n        <pose>0 0 0 0 0 0</pose>\n        <geometry>\n          <box>\n            <size>2.2545134167875767 2.8441510297709982 2.4277955972413787</size>\n          </box>\n        </geometry>\n        <cast_shadows>true</cast_shadows>\n        <laser_retro>0</laser_retro>\n        <transparency>0</transparency>\n        <visibility_flags>4294967295</visibility_flags>\n        <material>\n          <ambient>0.318036497 0.149471715 0.74475807 1</ambient>\n          <diffuse>0.318036497 0.149471715 0.74475807 1</diffuse>\n          <specular>0 0 0 1</specular>\n          <emissive>0 0 0 1</emissive>\n          <render_order>0</render_order>\n          <lighting>true</lighting>\n          <double_sided>false</double_sided>\n          <shader type="pixel"/>\n        </material>\n      </visual>\n    </link>\n    <link name="link_1031">\n      <pose>2.679733387632357 -2.9946644575587111 2.9541104022658904 0 0 0</pose>\n      <inertial>\n        <pose>0 0 0 0 0 0</pose>\n        <mass>1</mass>\n        <inertia>\n          <ixx>1</ixx>\n          <ixy>0</ixy>\n          <ixz>0</ixz>\n          <iyy>1</iyy>\n          <iyz>0</iyz>\n          <izz>1</izz>\n        </inertia>\n      </inertial>\n      <enable_wind>false</enable_wind>\n      <collision name="collision_1031">\n        <pose>0 0 0 0 0 0</pose>\n        <geometry>\n          <cylinder>\n            <radius>2.6192668772813574</radius>\n            <length>2.4394143624854721</length>\n          </cylinder>\n        </geometry>\n        <surface>\n          <contact>\n            <collide_bitmask>255</collide_bitmask>\n          </contact>\n          <friction>\n            <ode>\n              <mu>1</mu>\n              <mu2>1</mu2>\n              <slip1>0</slip1>\n              <slip2>0</slip2>\n              <fdir1>0 0 0</fdir1>\n            </ode>\n          </friction>\n        </surface>\n      </collision>\n      <visual name="visual_1031">\n        <pose>0 0 0 0 0 0</pose>\n        <geometry>\n          <cylinder>\n            <radius>2.6192668772813574</radius>\n            <length>2.4394143624854721</length>\n          </cylinder>\n        </geometry>\n        <cast_shadows>true</cast_shadows>\n        <laser_retro>0</laser_retro>\n        <transparency>0</transparency>\n        <visibility_flags>4294967295</visibility_flags>\n        <material>\n          <ambient>0.643970668 0.315666974 0.883563936 1</ambient>\n          <diffuse>0.643970668 0.315666974 0.883563936 1</diffuse>\n          <specular>0 0 0 1</specular>\n          <emissive>0 0 0 1</emissive>\n          <render_order>0</render_order>\n          <lighting>true</lighting>\n          <double_sided>false</double_sided>\n          <shader type="pixel"/>\n        </material>\n      </visual>\n    </link>\n    <joint name="joint_686" type="screw">\n      <pose>0 0 0 0 0 0</pose>\n      <parent>link_1030</parent>\n      <child>link_1029</child>\n      <axis>\n        <xyz>0.63279247992995069 0.31496973807818579 0.70736676585704961</xyz>\n        <limit>\n          <lower>-inf</lower>\n          <upper>inf</upper>\n          <effort>inf</effort>\n          <velocity>2.9300662511878572</velocity>\n          <stiffness>100000000</stiffness>\n          <dissipation>1</dissipation>\n        </limit>\n        <dynamics>\n          <spring_reference>0</spring_reference>\n          <spring_stiffness>0</spring_stiffness>\n          <damping>0</damping>\n          <friction>0</friction>\n        </dynamics>\n      </axis>\n      <axis2>\n        <xyz>0.75621461546314894 0.33592524214533936 0.56151018427942756</xyz>\n        <limit>\n          <lower>-inf</lower>\n          <upper>inf</upper>\n          <effort>inf</effort>\n          <velocity>7.2853338751580647</velocity>\n          <stiffness>100000000</stiffness>\n          <dissipation>1</dissipation>\n        </limit>\n        <dynamics>\n          <spring_reference>0</spring_reference>\n          <spring_stiffness>0</spring_stiffness>\n          <damping>0</damping>\n          <friction>0</friction>\n        </dynamics>\n      </axis2>\n      <thread_pitch>-6.2831853071795862</thread_pitch>\n    </joint>\n    <joint name="joint_687" type="continuous">\n      <pose>0 0 0 0 0 0</pose>\n      <parent>link_1030</parent>\n      <child>link_1029</child>\n      <axis>\n        <xyz>0.78103223557101809 0.36523537629958008 0.50654887908102386</xyz>\n        <limit>\n          <lower>-inf</lower>\n          <upper>inf</upper>\n          <effort>inf</effort>\n          <velocity>2.8329494899340526</velocity>\n          <stiffness>100000000</stiffness>\n          <dissipation>1</dissipation>\n        </limit>\n        <dynamics>\n          <spring_reference>0</spring_reference>\n          <spring_stiffness>0</spring_stiffness>\n          <damping>0</damping>\n          <friction>0</friction>\n        </dynamics>\n      </axis>\n      <axis2>\n        <xyz>0.10410907976905005 0.65333445605224283 0.74987691526313927</xyz>\n        <limit>\n          <lower>-inf</lower>\n          <upper>inf</upper>\n          <effort>inf</effort>\n          <velocity>0.9238098351706725</velocity>\n          <stiffness>100000000</stiffness>\n          <dissipation>1</dissipation>\n        </limit>\n        <dynamics>\n          <spring_reference>0</spring_reference>\n          <spring_stiffness>0</spring_stiffness>\n          <damping>0</damping>\n          <friction>0</friction>\n        </dynamics>\n      </axis2>\n    </joint>\n  </model>\n</sdf>\n"[0m[1;31m[0m
gz sim server: ./dart/constraint/JointConstraint.cpp:207: virtual void dart::constraint::JointConstraint::update(): Assertion `positionLowerLimits[i] <= positionUpperLimits[i]' failed.
Stack trace (most recent call last):
#31   Object "/lib/x86_64-linux-gnu/libruby-3.0.so.3.0", at 0x761904234c96, in 
#30   Object "/lib/x86_64-linux-gnu/libruby-3.0.so.3.0", at 0x761904231fc5, in 
#29   Object "/lib/x86_64-linux-gnu/libruby-3.0.so.3.0", at 0x76190422fc34, in 
#28   Object "/lib/x86_64-linux-gnu/libruby-3.0.so.3.0", at 0x76190417ba4e, in 
#27   Object "/lib/x86_64-linux-gnu/libruby-3.0.so.3.0", at 0x7619040a69ac, in rb_protect
#26   Object "/lib/x86_64-linux-gnu/libruby-3.0.so.3.0", at 0x76190423ec61, in rb_yield
#25   Object "/lib/x86_64-linux-gnu/libruby-3.0.so.3.0", at 0x76190423a30c, in rb_vm_exec
#24   Object "/lib/x86_64-linux-gnu/libruby-3.0.so.3.0", at 0x761904234c96, in 
#23   Object "/lib/x86_64-linux-gnu/libruby-3.0.so.3.0", at 0x761904231fc5, in 
#22   Object "/lib/x86_64-linux-gnu/libruby-3.0.so.3.0", at 0x76190422fc34, in 
#21   Object "/usr/lib/x86_64-linux-gnu/ruby/3.0.0/fiddle.so", at 0x76190438744b, in 
#20   Object "/lib/x86_64-linux-gnu/libruby-3.0.so.3.0", at 0x7619041fd088, in rb_nogvl
#19   Object "/usr/lib/x86_64-linux-gnu/ruby/3.0.0/fiddle.so", at 0x761904386d6b, in 
#18   Object "/lib/x86_64-linux-gnu/libffi.so.8", at 0x761903e37492, in 
#17   Object "/lib/x86_64-linux-gnu/libffi.so.8", at 0x761903e3ae2d, in 
#16   Object "/usr/lib/x86_64-linux-gnu/libgz-sim8-gz.so.8.6.0", at 0x761903ab3605, in runServer
#15   Object "/lib/x86_64-linux-gnu/libgz-sim8.so.8", at 0x7618fe53d485, in 
#14   Object "/lib/x86_64-linux-gnu/libgz-sim8.so.8", at 0x7618fe54d8a2, in gz::sim::v8::SimulationRunner::Run(unsigned long)
#13   Object "/lib/x86_64-linux-gnu/libgz-sim8.so.8", at 0x7618fe54ce60, in gz::sim::v8::SimulationRunner::Step(gz::sim::v8::UpdateInfo const&)
#12   Object "/lib/x86_64-linux-gnu/libgz-sim8.so.8", at 0x7618fe54c0a2, in gz::sim::v8::SimulationRunner::UpdateSystems()
#11   Object "/usr/lib/x86_64-linux-gnu/gz-sim-8/plugins/libgz-sim-physics-system.so", at 0x7618f591f5b6, in gz::sim::v8::systems::Physics::Update(gz::sim::v8::UpdateInfo const&, gz::sim::v8::EntityComponentManager&)
#10   Object "/usr/lib/x86_64-linux-gnu/gz-sim-8/plugins/libgz-sim-physics-system.so", at 0x7618f591fc31, in gz::sim::v8::systems::PhysicsPrivate::Step(std::chrono::duration<long, std::ratio<1l, 1000000000l> > const&)
#9    Object "/usr/lib/x86_64-linux-gnu/gz-physics-7/engine-plugins/libgz-physics-dartsim-plugin.so", at 0x7618be00900b, in gz::physics::dartsim::SimulationFeatures::WorldForwardStep(gz::physics::Identity const&, gz::physics::SpecifyData<gz::physics::RequireData<gz::physics::WorldPoses>, gz::physics::ExpectData<gz::physics::ChangedWorldPoses, gz::physics::Contacts, gz::physics::JointPositions> >&, gz::physics::CompositeData&, gz::physics::ExpectData<gz::physics::ApplyExternalForceTorques, gz::physics::ApplyGeneralizedForces, gz::physics::VelocityControlCommands, gz::physics::ServoControlCommands, std::chrono::duration<long, std::ratio<1l, 1000000000l> > > const&)
#8    Object "/lib/x86_64-linux-gnu/libdart.so.6.13", at 0x7618bdb936d3, in dart::simulation::World::step(bool)
#7    Object "/lib/x86_64-linux-gnu/libdart.so.6.13", at 0x7618bdb78ca5, in dart::constraint::ConstraintSolver::solve()
#6    Object "/lib/x86_64-linux-gnu/libdart.so.6.13", at 0x7618bdb77d33, in dart::constraint::ConstraintSolver::updateConstraints()
#5    Object "/lib/x86_64-linux-gnu/libdart.so.6.13", at 0x7618bdb86256, in dart::constraint::JointConstraint::update()
#4    Object "/lib/x86_64-linux-gnu/libc.so.6", at 0x761903c39e95, in __assert_fail
#3    Object "/lib/x86_64-linux-gnu/libc.so.6", at 0x761903c2871a, in 
#2    Object "/lib/x86_64-linux-gnu/libc.so.6", at 0x761903c287f2, in abort
#1    Object "/lib/x86_64-linux-gnu/libc.so.6", at 0x761903c42475, in raise
#0    Object "/lib/x86_64-linux-gnu/libc.so.6", at 0x761903c969fc, in pthread_kill
Aborted (Signal sent by tkill() 480289 1000)
