Warning: Ignoring XDG_SESSION_TYPE=wayland on Gnome. Use QT_QPA_PLATFORM=wayland to run on Wayland anyway.
[1;31m[Err] [UserCommands.cc:1145] [0m[1;31mError Code [0m[1;31m30[0m[1;31m: [0m[1;31mMsg: [0m[1;31mError parsing XML from string: Error=XML_ERROR_PARSING_TEXT ErrorID=8 (0x8) Line number=1[0m[1;31m[0m
[1;31m[Err] [UserCommands.cc:1145] [0m[1;31mError Code [0m[1;31m30[0m[1;31m: [0m[1;31mMsg: [0m[1;31mUnable to read SDF string: b"<sdf version="1.11">\n  <model name="model">\n    <static>true</static>\n    <self_collide>false</self_collide>\n    <allow_auto_disable>true</allow_auto_disable>\n    <enable_wind>false</enable_wind>\n    <pose>-8.1159530445963934 -5.3354422776451589 8.5522896894757601 0 0 0</pose>\n    <link name="link_3675">\n      <pose>-9.7860385467154778 -6.9582735695753817 3.3984995859722558 0 0 0</pose>\n      <inertial>\n        <pose>0 0 0 0 0 0</pose>\n        <mass>1</mass>\n        <inertia>\n          <ixx>1</ixx>\n          <ixy>0</ixy>\n          <ixz>0</ixz>\n          <iyy>1</iyy>\n          <iyz>0</iyz>\n          <izz>1</izz>\n        </inertia>\n      </inertial>\n      <enable_wind>false</enable_wind>\n      <collision name="collision_3675">\n        <pose>0 0 0 0 0 0</pose>\n        <geometry>\n          <sphere>\n            <radius>1.6280086205159987</radius>\n          </sphere>\n        </geometry>\n        <surface>\n          <contact>\n            <collide_bitmask>255</collide_bitmask>\n          </contact>\n          <friction>\n            <ode>\n              <mu>1</mu>\n              <mu2>1</mu2>\n              <slip1>0</slip1>\n              <slip2>0</slip2>\n              <fdir1>0 0 0</fdir1>\n            </ode>\n          </friction>\n        </surface>\n      </collision>\n      <visual name="visual_3675">\n        <pose>0 0 0 0 0 0</pose>\n        <geometry>\n          <sphere>\n            <radius>1.6280086205159987</radius>\n          </sphere>\n        </geometry>\n        <cast_shadows>true</cast_shadows>\n        <laser_retro>0</laser_retro>\n        <transparency>0</transparency>\n        <visibility_flags>4294967295</visibility_flags>\n        <material>\n          <ambient>0.180191308 0.644760251 0.0796050653 1</ambient>\n          <diffuse>0.180191308 0.644760251 0.0796050653 1</diffuse>\n          <specular>0 0 0 1</specular>\n          <emissive>0 0 0 1</emissive>\n          <render_order>0</render_order>\n          <lighting>true</lighting>\n          <double_sided>false</double_sided>\n          <shader type="pixel"/>\n        </material>\n      </visual>\n    </link>\n    <link name="link_3676">\n      <pose>0.10176593594050942 3.2924507740178157 6.225530371489139 0 0 0</pose>\n      <inertial>\n        <pose>0 0 0 0 0 0</pose>\n        <mass>1</mass>\n        <inertia>\n          <ixx>1</ixx>\n          <ixy>0</ixy>\n          <ixz>0</ixz>\n          <iyy>1</iyy>\n          <iyz>0</iyz>\n          <izz>1</izz>\n        </inertia>\n      </inertial>\n      <enable_wind>false</enable_wind>\n      <collision name="collision_3676">\n        <pose>0 0 0 0 0 0</pose>\n        <geometry>\n          <sphere>\n            <radius>1.4341349640025305</radius>\n          </sphere>\n        </geometry>\n        <surface>\n          <contact>\n            <collide_bitmask>255</collide_bitmask>\n          </contact>\n          <friction>\n            <ode>\n              <mu>1</mu>\n              <mu2>1</mu2>\n              <slip1>0</slip1>\n              <slip2>0</slip2>\n              <fdir1>0 0 0</fdir1>\n            </ode>\n          </friction>\n        </surface>\n      </collision>\n      <visual name="visual_3676">\n        <pose>0 0 0 0 0 0</pose>\n        <geometry>\n          <sphere>\n            <radius>1.4341349640025305</radius>\n          </sphere>\n        </geometry>\n        <cast_shadows>true</cast_shadows>\n        <laser_retro>0</laser_retro>\n        <transparency>0</transparency>\n        <visibility_flags>4294967295</visibility_flags>\n        <material>\n          <ambient>0.859541833 0.663855135 0.58853215 1</ambient>\n          <diffuse>0.859541833 0.663855135 0.58853215 1</diffuse>\n          <specular>0 0 0 1</specular>\n          <emissive>0 0 0 1</emissive>\n          <render_order>0</render_order>\n          <lighting>true</lighting>\n          <double_sided>false</double_sided>\n          <shader type="pixel"/>\n        </material>\n      </visual>\n    </link>\n    <link name="link_3677">\n      <pose>-2.0710498856482822 -3.5432304409870934 8.8733669352479101 0 0 0</pose>\n      <inertial>\n        <pose>0 0 0 0 0 0</pose>\n        <mass>1</mass>\n        <inertia>\n          <ixx>1</ixx>\n          <ixy>0</ixy>\n          <ixz>0</ixz>\n          <iyy>1</iyy>\n          <iyz>0</iyz>\n          <izz>1</izz>\n        </inertia>\n      </inertial>\n      <enable_wind>false</enable_wind>\n      <collision name="collision_3677">\n        <pose>0 0 0 0 0 0</pose>\n        <geometry>\n          <box>\n            <size>1.4083331475202676 2.4046313928735685 2.4082340150728823</size>\n          </box>\n        </geometry>\n        <surface>\n          <contact>\n            <collide_bitmask>255</collide_bitmask>\n          </contact>\n          <friction>\n            <ode>\n              <mu>1</mu>\n              <mu2>1</mu2>\n              <slip1>0</slip1>\n              <slip2>0</slip2>\n              <fdir1>0 0 0</fdir1>\n            </ode>\n          </friction>\n        </surface>\n      </collision>\n      <visual name="visual_3677">\n        <pose>0 0 0 0 0 0</pose>\n        <geometry>\n          <box>\n            <size>1.4083331475202676 2.4046313928735685 2.4082340150728823</size>\n          </box>\n        </geometry>\n        <cast_shadows>true</cast_shadows>\n        <laser_retro>0</laser_retro>\n        <transparency>0</transparency>\n        <visibility_flags>4294967295</visibility_flags>\n        <material>\n          <ambient>0.939361572 0.196595535 0.531744063 1</ambient>\n          <diffuse>0.939361572 0.196595535 0.531744063 1</diffuse>\n          <specular>0 0 0 1</specular>\n          <emissive>0 0 0 1</emissive>\n          <render_order>0</render_order>\n          <lighting>true</lighting>\n          <double_sided>false</double_sided>\n          <shader type="pixel"/>\n        </material>\n      </visual>\n    </link>\n    <joint name="joint_2450" type="universal">\n      <pose>0 0 0 0 0 0</pose>\n      <parent>link_3676</parent>\n      <child>link_3677</child>\n      <axis>\n        <xyz>0.59261250463067627 0.78369158106347991 0.18611266782672212</xyz>\n        <limit>\n          <lower>-inf</lower>\n          <upper>inf</upper>\n          <effort>inf</effort>\n          <velocity>4.2422452351603024</velocity>\n          <stiffness>100000000</stiffness>\n          <dissipation>1</dissipation>\n        </limit>\n        <dynamics>\n          <spring_reference>0</spring_reference>\n          <spring_stiffness>0</spring_stiffness>\n          <damping>0</damping>\n          <friction>0</friction>\n        </dynamics>\n      </axis>\n      <axis2>\n        <xyz>0.40298845533056693 0.55643256332764146 0.72662446101057854</xyz>\n        <limit>\n          <lower>-inf</lower>\n          <upper>inf</upper>\n          <effort>inf</effort>\n          <velocity>1.5125274089059637</velocity>\n          <stiffness>100000000</stiffness>\n          <dissipation>1</dissipation>\n        </limit>\n        <dynamics>\n          <spring_reference>0</spring_reference>\n          <spring_stiffness>0</spring_stiffness>\n          <damping>0</damping>\n          <friction>0</friction>\n        </dynamics>\n      </axis2>\n    </joint>\n    <joint name="joint_2451" type="screw">\n      <pose>0 0 0 0 0 0</pose>\n      <parent>link_3675</parent>\n      <child>link_3676</child>\n      <axis>\n        <xyz>0.23133501741351545 0.88298540543734139 0.40843712307152297</xyz>\n        <limit>\n          <lower>-inf</lower>\n          <upper>inf</upper>\n          <effort>inf</effort>\n          <velocity>6.941646988652991</velocity>\n          <stiffness>100000000</stiffness>\n          <dissipation>1</dissipation>\n        </limit>\n        <dynamics>\n          <spring_reference>0</spring_reference>\n          <spring_stiffness>0</spring_stiffness>\n          <damping>0</damping>\n          <friction>0</friction>\n        </dynamics>\n      </axis>\n      <axis2>\n        <xyz>0.54698120295435781 0.64614738305376862 0.53226414775689157</xyz>\n        <limit>\n          <lower>-inf</lower>\n          <upper>inf</upper>\n          <effort>inf</effort>\n          <velocity>4.2331938763960295</velocity>\n          <stiffness>100000000</stiffness>\n          <dissipation>1</dissipation>\n        </limit>\n        <dynamics>\n          <spring_reference>0</spring_reference>\n          <spring_stiffness>0</spring_stiffness>\n          <damping>0</damping>\n          <friction>0</friction>\n        </dynamics>\n      </axis2>\n      <thread_pitch>-6.2831853071795862</thread_pitch>\n    </joint>\n  </model>\n</sdf>\n"[0m[1;31m[0m
[1;31m[Err] [UserCommands.cc:1145] [0m[1;31mError Code [0m[1;31m30[0m[1;31m: [0m[1;31mMsg: [0m[1;31mError parsing XML from string: Error=XML_ERROR_PARSING_TEXT ErrorID=8 (0x8) Line number=1[0m[1;31m[0m
[1;31m[Err] [UserCommands.cc:1145] [0m[1;31mError Code [0m[1;31m30[0m[1;31m: [0m[1;31mMsg: [0m[1;31mUnable to read SDF string: b"<sdf version="1.11">\n  <model name="model">\n    <static>true</static>\n    <self_collide>false</self_collide>\n    <allow_auto_disable>true</allow_auto_disable>\n    <enable_wind>false</enable_wind>\n    <pose>9.7319889271041795 -9.5693216216520973 6.4225942159714258 0 0 0</pose>\n    <link name="link_3678">\n      <pose>5.1964347749461091 -1.288720133587379 1.8860145989982835 0 0 0</pose>\n      <inertial>\n        <pose>0 0 0 0 0 0</pose>\n        <mass>1</mass>\n        <inertia>\n          <ixx>1</ixx>\n          <ixy>0</ixy>\n          <ixz>0</ixz>\n          <iyy>1</iyy>\n          <iyz>0</iyz>\n          <izz>1</izz>\n        </inertia>\n      </inertial>\n      <enable_wind>false</enable_wind>\n      <collision name="collision_3678">\n        <pose>0 0 0 0 0 0</pose>\n        <geometry>\n          <capsule>\n            <radius>1.4510711819738242</radius>\n            <length>2.8173604472009548</length>\n          </capsule>\n        </geometry>\n        <surface>\n          <contact>\n            <collide_bitmask>255</collide_bitmask>\n          </contact>\n          <friction>\n            <ode>\n              <mu>1</mu>\n              <mu2>1</mu2>\n              <slip1>0</slip1>\n              <slip2>0</slip2>\n              <fdir1>0 0 0</fdir1>\n            </ode>\n          </friction>\n        </surface>\n      </collision>\n      <visual name="visual_3678">\n        <pose>0 0 0 0 0 0</pose>\n        <geometry>\n          <capsule>\n            <radius>1.4510711819738242</radius>\n            <length>2.8173604472009548</length>\n          </capsule>\n        </geometry>\n        <cast_shadows>true</cast_shadows>\n        <laser_retro>0</laser_retro>\n        <transparency>0</transparency>\n        <visibility_flags>4294967295</visibility_flags>\n        <material>\n          <ambient>0.0866474584 0.270516843 0.977660716 1</ambient>\n          <diffuse>0.0866474584 0.270516843 0.977660716 1</diffuse>\n          <specular>0 0 0 1</specular>\n          <emissive>0 0 0 1</emissive>\n          <render_order>0</render_order>\n          <lighting>true</lighting>\n          <double_sided>false</double_sided>\n          <shader type="pixel"/>\n        </material>\n      </visual>\n    </link>\n    <link name="link_3679">\n      <pose>7.236980314085816 3.4219089779780827 8.7509508847503827 0 0 0</pose>\n      <inertial>\n        <pose>0 0 0 0 0 0</pose>\n        <mass>1</mass>\n        <inertia>\n          <ixx>1</ixx>\n          <ixy>0</ixy>\n          <ixz>0</ixz>\n          <iyy>1</iyy>\n          <iyz>0</iyz>\n          <izz>1</izz>\n        </inertia>\n      </inertial>\n      <enable_wind>false</enable_wind>\n      <collision name="collision_3679">\n        <pose>0 0 0 0 0 0</pose>\n        <geometry>\n          <sphere>\n            <radius>2.7176208207398176</radius>\n          </sphere>\n        </geometry>\n        <surface>\n          <contact>\n            <collide_bitmask>255</collide_bitmask>\n          </contact>\n          <friction>\n            <ode>\n              <mu>1</mu>\n              <mu2>1</mu2>\n              <slip1>0</slip1>\n              <slip2>0</slip2>\n              <fdir1>0 0 0</fdir1>\n            </ode>\n          </friction>\n        </surface>\n      </collision>\n      <visual name="visual_3679">\n        <pose>0 0 0 0 0 0</pose>\n        <geometry>\n          <sphere>\n            <radius>2.7176208207398176</radius>\n          </sphere>\n        </geometry>\n        <cast_shadows>true</cast_shadows>\n        <laser_retro>0</laser_retro>\n        <transparency>0</transparency>\n        <visibility_flags>4294967295</visibility_flags>\n        <material>\n          <ambient>0.440126806 0.633174241 0.0541245192 1</ambient>\n          <diffuse>0.440126806 0.633174241 0.0541245192 1</diffuse>\n          <specular>0 0 0 1</specular>\n          <emissive>0 0 0 1</emissive>\n          <render_order>0</render_order>\n          <lighting>true</lighting>\n          <double_sided>false</double_sided>\n          <shader type="pixel"/>\n        </material>\n      </visual>\n    </link>\n    <link name="link_3680">\n      <pose>1.1189399577838817 0.99185042614939434 4.2836441470309028 0 0 0</pose>\n      <inertial>\n        <pose>0 0 0 0 0 0</pose>\n        <mass>1</mass>\n        <inertia>\n          <ixx>1</ixx>\n          <ixy>0</ixy>\n          <ixz>0</ixz>\n          <iyy>1</iyy>\n          <iyz>0</iyz>\n          <izz>1</izz>\n        </inertia>\n      </inertial>\n      <enable_wind>false</enable_wind>\n      <collision name="collision_3680">\n        <pose>0 0 0 0 0 0</pose>\n        <geometry>\n          <box>\n            <size>2.980618692808342 1.069441126720758 2.8992569431943886</size>\n          </box>\n        </geometry>\n        <surface>\n          <contact>\n            <collide_bitmask>255</collide_bitmask>\n          </contact>\n          <friction>\n            <ode>\n              <mu>1</mu>\n              <mu2>1</mu2>\n              <slip1>0</slip1>\n              <slip2>0</slip2>\n              <fdir1>0 0 0</fdir1>\n            </ode>\n          </friction>\n        </surface>\n      </collision>\n      <visual name="visual_3680">\n        <pose>0 0 0 0 0 0</pose>\n        <geometry>\n          <box>\n            <size>2.980618692808342 1.069441126720758 2.8992569431943886</size>\n          </box>\n        </geometry>\n        <cast_shadows>true</cast_shadows>\n        <laser_retro>0</laser_retro>\n        <transparency>0</transparency>\n        <visibility_flags>4294967295</visibility_flags>\n        <material>\n          <ambient>0.386412114 0.335658878 0.227332681 1</ambient>\n          <diffuse>0.386412114 0.335658878 0.227332681 1</diffuse>\n          <specular>0 0 0 1</specular>\n          <emissive>0 0 0 1</emissive>\n          <render_order>0</render_order>\n          <lighting>true</lighting>\n          <double_sided>false</double_sided>\n          <shader type="pixel"/>\n        </material>\n      </visual>\n    </link>\n    <joint name="joint_2452" type="ball">\n      <pose>0 0 0 0 0 0</pose>\n      <parent>link_3678</parent>\n      <child>link_3680</child>\n      <axis>\n        <xyz>0.34597561342448696 0.93168792631114028 0.11071803322673822</xyz>\n        <limit>\n          <lower>-inf</lower>\n          <upper>inf</upper>\n          <effort>inf</effort>\n          <velocity>8.3673564831834675</velocity>\n          <stiffness>100000000</stiffness>\n          <dissipation>1</dissipation>\n        </limit>\n        <dynamics>\n          <spring_reference>0</spring_reference>\n          <spring_stiffness>0</spring_stiffness>\n          <damping>0</damping>\n          <friction>0</friction>\n        </dynamics>\n      </axis>\n      <axis2>\n        <xyz>0.85912557249608601 0.3025699953907971 0.41274041305944986</xyz>\n        <limit>\n          <lower>-inf</lower>\n          <upper>inf</upper>\n          <effort>inf</effort>\n          <velocity>7.0400258963466777</velocity>\n          <stiffness>100000000</stiffness>\n          <dissipation>1</dissipation>\n        </limit>\n        <dynamics>\n          <spring_reference>0</spring_reference>\n          <spring_stiffness>0</spring_stiffness>\n          <damping>0</damping>\n          <friction>0</friction>\n        </dynamics>\n      </axis2>\n    </joint>\n    <joint name="joint_2453" type="screw">\n      <pose>0 0 0 0 0 0</pose>\n      <parent>link_3680</parent>\n      <child>link_3679</child>\n      <axis>\n        <xyz>0.97319419458166134 0.11024608983434238 0.20183869626211259</xyz>\n        <limit>\n          <lower>-inf</lower>\n          <upper>gdr</upper>\n          <effort>inf</effort>\n          <velocity>3.7753895257570971</velocity>\n          <stiffness>100000000</stiffness>\n          <dissipation>1</dissipation>\n        </limit>\n        <dynamics>\n          <spring_reference>0</spring_reference>\n          <spring_stiffness>0</spring_stiffness>\n          <damping>0</damping>\n          <friction>0</friction>\n        </dynamics>\n      </axis>\n      <axis2>\n        <xyz>0.024645839815995392 0.66040023185191266 0.75050923801756386</xyz>\n        <limit>\n          <lower>-inf</lower>\n          <upper>inf</upper>\n          <effort>inf</effort>\n          <velocity>7.6595223003556177</velocity>\n          <stiffness>100000000</stiffness>\n          <dissipation>1</dissipation>\n        </limit>\n        <dynamics>\n          <spring_reference>0</spring_reference>\n          <spring_stiffness>0</spring_stiffness>\n          <damping>0</damping>\n          <friction>0</friction>\n        </dynamics>\n      </axis2>\n      <thread_pitch>-6.2831853071795862</thread_pitch>\n    </joint>\n  </model>\n</sdf>\n"[0m[1;31m[0m
Stack trace (most recent call last):
#30   Object "[0xffffffffffffffff]", at 0xffffffffffffffff, in 
#29   Object "gz sim server", at 0x5e3888ba61c4, in _start
#28   Object "/lib/x86_64-linux-gnu/libc.so.6", at 0x79514d829e3f, in __libc_start_main
#27   Object "/lib/x86_64-linux-gnu/libc.so.6", at 0x79514d829d8f, in 
#26   Object "gz sim server", at 0x5e3888ba617e, in 
#25   Object "/lib/x86_64-linux-gnu/libruby-3.0.so.3.0", at 0x79514dca8e19, in ruby_run_node
#24   Object "/lib/x86_64-linux-gnu/libruby-3.0.so.3.0", at 0x79514dca5317, in 
#23   Object "/lib/x86_64-linux-gnu/libruby-3.0.so.3.0", at 0x79514de3a30c, in rb_vm_exec
#22   Object "/lib/x86_64-linux-gnu/libruby-3.0.so.3.0", at 0x79514de34c96, in 
#21   Object "/lib/x86_64-linux-gnu/libruby-3.0.so.3.0", at 0x79514de31fc5, in 
#20   Object "/lib/x86_64-linux-gnu/libruby-3.0.so.3.0", at 0x79514de2fc34, in 
#19   Object "/lib/x86_64-linux-gnu/libruby-3.0.so.3.0", at 0x79514dd7ba4e, in 
#18   Object "/lib/x86_64-linux-gnu/libruby-3.0.so.3.0", at 0x79514dca69ac, in rb_protect
#17   Object "/lib/x86_64-linux-gnu/libruby-3.0.so.3.0", at 0x79514de3ec61, in rb_yield
#16   Object "/lib/x86_64-linux-gnu/libruby-3.0.so.3.0", at 0x79514de3a30c, in rb_vm_exec
#15   Object "/lib/x86_64-linux-gnu/libruby-3.0.so.3.0", at 0x79514de34c96, in 
#14   Object "/lib/x86_64-linux-gnu/libruby-3.0.so.3.0", at 0x79514de31fc5, in 
#13   Object "/lib/x86_64-linux-gnu/libruby-3.0.so.3.0", at 0x79514de2fc34, in 
#12   Object "/usr/lib/x86_64-linux-gnu/ruby/3.0.0/fiddle.so", at 0x79514daaf44b, in 
#11   Object "/lib/x86_64-linux-gnu/libruby-3.0.so.3.0", at 0x79514ddfd088, in rb_nogvl
#10   Object "/usr/lib/x86_64-linux-gnu/ruby/3.0.0/fiddle.so", at 0x79514daaed6b, in 
#9    Object "/lib/x86_64-linux-gnu/libffi.so.8", at 0x79514daa0492, in 
#8    Object "/lib/x86_64-linux-gnu/libffi.so.8", at 0x79514daa3e2d, in 
#7    Object "/usr/lib/x86_64-linux-gnu/libgz-sim8-gz.so.8.6.0", at 0x79514d6d3605, in runServer
#6    Object "/lib/x86_64-linux-gnu/libgz-sim8.so.8", at 0x79514813d485, in 
#5    Object "/lib/x86_64-linux-gnu/libgz-sim8.so.8", at 0x79514814d8a2, in gz::sim::v8::SimulationRunner::Run(unsigned long)
#4    Object "/lib/x86_64-linux-gnu/libgz-sim8.so.8", at 0x79514814ce60, in gz::sim::v8::SimulationRunner::Step(gz::sim::v8::UpdateInfo const&)
#3    Object "/lib/x86_64-linux-gnu/libgz-sim8.so.8", at 0x79514814c031, in gz::sim::v8::SimulationRunner::UpdateSystems()
#2    Object "/usr/lib/x86_64-linux-gnu/gz-sim-8/plugins/libgz-sim-user-commands-system.so", at 0x795136055210, in gz::sim::v8::systems::UserCommands::PreUpdate(gz::sim::v8::UpdateInfo const&, gz::sim::v8::EntityComponentManager&)
#1    Object "/usr/lib/x86_64-linux-gnu/gz-sim-8/plugins/libgz-sim-user-commands-system.so", at 0x795136063535, in gz::sim::v8::systems::EnableCollisionCommand::Execute()
#0    Object "/usr/lib/x86_64-linux-gnu/gz-sim-8/plugins/libgz-sim-user-commands-system.so", at 0x79513605dbd4, in gz::sim::v8::systems::UserCommandsInterface::HasContactSensor(unsigned long)
Segmentation fault (Address not mapped to object [0x8])
