Warning: Ignoring XDG_SESSION_TYPE=wayland on Gnome. Use QT_QPA_PLATFORM=wayland to run on Wayland anyway.
[1;31m[Err] [UserCommands.cc:1145] [0m[1;31mError Code [0m[1;31m30[0m[1;31m: [0m[1;31mMsg: [0m[1;31mError parsing XML from string: Error=XML_ERROR_PARSING_TEXT ErrorID=8 (0x8) Line number=1[0m[1;31m[0m
[1;31m[Err] [UserCommands.cc:1145] [0m[1;31mError Code [0m[1;31m30[0m[1;31m: [0m[1;31mMsg: [0m[1;31mUnable to read SDF string: b"<sdf version="1.11">\n  <model name="model">\n    <static>true</static>\n    <self_collide>true</self_collide>\n    <allow_auto_disable>true</allow_auto_disable>\n    <enable_wind>true</enable_wind>\n    <pose>-2.4410151771855553 4.9832443820275714 9.4536412299281185 0 0 0</pose>\n    <link name="link_3045">\n      <pose>-5.8411371402851042 -3.2064100747361035 0.96005700850949283 0 0 0</pose>\n      <inertial>\n        <pose>0 0 0 0 0 0</pose>\n        <mass>1</mass>\n        <inertia>\n          <ixx>1</ixx>\n          <ixy>0</ixy>\n          <ixz>0</ixz>\n          <iyy>1</iyy>\n          <iyz>490576</iyz>\n          <izz>1</izz>\n        </inertia>\n      </inertial>\n      <enable_wind>false</enable_wind>\n      <collision name="collision_3045">\n        <pose>0 0 0 0 0 0</pose>\n        <geometry>\n          <sphere>\n            <radius>2.3890242804463071</radius>\n          </sphere>\n        </geometry>\n        <surface>\n          <contact>\n            <collide_bitmask>255</collide_bitmask>\n          </contact>\n          <friction>\n            <ode>\n              <mu>1</mu>\n              <mu2>1</mu2>\n              <slip1>0</slip1>\n              <slip2>0</slip2>\n              <fdir1>0 0 0</fdir1>\n            </ode>\n          </friction>\n        </surface>\n      </collision>\n      <visual name="visual_3045">\n        <pose>0 0 0 0 0 0</pose>\n        <geometry>\n          <sphere>\n            <radius>2.3890242804463071</radius>\n          </sphere>\n        </geometry>\n        <cast_shadows>true</cast_shadows>\n        <laser_retro>0</laser_retro>\n        <transparency>0</transparency>\n        <visibility_flags>4294967295</visibility_flags>\n        <material>\n          <ambient>0.359925807 0.555286288 0.472201586 1</ambient>\n          <diffuse>0.359925807 0.555286288 0.472201586 1</diffuse>\n          <specular>0 0 0 1</specular>\n          <emissive>0 0 0 1</emissive>\n          <render_order>0</render_order>\n          <lighting>true</lighting>\n          <double_sided>false</double_sided>\n          <shader type="pixel"/>\n        </material>\n      </visual>\n    </link>\n    <link name="link_3046">\n      <pose>-3.9864076544719707 8.2441703188015367 9.2718732054526356 0 0 0</pose>\n      <inertial>\n        <pose>0 0 0 0 0 0</pose>\n        <mass>1</mass>\n        <inertia>\n          <ixx>1</ixx>\n          <ixy>0</ixy>\n          <ixz>0</ixz>\n          <iyy>1</iyy>\n          <iyz>0</iyz>\n          <izz>1</izz>\n        </inertia>\n      </inertial>\n      <enable_wind>false</enable_wind>\n      <collision name="collision_3046">\n        <pose>0 0 0 0 0 0</pose>\n        <geometry>\n          <box>\n            <size>1.1188174011551866 1.5200011640905173 2.1634447092843776</size>\n          </box>\n        </geometry>\n        <surface>\n          <contact>\n            <collide_bitmask>255</collide_bitmask>\n          </contact>\n          <friction>\n            <ode>\n              <mu>1</mu>\n              <mu2>1</mu2>\n              <slip1>0</slip1>\n              <slip2>0</slip2>\n              <fdir1>0 0 0</fdir1>\n            </ode>\n          </friction>\n        </surface>\n      </collision>\n      <visual name="visual_3046">\n        <pose>0 0 0 0 0 0</pose>\n        <geometry>\n          <box>\n            <size>1.1188174011551866 1.5200011640905173 2.1634447092843776</size>\n          </box>\n        </geometry>\n        <cast_shadows>true</cast_shadows>\n        <laser_retro>0</laser_retro>\n        <transparency>0</transparency>\n        <visibility_flags>4294967295</visibility_flags>\n        <material>\n          <ambient>0.811227798 0.567750752 0.352209121 1</ambient>\n          <diffuse>0.811227798 0.567750752 0.352209121 1</diffuse>\n          <specular>0 0 0 1</specular>\n          <emissive>0 0 0 1</emissive>\n          <render_order>0</render_order>\n          <lighting>true</lighting>\n          <double_sided>false</double_sided>\n          <shader type="pixel"/>\n        </material>\n      </visual>\n    </link>\n    <link name="link_3047">\n      <pose>6.8097837610926923 -9.5258655925748918 6.6337806949521427 0 0 0</pose>\n      <inertial>\n        <pose>0 0 0 0 0 0</pose>\n        <mass>1</mass>\n        <inertia>\n          <ixx>1</ixx>\n          <ixy>0</ixy>\n          <ixz>0</ixz>\n          <iyy>1</iyy>\n          <iyz>0</iyz>\n          <izz>1</izz>\n        </inertia>\n      </inertial>\n      <enable_wind>false</enable_wind>\n      <collision name="collision_3047">\n        <pose>0 0 0 0 0 0</pose>\n        <geometry>\n          <box>\n            <size>1.0162828048896577 1.2207858947223098 1.1492280408616247</size>\n          </box>\n        </geometry>\n        <surface>\n          <contact>\n            <collide_bitmask>255</collide_bitmask>\n          </contact>\n          <friction>\n            <ode>\n              <mu>1</mu>\n              <mu2>1</mu2>\n              <slip1>0</slip1>\n              <slip2>0</slip2>\n              <fdir1>0 0 0</fdir1>\n            </ode>\n          </friction>\n        </surface>\n      </collision>\n      <visual name="visual_3047">\n        <pose>0 0 0 0 0 0</pose>\n        <geometry>\n          <box>\n            <size>1.0162828048896577 1.2207858947223098 1.1492280408616247</size>\n          </box>\n        </geometry>\n        <cast_shadows>true</cast_shadows>\n        <laser_retro>0</laser_retro>\n        <transparency>0</transparency>\n        <visibility_flags>4294967295</visibility_flags>\n        <material>\n          <ambient>0.416294187 0.929588675 0.165948525 1</ambient>\n          <diffuse>0.416294187 0.929588675 0.165948525 1</diffuse>\n          <specular>0 0 0 1</specular>\n          <emissive>0 0 0 1</emissive>\n          <render_order>0</render_order>\n          <lighting>true</lighting>\n          <double_sided>false</double_sided>\n          <shader type="pixel"/>\n        </material>\n      </visual>\n    </link>\n    <joint name="joint_2030" type="ball">\n      <pose>0 0 0 0 0 0</pose>\n      <parent>link_3047</parent>\n      <child>link_3046</child>\n      <axis>\n        <xyz>0.85342454958335989 0.1902486458789078 0.48525456299728004</xyz>\n        <limit>\n          <lower>-inf</lower>\n          <upper>inf</upper>\n          <effort>inf</effort>\n          <velocity>4.7829255949636442</velocity>\n          <stiffness>100000000</stiffness>\n          <dissipation>1</dissipation>\n        </limit>\n        <dynamics>\n          <spring_reference>0</spring_reference>\n          <spring_stiffness>0</spring_stiffness>\n          <damping>0</damping>\n          <friction>0</friction>\n        </dynamics>\n      </axis>\n      <axis2>\n        <xyz>0.55376436580992894 0.61586663194045421 0.56040460278396054</xyz>\n        <limit>\n          <lower>-inf</lower>\n          <upper>inf</upper>\n          <effort>inf</effort>\n          <velocity>3.9415622675980755</velocity>\n          <stiffness>100000000</stiffness>\n          <dissipation>1</dissipation>\n        </limit>\n        <dynamics>\n          <spring_reference>0</spring_reference>\n          <spring_stiffness>0</spring_stiffness>\n          <damping>0</damping>\n          <friction>0</friction>\n        </dynamics>\n      </axis2>\n    </joint>\n    <joint name="joint_2031" type="prismatic">\n      <pose>0 0 0 0 0 0</pose>\n      <parent>link_3046</parent>\n      <child>link_3045</child>\n      <axis>\n        <xyz>0.47672009307005497 0.84887549327321876 0.22836013177310027</xyz>\n        <limit>\n          <lower>-inf</lower>\n          <upper>inf</upper>\n          <effort>inf</effort>\n          <velocity>7.0618497502595439</velocity>\n          <stiffness>100000000</stiffness>\n          <dissipation>1</dissipation>\n        </limit>\n        <dynamics>\n          <spring_reference>0</spring_reference>\n          <spring_stiffness>0</spring_stiffness>\n          <damping>0</damping>\n          <friction>0</friction>\n        </dynamics>\n      </axis>\n      <axis2>\n        <xyz>0.60565851449129071 0.44407850321532688 0.6602817934838412</xyz>\n        <limit>\n          <lower>-inf</lower>\n          <upper>inf</upper>\n          <effort>inf</effort>\n          <velocity>2.3666750665372636</velocity>\n          <stiffness>100000000</stiffness>\n          <dissipation>1</dissipation>\n        </limit>\n        <dynamics>\n          <spring_reference>0</spring_reference>\n          <spring_stiffness>0</spring_stiffness>\n          <damping>0</damping>\n          <friction>0</friction>\n        </dynamics>\n      </axis2>\n    </joint>\n  </model>\n</sdf>\n"[0m[1;31m[0m
[1;31m[Err] [UserCommands.cc:1145] [0m[1;31mError Code [0m[1;31m30[0m[1;31m: [0m[1;31mMsg: [0m[1;31mError parsing XML from string: Error=XML_ERROR_PARSING_TEXT ErrorID=8 (0x8) Line number=1[0m[1;31m[0m
[1;31m[Err] [UserCommands.cc:1145] [0m[1;31mError Code [0m[1;31m30[0m[1;31m: [0m[1;31mMsg: [0m[1;31mUnable to read SDF string: b"<sdf version="1.11">\n  <model name="model">\n    <static>true</static>\n    <self_collide>true</self_collide>\n    <allow_auto_disable>true</allow_auto_disable>\n    <enable_wind>false</enable_wind>\n    <pose>-7.7772411273752944 -9.6259543826695158 7.2108459779964935 0 0 0</pose>\n    <link name="link_3048">\n      <pose>-8.6029616812014815 2.4268468306987359 6.7352248310294254 0 0 0</pose>\n      <inertial>\n        <pose>0 0 0 0 0 0</pose>\n        <mass>1</mass>\n        <inertia>\n          <ixx>1</ixx>\n          <ixy>0</ixy>\n          <ixz>0</ixz>\n          <iyy>1</iyy>\n          <iyz>0</iyz>\n          <izz>1</izz>\n        </inertia>\n      </inertial>\n      <enable_wind>false</enable_wind>\n      <collision name="collision_3048">\n        <pose>0 0 0 0 0 0</pose>\n        <geometry>\n          <sphere>\n            <radius>2.1210002041433773</radius>\n          </sphere>\n        </geometry>\n        <surface>\n          <contact>\n            <collide_bitmask>255</collide_bitmask>\n          </contact>\n          <friction>\n            <ode>\n              <mu>1</mu>\n              <mu2>1</mu2>\n              <slip1>0</slip1>\n              <slip2>0</slip2>\n              <fdir1>0 0 0</fdir1>\n            </ode>\n          </friction>\n        </surface>\n      </collision>\n      <visual name="visual_3048">\n        <pose>0 0 0 0 0 0</pose>\n        <geometry>\n          <sphere>\n            <radius>2.1210002041433773</radius>\n          </sphere>\n        </geometry>\n        <cast_shadows>true</cast_shadows>\n        <laser_retro>0</laser_retro>\n        <transparency>0</transparency>\n        <visibility_flags>4294967295</visibility_flags>\n        <material>\n          <ambient>0.0101073729 0.112981893 0.964054108 1</ambient>\n          <diffuse>0.0101073729 0.112981893 0.964054108 1</diffuse>\n          <specular>0 0 0 1</specular>\n          <emissive>0 0 0 1</emissive>\n          <render_order>0</render_order>\n          <lighting>true</lighting>\n          <double_sided>false</double_sided>\n          <shader type="pixel"/>\n        </material>\n      </visual>\n    </link>\n    <link name="link_3049">\n      <pose>1.8463555324045338 2.63018542636887 8.2978299908228639 0 0 0</pose>\n      <inertial>\n        <pose>0 0 0 0 0 0</pose>\n        <mass>1</mass>\n        <inertia>\n          <ixx>1</ixx>\n          <ixy>0</ixy>\n          <ixz>0</ixz>\n          <iyy>1</iyy>\n          <iyz>0</iyz>\n          <izz>1</izz>\n        </inertia>\n      </inertial>\n      <enable_wind>false</enable_wind>\n      <collision name="collision_3049">\n        <pose>0 0 0 0 0 0</pose>\n        <geometry>\n          <sphere>\n            <radius>1.8398602712043641</radius>\n          </sphere>\n        </geometry>\n        <surface>\n          <contact>\n            <collide_bitmask>255</collide_bitmask>\n          </contact>\n          <friction>\n            <ode>\n              <mu>1</mu>\n              <mu2>1</mu2>\n              <slip1>0</slip1>\n              <slip2>0</slip2>\n              <fdir1>0 0 0</fdir1>\n            </ode>\n          </friction>\n        </surface>\n      </collision>\n      <visual name="visual_3049">\n        <pose>0 0 0 0 0 0</pose>\n        <geometry>\n          <sphere>\n            <radius>1.8398602712043641</radius>\n          </sphere>\n        </geometry>\n        <cast_shadows>true</cast_shadows>\n        <laser_retro>0</laser_retro>\n        <transparency>0</transparency>\n        <visibility_flags>4294967295</visibility_flags>\n        <material>\n          <ambient>0.224750713 0.357548267 0.435320228 1</ambient>\n          <diffuse>0.224750713 0.357548267 0.435320228 1</diffuse>\n          <specular>0 0 0 1</specular>\n          <emissive>0 0 0 1</emissive>\n          <render_order>0</render_order>\n          <lighting>true</lighting>\n          <double_sided>false</double_sided>\n          <shader type="pixel"/>\n        </material>\n      </visual>\n    </link>\n    <link name="link_3050">\n      <pose>-9.5991452224432745 -1.5650589752077231 6.4552193978827432 0 0 0</pose>\n      <inertial>\n        <pose>0 0 0 0 0 0</pose>\n        <mass>1</mass>\n        <inertia>\n          <ixx>1</ixx>\n          <ixy>0</ixy>\n          <ixz>0</ixz>\n          <iyy>1</iyy>\n          <iyz>0</iyz>\n          <izz>1</izz>\n        </inertia>\n      </inertial>\n      <enable_wind>false</enable_wind>\n      <collision name="collision_3050">\n        <pose>0 0 0 0 0 0</pose>\n        <geometry>\n          <capsule>\n            <radius>2.3896388496208627</radius>\n            <length>1.2905144819411791</length>\n          </capsule>\n        </geometry>\n        <surface>\n          <contact>\n            <collide_bitmask>255</collide_bitmask>\n          </contact>\n          <friction>\n            <ode>\n              <mu>1</mu>\n              <mu2>1</mu2>\n              <slip1>0</slip1>\n              <slip2>0</slip2>\n              <fdir1>0 0 0</fdir1>\n            </ode>\n          </friction>\n        </surface>\n      </collision>\n      <visual name="visual_3050">\n        <pose>0 0 0 0 0 0</pose>\n        <geometry>\n          <capsule>\n            <radius>2.3896388496208627</radius>\n            <length>1.2905144819411791</length>\n          </capsule>\n        </geometry>\n        <cast_shadows>true</cast_shadows>\n        <laser_retro>0</laser_retro>\n        <transparency>0</transparency>\n        <visibility_flags>4294967295</visibility_flags>\n        <material>\n          <ambient>0.0445026271 0.130598858 0.104845695 1</ambient>\n          <diffuse>0.0445026271 0.130598858 0.104845695 1</diffuse>\n          <specular>0 0 0 1</specular>\n          <emissive>0 0 0 1</emissive>\n          <render_order>0</render_order>\n          <lighting>true</lighting>\n          <double_sided>false</double_sided>\n          <shader type="pixel"/>\n        </material>\n      </visual>\n    </link>\n    <joint name="joint_2032" type="revolute">\n      <pose>0 0 0 0 0 0</pose>\n      <parent>link_3049</parent>\n      <child>link_3048</child>\n      <axis>\n        <xyz>0.37084217543316428 0.34522080887324286 0.86214771010593194</xyz>\n        <limit>\n          <lower>-inf</lower>\n          <upper>inf</upper>\n          <effort>inf</effort>\n          <velocity>8.365810509662154</velocity>\n          <stiffness>100000000</stiffness>\n          <dissipation>1</dissipation>\n        </limit>\n        <dynamics>\n          <spring_reference>0</spring_reference>\n          <spring_stiffness>0</spring_stiffness>\n          <damping>0</damping>\n          <friction>0</friction>\n        </dynamics>\n      </axis>\n      <axis2>\n        <xyz>0.44497765764893116 0.7554656434858894 0.48090180463970178</xyz>\n        <limit>\n          <lower>-inf</lower>\n          <upper>inf</upper>\n          <effort>inf</effort>\n          <velocity>2.9747253819612238</velocity>\n          <stiffness>100000000</stiffness>\n          <dissipation>1</dissipation>\n        </limit>\n        <dynamics>\n          <spring_reference>0</spring_reference>\n          <spring_stiffness>0</spring_stiffness>\n          <damping>0</damping>\n          <friction>0</friction>\n        </dynamics>\n      </axis2>\n    </joint>\n    <joint name="joint_2033" type="continuous">\n      <pose>0 0 0 0 0 0</pose>\n      <parent>-3050</parent>\n      <child>link_3048</child>\n      <axis>\n        <xyz>0.63944476224200109 0.29124882443366651 0.71153673011818452</xyz>\n        <limit>\n          <lower>-inf</lower>\n          <upper>inf</upper>\n          <effort>inf</effort>\n          <velocity>6.9032746372158211</velocity>\n          <stiffness>100000000</stiffness>\n          <dissipation>1</dissipation>\n        </limit>\n        <dynamics>\n          <spring_reference>0</spring_reference>\n          <spring_stiffness>0</spring_stiffness>\n          <damping>0</damping>\n          <friction>0</friction>\n        </dynamics>\n      </axis>\n      <axis2>\n        <xyz>0.10034833225937423 0.88305248167387373 0.45841959690045475</xyz>\n        <limit>\n          <lower>-inf</lower>\n          <upper>inf</upper>\n          <effort>inf</effort>\n          <velocity>3.3939139458964149</velocity>\n          <stiffness>100000000</stiffness>\n          <dissipation>1</dissipation>\n        </limit>\n        <dynamics>\n          <spring_reference>0</spring_reference>\n          <spring_stiffness>0</spring_stiffness>\n          <damping>0</damping>\n          <friction>0</friction>\n        </dynamics>\n      </axis2>\n    </joint>\n  </model>\n</sdf>\n"[0m[1;31m[0m
[1;33mWarning [Utils.cc:132][0m [/sdf/model[@name="submarine"]/joint[@name="propeller_joint"]/axis/use_parent_model_frame:<data-string>:L136]: XML Element[use_parent_model_frame], child of element[axis], not defined in SDF. Copying[use_parent_model_frame] as children of [axis].
[1;31m[Err] [UserCommands.cc:1145] [0m[1;31mError Code [0m[1;31m19[0m[1;31m: [0m[1;31mMsg: [0m[1;31mA link named body has invalid inertia.[0m[1;31m[0m
gz sim server: ./dart/dynamics/SphereShape.cpp:68: void dart::dynamics::SphereShape::setRadius(double): Assertion `radius > 0.0' failed.
Stack trace (most recent call last):
#31   Object "/lib/x86_64-linux-gnu/libruby-3.0.so.3.0", at 0x721fd6e3ec61, in rb_yield
#30   Object "/lib/x86_64-linux-gnu/libruby-3.0.so.3.0", at 0x721fd6e3a30c, in rb_vm_exec
#29   Object "/lib/x86_64-linux-gnu/libruby-3.0.so.3.0", at 0x721fd6e34c96, in 
#28   Object "/lib/x86_64-linux-gnu/libruby-3.0.so.3.0", at 0x721fd6e31fc5, in 
#27   Object "/lib/x86_64-linux-gnu/libruby-3.0.so.3.0", at 0x721fd6e2fc34, in 
#26   Object "/usr/lib/x86_64-linux-gnu/ruby/3.0.0/fiddle.so", at 0x721fd6f7b44b, in 
#25   Object "/lib/x86_64-linux-gnu/libruby-3.0.so.3.0", at 0x721fd6dfd088, in rb_nogvl
#24   Object "/usr/lib/x86_64-linux-gnu/ruby/3.0.0/fiddle.so", at 0x721fd6f7ad6b, in 
#23   Object "/lib/x86_64-linux-gnu/libffi.so.8", at 0x721fd6a33492, in 
#22   Object "/lib/x86_64-linux-gnu/libffi.so.8", at 0x721fd6a36e2d, in 
#21   Object "/usr/lib/x86_64-linux-gnu/libgz-sim8-gz.so.8.6.0", at 0x721fd5da8605, in runServer
#20   Object "/lib/x86_64-linux-gnu/libgz-sim8.so.8", at 0x721fd113d485, in 
#19   Object "/lib/x86_64-linux-gnu/libgz-sim8.so.8", at 0x721fd114d8a2, in gz::sim::v8::SimulationRunner::Run(unsigned long)
#18   Object "/lib/x86_64-linux-gnu/libgz-sim8.so.8", at 0x721fd114ce60, in gz::sim::v8::SimulationRunner::Step(gz::sim::v8::UpdateInfo const&)
#17   Object "/lib/x86_64-linux-gnu/libgz-sim8.so.8", at 0x721fd114c0a2, in gz::sim::v8::SimulationRunner::UpdateSystems()
#16   Object "/usr/lib/x86_64-linux-gnu/gz-sim-8/plugins/libgz-sim-physics-system.so", at 0x721fc851f585, in gz::sim::v8::systems::Physics::Update(gz::sim::v8::UpdateInfo const&, gz::sim::v8::EntityComponentManager&)
#15   Object "/usr/lib/x86_64-linux-gnu/gz-sim-8/plugins/libgz-sim-physics-system.so", at 0x721fc851f4b2, in gz::sim::v8::systems::PhysicsPrivate::CreatePhysicsEntities(gz::sim::v8::EntityComponentManager const&, bool)
#14   Object "/usr/lib/x86_64-linux-gnu/gz-sim-8/plugins/libgz-sim-physics-system.so", at 0x721fc8519544, in gz::sim::v8::systems::PhysicsPrivate::CreateModelEntities(gz::sim::v8::EntityComponentManager const&, bool)
#13   Object "/usr/lib/x86_64-linux-gnu/gz-sim-8/plugins/libgz-sim-physics-system.so", at 0x721fc8598f06, in 
#12   Object "/usr/lib/x86_64-linux-gnu/gz-physics-7/engine-plugins/libgz-physics-dartsim-plugin.so", at 0x721f90bf1fb3, in virtual thunk to gz::physics::dartsim::SDFFeatures::ConstructSdfModel(gz::physics::Identity const&, sdf::v14::Model const&)
#11   Object "/usr/lib/x86_64-linux-gnu/gz-physics-7/engine-plugins/libgz-physics-dartsim-plugin.so", at 0x721f90bf13fa, in gz::physics::dartsim::SDFFeatures::ConstructSdfModelImpl(unsigned long, sdf::v14::Model const&)
#10   Object "/usr/lib/x86_64-linux-gnu/gz-physics-7/engine-plugins/libgz-physics-dartsim-plugin.so", at 0x721f90bed384, in gz::physics::dartsim::SDFFeatures::FindOrConstructLink(std::shared_ptr<dart::dynamics::Skeleton> const&, gz::physics::Identity const&, sdf::v14::Model const&, std::__cxx11::basic_string<char, std::char_traits<char>, std::allocator<char> > const&)
#9    Object "/usr/lib/x86_64-linux-gnu/gz-physics-7/engine-plugins/libgz-physics-dartsim-plugin.so", at 0x721f90becdc4, in gz::physics::dartsim::SDFFeatures::ConstructSdfLink(gz::physics::Identity const&, sdf::v14::Link const&)
#8    Object "/usr/lib/x86_64-linux-gnu/gz-physics-7/engine-plugins/libgz-physics-dartsim-plugin.so", at 0x721f90bf3a6e, in gz::physics::dartsim::SDFFeatures::ConstructSdfCollision(gz::physics::Identity const&, sdf::v14::Collision const&)
#7    Object "/usr/lib/x86_64-linux-gnu/gz-physics-7/engine-plugins/libgz-physics-dartsim-plugin.so", at 0x721f90bf32e6, in 
#6    Object "/lib/x86_64-linux-gnu/libdart.so.6.13", at 0x721f9071b16f, in dart::dynamics::SphereShape::SphereShape(double)
#5    Object "/lib/x86_64-linux-gnu/libdart.so.6.13", at 0x721f907199a2, in dart::dynamics::SphereShape::setRadius(double)
#4    Object "/lib/x86_64-linux-gnu/libc.so.6", at 0x721fd6839e95, in __assert_fail
#3    Object "/lib/x86_64-linux-gnu/libc.so.6", at 0x721fd682871a, in 
#2    Object "/lib/x86_64-linux-gnu/libc.so.6", at 0x721fd68287f2, in abort
#1    Object "/lib/x86_64-linux-gnu/libc.so.6", at 0x721fd6842475, in raise
#0    Object "/lib/x86_64-linux-gnu/libc.so.6", at 0x721fd68969fc, in pthread_kill
Aborted (Signal sent by tkill() 483901 1000)
