<!-- seed: 1718592691 -->
<sdf version='1.11'>
  <world name='world_0'>
    <gravity>0 0 -9.8066499999999994</gravity>
    <magnetic_field>5.5644999999999998e-06 2.2875799999999999e-05 -4.2388400000000002e-05</magnetic_field>
    <wind>
      <linear_velocity>3 4 1</linear_velocity>
    </wind>
    <physics default='false' type='ode'>
      <max_step_size>0.001</max_step_size>
      <real_time_factor>1</real_time_factor>
      <max_contacts>20</max_contacts>
    </physics>
    <model name='model_0'>
      <static>false</static>
      <self_collide>false</self_collide>
      <allow_auto_disable>true</allow_auto_disable>
      <enable_wind>false</enable_wind>
      <pose>3.4206541258259122 6.4607010606082014 4.4707355685221781 0 0 0</pose>
      <link name='link_8025'>
        <pose>4.8745590096958473 -7.3397881513739911 7.6829806610187195 0 0 0</pose>
        <inertial>
          <pose>0 0 0 0 0 0</pose>
          <mass>1</mass>
          <inertia>
            <ixx>1</ixx>
            <ixy>0</ixy>
            <ixz>0</ixz>
            <iyy>1</iyy>
            <iyz>0</iyz>
            <izz>1</izz>
          </inertia>
        </inertial>
        <enable_wind>false</enable_wind>
        <collision name='collision_8025'>
          <pose>0 0 0 0 0 0</pose>
          <geometry>
            <box>
              <size>1.6803494809091224 2.71709685828439 2.4120832660330991</size>
            </box>
          </geometry>
          <surface>
            <contact>
              <collide_bitmask>255</collide_bitmask>
            </contact>
            <friction>
              <ode>
                <mu>1</mu>
                <mu2>1</mu2>
                <slip1>0</slip1>
                <slip2>0</slip2>
                <fdir1>0 0 0</fdir1>
              </ode>
            </friction>
          </surface>
        </collision>
        <visual name='visual_8025'>
          <pose>0 0 0 0 0 0</pose>
          <geometry>
            <box>
              <size>1.6803494809091224 2.71709685828439 2.4120832660330991</size>
            </box>
          </geometry>
          <cast_shadows>true</cast_shadows>
          <laser_retro>0</laser_retro>
          <transparency>0</transparency>
          <visibility_flags>4294967295</visibility_flags>
          <material>
            <ambient>0.175981507 0.188861534 0.100955322 1</ambient>
            <diffuse>0.175981507 0.188861534 0.100955322 1</diffuse>
            <specular>0 0 0 1</specular>
            <emissive>0 0 0 1</emissive>
            <render_order>0</render_order>
            <lighting>true</lighting>
            <double_sided>false</double_sided>
            <shader type='pixel'/>
          </material>
        </visual>
      </link>
      <link name='link_8026'>
        <pose>-5.7277002935778736 -7.1828665090798349 8.6348689989369038 0 0 0</pose>
        <inertial>
          <pose>0 0 0 0 0 0</pose>
          <mass>1</mass>
          <inertia>
            <ixx>1</ixx>
            <ixy>0</ixy>
            <ixz>0</ixz>
            <iyy>1</iyy>
            <iyz>0</iyz>
            <izz>1</izz>
          </inertia>
        </inertial>
        <enable_wind>false</enable_wind>
        <collision name='collision_8026'>
          <pose>0 0 0 0 0 0</pose>
          <geometry>
            <cylinder>
              <radius>2.3757096206883954</radius>
              <length>2.889196408083734</length>
            </cylinder>
          </geometry>
          <surface>
            <contact>
              <collide_bitmask>255</collide_bitmask>
            </contact>
            <friction>
              <ode>
                <mu>1</mu>
                <mu2>1</mu2>
                <slip1>0</slip1>
                <slip2>0</slip2>
                <fdir1>0 0 0</fdir1>
              </ode>
            </friction>
          </surface>
        </collision>
        <visual name='visual_8026'>
          <pose>0 0 0 0 0 0</pose>
          <geometry>
            <cylinder>
              <radius>2.3757096206883954</radius>
              <length>2.889196408083734</length>
            </cylinder>
          </geometry>
          <cast_shadows>true</cast_shadows>
          <laser_retro>0</laser_retro>
          <transparency>0</transparency>
          <visibility_flags>4294967295</visibility_flags>
          <material>
            <ambient>0.808294117 0.903594077 0.287423074 1</ambient>
            <diffuse>0.808294117 0.903594077 0.287423074 1</diffuse>
            <specular>0 0 0 1</specular>
            <emissive>0 0 0 1</emissive>
            <render_order>0</render_order>
            <lighting>true</lighting>
            <double_sided>false</double_sided>
            <shader type='pixel'/>
          </material>
        </visual>
      </link>
      <link name='link_8027'>
        <pose>2.0099328163168586 -7.1964705472443065 3.6959286025966733 0 0 0</pose>
        <inertial>
          <pose>0 0 0 0 0 0</pose>
          <mass>1</mass>
          <inertia>
            <ixx>1</ixx>
            <ixy>0</ixy>
            <ixz>0</ixz>
            <iyy>1</iyy>
            <iyz>0</iyz>
            <izz>1</izz>
          </inertia>
        </inertial>
        <enable_wind>false</enable_wind>
        <collision name='collision_8027'>
          <pose>0 0 0 0 0 0</pose>
          <geometry>
            <capsule>
              <radius>1.9220359479700075</radius>
              <length>2.0127480971969613</length>
            </capsule>
          </geometry>
          <surface>
            <contact>
              <collide_bitmask>255</collide_bitmask>
            </contact>
            <friction>
              <ode>
                <mu>1</mu>
                <mu2>1</mu2>
                <slip1>0</slip1>
                <slip2>0</slip2>
                <fdir1>0 0 0</fdir1>
              </ode>
            </friction>
          </surface>
        </collision>
        <visual name='visual_8027'>
          <pose>0 0 0 0 0 0</pose>
          <geometry>
            <capsule>
              <radius>1.9220359479700075</radius>
              <length>2.0127480971969613</length>
            </capsule>
          </geometry>
          <cast_shadows>true</cast_shadows>
          <laser_retro>0</laser_retro>
          <transparency>0</transparency>
          <visibility_flags>4294967295</visibility_flags>
          <material>
            <ambient>0.26795274 0.264875114 0.448483497 1</ambient>
            <diffuse>0.26795274 0.264875114 0.448483497 1</diffuse>
            <specular>0 0 0 1</specular>
            <emissive>0 0 0 1</emissive>
            <render_order>0</render_order>
            <lighting>true</lighting>
            <double_sided>false</double_sided>
            <shader type='pixel'/>
          </material>
        </visual>
      </link>
      <joint name='joint_5350' type='gearbox'>
        <pose>0 0 0 0 0 0</pose>
        <parent>link_8025</parent>
        <child>link_8026</child>
        <axis>
          <xyz>0.84938241332972275 0.52171033905978015 0.079798734603408958</xyz>
          <limit>
            <lower>-inf</lower>
            <upper>inf</upper>
            <effort>inf</effort>
            <velocity>8.5721088869967286</velocity>
            <stiffness>100000000</stiffness>
            <dissipation>1</dissipation>
          </limit>
          <dynamics>
            <spring_reference>0</spring_reference>
            <spring_stiffness>0</spring_stiffness>
            <damping>0</damping>
            <friction>0</friction>
          </dynamics>
        </axis>
        <axis2>
          <xyz>0.43481488050418687 0.62771762235840622 0.64568305403877457</xyz>
          <limit>
            <lower>-inf</lower>
            <upper>inf</upper>
            <effort>inf</effort>
            <velocity>6.7497557298877453</velocity>
            <stiffness>100000000</stiffness>
            <dissipation>1</dissipation>
          </limit>
          <dynamics>
            <spring_reference>0</spring_reference>
            <spring_stiffness>0</spring_stiffness>
            <damping>0</damping>
            <friction>0</friction>
          </dynamics>
        </axis2>
      </joint>
      <joint name='joint_5351' type='screw'>
        <pose>0 0 0 0 0 0</pose>
        <parent>link_8025</parent>
        <child>link_8026</child>
        <axis>
          <xyz>0.89680802458992925 0.29826354249447368 0.32676325719051708</xyz>
          <limit>
            <lower>-inf</lower>
            <upper>inf</upper>
            <effort>inf</effort>
            <velocity>1.2385150454223082</velocity>
            <stiffness>100000000</stiffness>
            <dissipation>1</dissipation>
          </limit>
          <dynamics>
            <spring_reference>0</spring_reference>
            <spring_stiffness>0</spring_stiffness>
            <damping>0</damping>
            <friction>0</friction>
          </dynamics>
        </axis>
        <axis2>
          <xyz>0.78212875029972306 0.54769876086362601 0.29715431227401407</xyz>
          <limit>
            <lower>-inf</lower>
            <upper>inf</upper>
            <effort>inf</effort>
            <velocity>1.8451185247011759</velocity>
            <stiffness>100000000</stiffness>
            <dissipation>1</dissipation>
          </limit>
          <dynamics>
            <spring_reference>0</spring_reference>
            <spring_stiffness>0</spring_stiffness>
            <damping>0</damping>
            <friction>0</friction>
          </dynamics>
        </axis2>
        <thread_pitch>-6.2831853071795862</thread_pitch>
      </joint>
    </model>
    <model name='model_1'>
      <static>false</static>
      <self_collide>true</self_collide>
      <allow_auto_disable>true</allow_auto_disable>
      <enable_wind>true</enable_wind>
      <pose>-0.49568227389750419 -4.6682092758964373 9.2974387670382512 0 0 0</pose>
      <link name='link_8028'>
        <pose>2.1176499223129248 9.5692860925004446 2.3453856325233158 0 0 0</pose>
        <inertial>
          <pose>0 0 0 0 0 0</pose>
          <mass>1</mass>
          <inertia>
            <ixx>1</ixx>
            <ixy>0</ixy>
            <ixz>0</ixz>
            <iyy>1</iyy>
            <iyz>0</iyz>
            <izz>1</izz>
          </inertia>
        </inertial>
        <enable_wind>false</enable_wind>
        <collision name='collision_8028'>
          <pose>0 0 0 0 0 0</pose>
          <geometry>
            <sphere>
              <radius>1.4335992166543015</radius>
            </sphere>
          </geometry>
          <surface>
            <contact>
              <collide_bitmask>255</collide_bitmask>
            </contact>
            <friction>
              <ode>
                <mu>1</mu>
                <mu2>1</mu2>
                <slip1>0</slip1>
                <slip2>0</slip2>
                <fdir1>0 0 0</fdir1>
              </ode>
            </friction>
          </surface>
        </collision>
        <visual name='visual_8028'>
          <pose>0 0 0 0 0 0</pose>
          <geometry>
            <sphere>
              <radius>1.4335992166543015</radius>
            </sphere>
          </geometry>
          <cast_shadows>true</cast_shadows>
          <laser_retro>0</laser_retro>
          <transparency>0</transparency>
          <visibility_flags>4294967295</visibility_flags>
          <material>
            <ambient>0.488979965 0.621560991 0.49778527 1</ambient>
            <diffuse>0.488979965 0.621560991 0.49778527 1</diffuse>
            <specular>0 0 0 1</specular>
            <emissive>0 0 0 1</emissive>
            <render_order>0</render_order>
            <lighting>true</lighting>
            <double_sided>false</double_sided>
            <shader type='pixel'/>
          </material>
        </visual>
      </link>
      <link name='link_8029'>
        <pose>-9.0100246560895592 1.823670645724091 3.671563255874676 0 0 0</pose>
        <inertial>
          <pose>0 0 0 0 0 0</pose>
          <mass>1</mass>
          <inertia>
            <ixx>1</ixx>
            <ixy>0</ixy>
            <ixz>0</ixz>
            <iyy>1</iyy>
            <iyz>0</iyz>
            <izz>1</izz>
          </inertia>
        </inertial>
        <enable_wind>false</enable_wind>
        <collision name='collision_8029'>
          <pose>0 0 0 0 0 0</pose>
          <geometry>
            <capsule>
              <radius>2.4583568472908235</radius>
              <length>1.225160247692983</length>
            </capsule>
          </geometry>
          <surface>
            <contact>
              <collide_bitmask>255</collide_bitmask>
            </contact>
            <friction>
              <ode>
                <mu>1</mu>
                <mu2>1</mu2>
                <slip1>0</slip1>
                <slip2>0</slip2>
                <fdir1>0 0 0</fdir1>
              </ode>
            </friction>
          </surface>
        </collision>
        <visual name='visual_8029'>
          <pose>0 0 0 0 0 0</pose>
          <geometry>
            <capsule>
              <radius>2.4583568472908235</radius>
              <length>1.225160247692983</length>
            </capsule>
          </geometry>
          <cast_shadows>true</cast_shadows>
          <laser_retro>0</laser_retro>
          <transparency>0</transparency>
          <visibility_flags>4294967295</visibility_flags>
          <material>
            <ambient>0.76805079 0.604769051 0.259278417 1</ambient>
            <diffuse>0.76805079 0.604769051 0.259278417 1</diffuse>
            <specular>0 0 0 1</specular>
            <emissive>0 0 0 1</emissive>
            <render_order>0</render_order>
            <lighting>true</lighting>
            <double_sided>false</double_sided>
            <shader type='pixel'/>
          </material>
        </visual>
      </link>
      <link name='link_8030'>
        <pose>7.3859958658694289 -7.5833355043274757 7.7976586103239427 0 0 0</pose>
        <inertial>
          <pose>0 0 0 0 0 0</pose>
          <mass>1</mass>
          <inertia>
            <ixx>1</ixx>
            <ixy>0</ixy>
            <ixz>0</ixz>
            <iyy>1</iyy>
            <iyz>0</iyz>
            <izz>1</izz>
          </inertia>
        </inertial>
        <enable_wind>false</enable_wind>
        <collision name='collision_8030'>
          <pose>0 0 0 0 0 0</pose>
          <geometry>
            <capsule>
              <radius>1.1489302334667928</radius>
              <length>2.9845734149434975</length>
            </capsule>
          </geometry>
          <surface>
            <contact>
              <collide_bitmask>255</collide_bitmask>
            </contact>
            <friction>
              <ode>
                <mu>1</mu>
                <mu2>1</mu2>
                <slip1>0</slip1>
                <slip2>0</slip2>
                <fdir1>0 0 0</fdir1>
              </ode>
            </friction>
          </surface>
        </collision>
        <visual name='visual_8030'>
          <pose>0 0 0 0 0 0</pose>
          <geometry>
            <capsule>
              <radius>1.1489302334667928</radius>
              <length>2.9845734149434975</length>
            </capsule>
          </geometry>
          <cast_shadows>true</cast_shadows>
          <laser_retro>0</laser_retro>
          <transparency>0</transparency>
          <visibility_flags>4294967295</visibility_flags>
          <material>
            <ambient>0.0847774372 0.827468038 0.722697437 1</ambient>
            <diffuse>0.0847774372 0.827468038 0.722697437 1</diffuse>
            <specular>0 0 0 1</specular>
            <emissive>0 0 0 1</emissive>
            <render_order>0</render_order>
            <lighting>true</lighting>
            <double_sided>false</double_sided>
            <shader type='pixel'/>
          </material>
        </visual>
      </link>
      <joint name='joint_5352' type='gearbox'>
        <pose>0 0 0 0 0 0</pose>
        <parent>link_8028</parent>
        <child>link_8029</child>
        <axis>
          <xyz>0.33499803777778392 0.93713487663833794 0.097747315426467946</xyz>
          <limit>
            <lower>-inf</lower>
            <upper>inf</upper>
            <effort>inf</effort>
            <velocity>8.737936766019228</velocity>
            <stiffness>100000000</stiffness>
            <dissipation>1</dissipation>
          </limit>
          <dynamics>
            <spring_reference>0</spring_reference>
            <spring_stiffness>0</spring_stiffness>
            <damping>0</damping>
            <friction>0</friction>
          </dynamics>
        </axis>
        <axis2>
          <xyz>0.57647197779587889 0.58370372405694027 0.57181292512338977</xyz>
          <limit>
            <lower>-inf</lower>
            <upper>inf</upper>
            <effort>inf</effort>
            <velocity>7.3139114252174551</velocity>
            <stiffness>100000000</stiffness>
            <dissipation>1</dissipation>
          </limit>
          <dynamics>
            <spring_reference>0</spring_reference>
            <spring_stiffness>0</spring_stiffness>
            <damping>0</damping>
            <friction>0</friction>
          </dynamics>
        </axis2>
      </joint>
      <joint name='joint_5353' type='prismatic'>
        <pose>0 0 0 0 0 0</pose>
        <parent>link_8030</parent>
        <child>link_8029</child>
        <axis>
          <xyz>0.02451791614024152 0.99805365289263892 0.057339146626016808</xyz>
          <limit>
            <lower>-inf</lower>
            <upper>inf</upper>
            <effort>inf</effort>
            <velocity>9.5720858721661912</velocity>
            <stiffness>100000000</stiffness>
            <dissipation>1</dissipation>
          </limit>
          <dynamics>
            <spring_reference>0</spring_reference>
            <spring_stiffness>0</spring_stiffness>
            <damping>0</damping>
            <friction>0</friction>
          </dynamics>
        </axis>
        <axis2>
          <xyz>0.48479207876507846 0.14469550226824654 0.86257744695185146</xyz>
          <limit>
            <lower>-inf</lower>
            <upper>inf</upper>
            <effort>inf</effort>
            <velocity>2.2790261819898481</velocity>
            <stiffness>100000000</stiffness>
            <dissipation>1</dissipation>
          </limit>
          <dynamics>
            <spring_reference>0</spring_reference>
            <spring_stiffness>0</spring_stiffness>
            <damping>0</damping>
            <friction>0</friction>
          </dynamics>
        </axis2>
      </joint>
    </model>
    <model name='ground_model'>
      <static>true</static>
      <self_collide>false</self_collide>
      <allow_auto_disable>true</allow_auto_disable>
      <enable_wind>false</enable_wind>
      <pose>0 0 0 0 0 0</pose>
      <link name='ground_link'>
        <pose>0 0 0 0 0 0</pose>
        <inertial>
          <pose>0 0 0 0 0 0</pose>
          <mass>1</mass>
          <inertia>
            <ixx>1</ixx>
            <ixy>0</ixy>
            <ixz>0</ixz>
            <iyy>1</iyy>
            <iyz>0</iyz>
            <izz>1</izz>
          </inertia>
        </inertial>
        <enable_wind>false</enable_wind>
        <collision name='ground_collision'>
          <pose>0 0 0 0 0 0</pose>
          <geometry>
            <plane>
              <normal>0 0 1</normal>
              <size>100 100</size>
            </plane>
          </geometry>
          <surface>
            <contact>
              <collide_bitmask>255</collide_bitmask>
            </contact>
            <friction>
              <ode>
                <mu>1</mu>
                <mu2>1</mu2>
                <slip1>0</slip1>
                <slip2>0</slip2>
                <fdir1>0 0 0</fdir1>
              </ode>
            </friction>
          </surface>
        </collision>
      </link>
    </model>
    <model name='ceiling_model'>
      <static>true</static>
      <self_collide>false</self_collide>
      <allow_auto_disable>true</allow_auto_disable>
      <enable_wind>false</enable_wind>
      <pose>0 0 100 0 0 0</pose>
      <link name='ceiling_link'>
        <pose>0 0 0 0 0 0</pose>
        <inertial>
          <pose>0 0 0 0 0 0</pose>
          <mass>1</mass>
          <inertia>
            <ixx>1</ixx>
            <ixy>0</ixy>
            <ixz>0</ixz>
            <iyy>1</iyy>
            <iyz>0</iyz>
            <izz>1</izz>
          </inertia>
        </inertial>
        <enable_wind>false</enable_wind>
        <collision name='ceiling_collision'>
          <pose>0 0 0 0 0 0</pose>
          <geometry>
            <box>
              <size>102 102 3</size>
            </box>
          </geometry>
          <surface>
            <contact>
              <collide_bitmask>255</collide_bitmask>
            </contact>
            <friction>
              <ode>
                <mu>1</mu>
                <mu2>1</mu2>
                <slip1>0</slip1>
                <slip2>0</slip2>
                <fdir1>0 0 0</fdir1>
              </ode>
            </friction>
          </surface>
        </collision>
        <visual name='ceiling_visual'>
          <pose>0 0 0 0 0 0</pose>
          <geometry>
            <box>
              <size>102 102 3</size>
            </box>
          </geometry>
          <cast_shadows>true</cast_shadows>
          <laser_retro>0</laser_retro>
          <transparency>0</transparency>
          <visibility_flags>4294967295</visibility_flags>
          <material>
            <ambient>0.200000003 0.200000003 0.200000003 0.200000003</ambient>
            <diffuse>0.200000003 0.200000003 0.200000003 0.200000003</diffuse>
            <specular>0 0 0 1</specular>
            <emissive>0 0 0 1</emissive>
            <render_order>0</render_order>
            <lighting>true</lighting>
            <double_sided>false</double_sided>
            <shader type='pixel'/>
          </material>
        </visual>
      </link>
    </model>
    <model name='west_model'>
      <static>true</static>
      <self_collide>false</self_collide>
      <allow_auto_disable>true</allow_auto_disable>
      <enable_wind>false</enable_wind>
      <pose>0 50 50 0 0 0</pose>
      <link name='west_link'>
        <pose>0 0 0 0 0 0</pose>
        <inertial>
          <pose>0 0 0 0 0 0</pose>
          <mass>1</mass>
          <inertia>
            <ixx>1</ixx>
            <ixy>0</ixy>
            <ixz>0</ixz>
            <iyy>1</iyy>
            <iyz>0</iyz>
            <izz>1</izz>
          </inertia>
        </inertial>
        <enable_wind>false</enable_wind>
        <collision name='west_collision'>
          <pose>0 0 0 0 0 0</pose>
          <geometry>
            <box>
              <size>102 3 102</size>
            </box>
          </geometry>
          <surface>
            <contact>
              <collide_bitmask>255</collide_bitmask>
            </contact>
            <friction>
              <ode>
                <mu>1</mu>
                <mu2>1</mu2>
                <slip1>0</slip1>
                <slip2>0</slip2>
                <fdir1>0 0 0</fdir1>
              </ode>
            </friction>
          </surface>
        </collision>
        <visual name='west_visual'>
          <pose>0 0 0 0 0 0</pose>
          <geometry>
            <box>
              <size>102 3 102</size>
            </box>
          </geometry>
          <cast_shadows>true</cast_shadows>
          <laser_retro>0</laser_retro>
          <transparency>0</transparency>
          <visibility_flags>4294967295</visibility_flags>
          <material>
            <ambient>0.200000003 0.200000003 0.200000003 0.200000003</ambient>
            <diffuse>0.200000003 0.200000003 0.200000003 0.200000003</diffuse>
            <specular>0 0 0 1</specular>
            <emissive>0 0 0 1</emissive>
            <render_order>0</render_order>
            <lighting>true</lighting>
            <double_sided>false</double_sided>
            <shader type='pixel'/>
          </material>
        </visual>
      </link>
    </model>
    <model name='east_model'>
      <static>true</static>
      <self_collide>false</self_collide>
      <allow_auto_disable>true</allow_auto_disable>
      <enable_wind>false</enable_wind>
      <pose>0 -50 50 0 0 0</pose>
      <link name='east_link'>
        <pose>0 0 0 0 0 0</pose>
        <inertial>
          <pose>0 0 0 0 0 0</pose>
          <mass>1</mass>
          <inertia>
            <ixx>1</ixx>
            <ixy>0</ixy>
            <ixz>0</ixz>
            <iyy>1</iyy>
            <iyz>0</iyz>
            <izz>1</izz>
          </inertia>
        </inertial>
        <enable_wind>false</enable_wind>
        <collision name='east_collision'>
          <pose>0 0 0 0 0 0</pose>
          <geometry>
            <box>
              <size>102 3 102</size>
            </box>
          </geometry>
          <surface>
            <contact>
              <collide_bitmask>255</collide_bitmask>
            </contact>
            <friction>
              <ode>
                <mu>1</mu>
                <mu2>1</mu2>
                <slip1>0</slip1>
                <slip2>0</slip2>
                <fdir1>0 0 0</fdir1>
              </ode>
            </friction>
          </surface>
        </collision>
        <visual name='east_visual'>
          <pose>0 0 0 0 0 0</pose>
          <geometry>
            <box>
              <size>102 3 102</size>
            </box>
          </geometry>
          <cast_shadows>true</cast_shadows>
          <laser_retro>0</laser_retro>
          <transparency>0</transparency>
          <visibility_flags>4294967295</visibility_flags>
          <material>
            <ambient>0.200000003 0.200000003 0.200000003 0.200000003</ambient>
            <diffuse>0.200000003 0.200000003 0.200000003 0.200000003</diffuse>
            <specular>0 0 0 1</specular>
            <emissive>0 0 0 1</emissive>
            <render_order>0</render_order>
            <lighting>true</lighting>
            <double_sided>false</double_sided>
            <shader type='pixel'/>
          </material>
        </visual>
      </link>
    </model>
    <model name='north_model'>
      <static>true</static>
      <self_collide>false</self_collide>
      <allow_auto_disable>true</allow_auto_disable>
      <enable_wind>false</enable_wind>
      <pose>50 0 50 0 0 0</pose>
      <link name='north_link'>
        <pose>0 0 0 0 0 0</pose>
        <inertial>
          <pose>0 0 0 0 0 0</pose>
          <mass>1</mass>
          <inertia>
            <ixx>1</ixx>
            <ixy>0</ixy>
            <ixz>0</ixz>
            <iyy>1</iyy>
            <iyz>0</iyz>
            <izz>1</izz>
          </inertia>
        </inertial>
        <enable_wind>false</enable_wind>
        <collision name='north_collision'>
          <pose>0 0 0 0 0 0</pose>
          <geometry>
            <box>
              <size>3 102 102</size>
            </box>
          </geometry>
          <surface>
            <contact>
              <collide_bitmask>255</collide_bitmask>
            </contact>
            <friction>
              <ode>
                <mu>1</mu>
                <mu2>1</mu2>
                <slip1>0</slip1>
                <slip2>0</slip2>
                <fdir1>0 0 0</fdir1>
              </ode>
            </friction>
          </surface>
        </collision>
        <visual name='north_visual'>
          <pose>0 0 0 0 0 0</pose>
          <geometry>
            <box>
              <size>3 102 102</size>
            </box>
          </geometry>
          <cast_shadows>true</cast_shadows>
          <laser_retro>0</laser_retro>
          <transparency>0</transparency>
          <visibility_flags>4294967295</visibility_flags>
          <material>
            <ambient>0.200000003 0.200000003 0.200000003 0.200000003</ambient>
            <diffuse>0.200000003 0.200000003 0.200000003 0.200000003</diffuse>
            <specular>0 0 0 1</specular>
            <emissive>0 0 0 1</emissive>
            <render_order>0</render_order>
            <lighting>true</lighting>
            <double_sided>false</double_sided>
            <shader type='pixel'/>
          </material>
        </visual>
      </link>
    </model>
    <model name='south_model'>
      <static>true</static>
      <self_collide>false</self_collide>
      <allow_auto_disable>true</allow_auto_disable>
      <enable_wind>false</enable_wind>
      <pose>-50 0 50 0 0 0</pose>
      <link name='south_link'>
        <pose>0 0 0 0 0 0</pose>
        <inertial>
          <pose>0 0 0 0 0 0</pose>
          <mass>1</mass>
          <inertia>
            <ixx>1</ixx>
            <ixy>0</ixy>
            <ixz>0</ixz>
            <iyy>1</iyy>
            <iyz>0</iyz>
            <izz>1</izz>
          </inertia>
        </inertial>
        <enable_wind>false</enable_wind>
        <collision name='south_collision'>
          <pose>0 0 0 0 0 0</pose>
          <geometry>
            <box>
              <size>3 102 102</size>
            </box>
          </geometry>
          <surface>
            <contact>
              <collide_bitmask>255</collide_bitmask>
            </contact>
            <friction>
              <ode>
                <mu>1</mu>
                <mu2>1</mu2>
                <slip1>0</slip1>
                <slip2>0</slip2>
                <fdir1>0 0 0</fdir1>
              </ode>
            </friction>
          </surface>
        </collision>
        <visual name='south_visual'>
          <pose>0 0 0 0 0 0</pose>
          <geometry>
            <box>
              <size>3 102 102</size>
            </box>
          </geometry>
          <cast_shadows>true</cast_shadows>
          <laser_retro>0</laser_retro>
          <transparency>0</transparency>
          <visibility_flags>4294967295</visibility_flags>
          <material>
            <ambient>0.200000003 0.200000003 0.200000003 0.200000003</ambient>
            <diffuse>0.200000003 0.200000003 0.200000003 0.200000003</diffuse>
            <specular>0 0 0 1</specular>
            <emissive>0 0 0 1</emissive>
            <render_order>0</render_order>
            <lighting>true</lighting>
            <double_sided>false</double_sided>
            <shader type='pixel'/>
          </material>
        </visual>
      </link>
    </model>
    <atmosphere type='adiabatic'>
      <temperature>288.14999999999998</temperature>
      <pressure>101325</pressure>
      <temperature_gradient>-0.0064999999999999997</temperature_gradient>
    </atmosphere>
    <scene>
      <ambient>0.400000006 0.400000006 0.400000006 1</ambient>
      <background>0.699999988 0.699999988 0.699999988 1</background>
      <grid>true</grid>
      <origin_visual>true</origin_visual>
      <shadows>true</shadows>
    </scene>
  </world>
</sdf>
