Warning: Ignoring XDG_SESSION_TYPE=wayland on Gnome. Use QT_QPA_PLATFORM=wayland to run on Wayland anyway.
[1;31m[Err] [UserCommands.cc:1676] [0m[1;31mUnable to update the pose for entity [[0m[1;31m1371360245057352846[0m[1;31m]: entity doesn't exist.[0m[1;31m[0m
[1;31m[Err] [UserCommands.cc:1145] [0m[1;31mError Code [0m[1;31m30[0m[1;31m: [0m[1;31mMsg: [0m[1;31mError parsing XML from string: Error=XML_ERROR_PARSING_TEXT ErrorID=8 (0x8) Line number=1[0m[1;31m[0m
[1;31m[Err] [UserCommands.cc:1145] [0m[1;31mError Code [0m[1;31m30[0m[1;31m: [0m[1;31mMsg: [0m[1;31mUnable to read SDF string: b"<sdf version="1.11">\n  <model name="model">\n    <static>false</static>\n    <self_collide>true</self_collide>\n    <allow_auto_disable>true</allow_auto_disable>\n    <enable_wind>true</enable_wind>\n    <pose>0.22326138675342833 -7.3055163761432969 8.3243843746408182 0 0 0</pose>\n    <link name="link_1254">\n      <pose>7.4462067264577207 -4.5653454655890524 9.6467743903802763 0 0 0</pose>\n      <inertial>\n        <pose>0 0 0 0 0 0</pose>\n        <mass>1</mass>\n        <inertia>\n          <ixx>1</ixx>\n          <ixy>0</ixy>\n          <ixz>0</ixz>\n          <iyy>1</iyy>\n          <iyz>0</iyz>\n          <izz>1</izz>\n        </inertia>\n      </inertial>\n      <enable_wind>false</enable_wind>\n      <collision name="collision_1254">\n        <pose>0 0 0 0 0 0</pose>\n        <geometry>\n          <cylinder>\n            <radius>1.3219372388893278</radius>\n            <length>2.6493273102230015</length>\n          </cylinder>\n        </geometry>\n        <surface>\n          <contact>\n            <collide_bitmask>255</collide_bitmask>\n          </contact>\n          <friction>\n            <ode>\n              <mu>-1</mu>\n              <mu2>1</mu2>\n              <slip1>0</slip1>\n              <slip2>0</slip2>\n              <fdir1>0 0 0</fdir1>\n            </ode>\n          </friction>\n        </surface>\n      </collision>\n      <visual name="visual_1254">\n        <pose>0 0 0 0 0 0</pose>\n        <geometry>\n          <cylinder>\n            <radius>1.3219372388893278</radius>\n            <length>2.6493273102230015</length>\n          </cylinder>\n        </geometry>\n        <cast_shadows>true</cast_shadows>\n        <laser_retro>0</laser_retro>\n        <transparency>0</transparency>\n        <visibility_flags>4294967295</visibility_flags>\n        <material>\n          <ambient>0.860719144 0.463813573 0.0883572549 1</ambient>\n          <diffuse>0.860719144 0.463813573 0.0883572549 1</diffuse>\n          <specular>0 0 0 1</specular>\n          <emissive>0 0 0 1</emissive>\n          <render_order>0</render_order>\n          <lighting>true</lighting>\n          <double_sided>false</double_sided>\n          <shader type="pixel"/>\n        </material>\n      </visual>\n    </link>\n    <link name="link_1255">\n      <pose>-3.4361664049435525 8.1548596004045706 9.0447513386431648 0 0 0</pose>\n      <inertial>\n        <pose>0 0 0 0 0 0</pose>\n        <mass>1</mass>\n        <inertia>\n          <ixx>1</ixx>\n          <ixy>0</ixy>\n          <ixz>0</ixz>\n          <iyy>1</iyy>\n          <iyz>0</iyz>\n          <izz>1</izz>\n        </inertia>\n      </inertial>\n      <enable_wind>false</enable_wind>\n      <collision name="collision_1255">\n        <pose>0 0 0 0 0 0</pose>\n        <geometry>\n          <sphere>\n            <radius>2.7013414660394224</radius>\n          </sphere>\n        </geometry>\n        <surface>\n          <contact>\n            <collide_bitmask>255</collide_bitmask>\n          </contact>\n          <friction>\n            <ode>\n              <mu>1</mu>\n              <mu2>1</mu2>\n              <slip1>0</slip1>\n              <slip2>0</slip2>\n              <fdir1>0 0 0</fdir1>\n            </ode>\n          </friction>\n        </surface>\n      </collision>\n      <visual name="visual_1255">\n        <pose>0 0 0 0 0 0</pose>\n        <geometry>\n          <sphere>\n            <radius>2.7013414660394224</radius>\n          </sphere>\n        </geometry>\n        <cast_shadows>true</cast_shadows>\n        <laser_retro>0</laser_retro>\n        <transparency>0</transparency>\n        <visibility_flags>4294967295</visibility_flags>\n        <material>\n          <ambient>0.0447216518 0.0338988267 0.910207152 1</ambient>\n          <diffuse>0.0447216518 0.0338988267 0.910207152 1</diffuse>\n          <specular>0 0 0 1</specular>\n          <emissive>0 0 0 1</emissive>\n          <render_order>0</render_order>\n          <lighting>true</lighting>\n          <double_sided>false</double_sided>\n          <shader type="pixel"/>\n        </material>\n      </visual>\n    </link>\n    <link name="link_1256">\n      <pose>6.9169412868213271 0.21464230776241422 9.0670670594117979 0 0 0</pose>\n      <inertial>\n        <pose>0 0 0 0 0 0</pose>\n        <mass>1</mass>\n        <inertia>\n          <ixx>1</ixx>\n          <ixy>0</ixy>\n          <ixz>0</ixz>\n          <iyy>1</iyy>\n          <iyz>0</iyz>\n          <izz>1</izz>\n        </inertia>\n      </inertial>\n      <enable_wind>false</enable_wind>\n      <collision name="collision_1256">\n        <pose>0 0 0 0 0 0</pose>\n        <geometry>\n          <cylinder>\n            <radius>2.6365331745367224</radius>\n            <length>1.5455326574357084</length>\n          </cylinder>\n        </geometry>\n        <surface>\n          <contact>\n            <collide_bitmask>255</collide_bitmask>\n          </contact>\n          <friction>\n            <ode>\n              <mu>1</mu>\n              <mu2>1</mu2>\n              <slip1>0</slip1>\n              <slip2>0</slip2>\n              <fdir1>0 0 0</fdir1>\n            </ode>\n          </friction>\n        </surface>\n      </collision>\n      <visual name="visual_1256">\n        <pose>0 0 0 0 0 0</pose>\n        <geometry>\n          <cylinder>\n            <radius>2.6365331745367224</radius>\n            <length>1.5455326574357084</length>\n          </cylinder>\n        </geometry>\n        <cast_shadows>true</cast_shadows>\n        <laser_retro>0</laser_retro>\n        <transparency>0</transparency>\n        <visibility_flags>4294967295</visibility_flags>\n        <material>\n          <ambient>0.0489885136 0.234247908 0.318793237 1</ambient>\n          <diffuse>0.0489885136 0.234247908 0.318793237 1</diffuse>\n          <specular>0 0 0 1</specular>\n          <emissive>0 0 0 1</emissive>\n          <render_order>0</render_order>\n          <lighting>true</lighting>\n          <double_sided>false</double_sided>\n          <shader type="pixel"/>\n        </material>\n      </visual>\n    </link>\n    <joint name="joint_836" type="revolute">\n      <pose>0 0 0 0 0 0</pose>\n      <parent>link_1255</parent>\n      <child>link_1254</child>\n      <axis>\n        <xyz>0.5955717537897649 0.7957138328388903 0.11015344895474767</xyz>\n        <limit>\n          <lower>-inf</lower>\n          <upper>inf</upper>\n          <effort>inf</effort>\n          <velocity>7.2039522153208138</velocity>\n          <stiffness>100000000</stiffness>\n          <dissipation>1</dissipation>\n        </limit>\n        <dynamics>\n          <spring_reference>0</spring_reference>\n          <spring_stiffness>0</spring_stiffness>\n          <damping>0</damping>\n          <friction>0</friction>\n        </dynamics>\n      </axis>\n      <axis2>\n        <xyz>0.020668711727414527 0.68135928355548669 0.73165724972030644</xyz>\n        <limit>\n          <lower>-inf</lower>\n          <upper>inf</upper>\n          <effort>inf</effort>\n          <velocity>1.3181439328187772</velocity>\n          <stiffness>100000000</stiffness>\n          <dissipation>1</dissipation>\n        </limit>\n        <dynamics>\n          <spring_reference>0</spring_reference>\n          <spring_stiffness>0</spring_stiffness>\n          <damping>0</damping>\n          <friction>0</friction>\n        </dynamics>\n      </axis2>\n    </joint>\n    <joint name="joint_837" type="screw">\n      <pose>0 0 0 0 0 0</pose>\n      <parent>link_1255</parent>\n      <child>link_1256</child>\n      <axis>\n        <xyz>0.52711556948646199 0.40108958908119086 0.74918376780042706</xyz>\n        <limit>\n          <lower>-inf</lower>\n          <upper>inf</upper>\n          <effort>inf</effort>\n          <velocity>7.6549328578121179</velocity>\n          <stiffness>100000000</stiffness>\n          <dissipation>1</dissipation>\n        </limit>\n        <dynamics>\n          <spring_reference>0</spring_reference>\n          <spring_stiffness>0</spring_stiffness>\n          <damping>0</damping>\n          <friction>0</friction>\n        </dynamics>\n      </axis>\n      <axis2>\n        <xyz>0.66734900789954987 0.38544664128430456 0.63724107555785769</xyz>\n        <limit>\n          <lower>-inf</lower>\n          <upper>inf</upper>\n          <effort>inf</effort>\n          <velocity>0.75455586643174422</velocity>\n          <stiffness>100000000</stiffness>\n          <dissipation>1</dissipation>\n        </limit>\n        <dynamics>\n          <spring_reference>0</spring_reference>\n          <spring_stiffness>0</spring_stiffness>\n          <damping>0</damping>\n          <friction>0</friction>\n        </dynamics>\n      </axis2>\n      <thread_pitch>-6.2831853071795862</thread_pitch>\n    </joint>\n  </model>\n</sdf>\n"[0m[1;31m[0m
gz sim server: ./dart/dynamics/BoxShape.cpp:43: dart::dynamics::BoxShape::BoxShape(const Vector3d&): Assertion `_size[0] > 0.0' failed.
Stack trace (most recent call last):
#31   Object "/lib/x86_64-linux-gnu/libruby-3.0.so.3.0", at 0x75f83e8a69ac, in rb_protect
#30   Object "/lib/x86_64-linux-gnu/libruby-3.0.so.3.0", at 0x75f83ea3ec61, in rb_yield
#29   Object "/lib/x86_64-linux-gnu/libruby-3.0.so.3.0", at 0x75f83ea3a30c, in rb_vm_exec
#28   Object "/lib/x86_64-linux-gnu/libruby-3.0.so.3.0", at 0x75f83ea34c96, in 
#27   Object "/lib/x86_64-linux-gnu/libruby-3.0.so.3.0", at 0x75f83ea31fc5, in 
#26   Object "/lib/x86_64-linux-gnu/libruby-3.0.so.3.0", at 0x75f83ea2fc34, in 
#25   Object "/usr/lib/x86_64-linux-gnu/ruby/3.0.0/fiddle.so", at 0x75f83e67144b, in 
#24   Object "/lib/x86_64-linux-gnu/libruby-3.0.so.3.0", at 0x75f83e9fd088, in rb_nogvl
#23   Object "/usr/lib/x86_64-linux-gnu/ruby/3.0.0/fiddle.so", at 0x75f83e670d6b, in 
#22   Object "/lib/x86_64-linux-gnu/libffi.so.8", at 0x75f83e645492, in 
#21   Object "/lib/x86_64-linux-gnu/libffi.so.8", at 0x75f83e648e2d, in 
#20   Object "/usr/lib/x86_64-linux-gnu/libgz-sim8-gz.so.8.6.0", at 0x75f83e2b3605, in runServer
#19   Object "/lib/x86_64-linux-gnu/libgz-sim8.so.8", at 0x75f838d3d485, in 
#18   Object "/lib/x86_64-linux-gnu/libgz-sim8.so.8", at 0x75f838d4d8a2, in gz::sim::v8::SimulationRunner::Run(unsigned long)
#17   Object "/lib/x86_64-linux-gnu/libgz-sim8.so.8", at 0x75f838d4ce60, in gz::sim::v8::SimulationRunner::Step(gz::sim::v8::UpdateInfo const&)
#16   Object "/lib/x86_64-linux-gnu/libgz-sim8.so.8", at 0x75f838d4c0a2, in gz::sim::v8::SimulationRunner::UpdateSystems()
#15   Object "/usr/lib/x86_64-linux-gnu/gz-sim-8/plugins/libgz-sim-physics-system.so", at 0x75f83011f585, in gz::sim::v8::systems::Physics::Update(gz::sim::v8::UpdateInfo const&, gz::sim::v8::EntityComponentManager&)
#14   Object "/usr/lib/x86_64-linux-gnu/gz-sim-8/plugins/libgz-sim-physics-system.so", at 0x75f83011f4b2, in gz::sim::v8::systems::PhysicsPrivate::CreatePhysicsEntities(gz::sim::v8::EntityComponentManager const&, bool)
#13   Object "/usr/lib/x86_64-linux-gnu/gz-sim-8/plugins/libgz-sim-physics-system.so", at 0x75f830119544, in gz::sim::v8::systems::PhysicsPrivate::CreateModelEntities(gz::sim::v8::EntityComponentManager const&, bool)
#12   Object "/usr/lib/x86_64-linux-gnu/gz-sim-8/plugins/libgz-sim-physics-system.so", at 0x75f830198f06, in 
#11   Object "/usr/lib/x86_64-linux-gnu/gz-physics-7/engine-plugins/libgz-physics-dartsim-plugin.so", at 0x75f7f8bf1fb3, in virtual thunk to gz::physics::dartsim::SDFFeatures::ConstructSdfModel(gz::physics::Identity const&, sdf::v14::Model const&)
#10   Object "/usr/lib/x86_64-linux-gnu/gz-physics-7/engine-plugins/libgz-physics-dartsim-plugin.so", at 0x75f7f8bf13fa, in gz::physics::dartsim::SDFFeatures::ConstructSdfModelImpl(unsigned long, sdf::v14::Model const&)
#9    Object "/usr/lib/x86_64-linux-gnu/gz-physics-7/engine-plugins/libgz-physics-dartsim-plugin.so", at 0x75f7f8bed384, in gz::physics::dartsim::SDFFeatures::FindOrConstructLink(std::shared_ptr<dart::dynamics::Skeleton> const&, gz::physics::Identity const&, sdf::v14::Model const&, std::__cxx11::basic_string<char, std::char_traits<char>, std::allocator<char> > const&)
#8    Object "/usr/lib/x86_64-linux-gnu/gz-physics-7/engine-plugins/libgz-physics-dartsim-plugin.so", at 0x75f7f8becdc4, in gz::physics::dartsim::SDFFeatures::ConstructSdfLink(gz::physics::Identity const&, sdf::v14::Link const&)
#7    Object "/usr/lib/x86_64-linux-gnu/gz-physics-7/engine-plugins/libgz-physics-dartsim-plugin.so", at 0x75f7f8bf3a6e, in gz::physics::dartsim::SDFFeatures::ConstructSdfCollision(gz::physics::Identity const&, sdf::v14::Collision const&)
#6    Object "/usr/lib/x86_64-linux-gnu/gz-physics-7/engine-plugins/libgz-physics-dartsim-plugin.so", at 0x75f7f8bf2c34, in 
#5    Object "/lib/x86_64-linux-gnu/libdart.so.6.13", at 0x75f7f8607eff, in dart::dynamics::BoxShape::BoxShape(Eigen::Matrix<double, 3, 1, 0, 3, 1> const&)
#4    Object "/lib/x86_64-linux-gnu/libc.so.6", at 0x75f83e439e95, in __assert_fail
#3    Object "/lib/x86_64-linux-gnu/libc.so.6", at 0x75f83e42871a, in 
#2    Object "/lib/x86_64-linux-gnu/libc.so.6", at 0x75f83e4287f2, in abort
#1    Object "/lib/x86_64-linux-gnu/libc.so.6", at 0x75f83e442475, in raise
#0    Object "/lib/x86_64-linux-gnu/libc.so.6", at 0x75f83e4969fc, in pthread_kill
Aborted (Signal sent by tkill() 481275 1000)
