Warning: Ignoring XDG_SESSION_TYPE=wayland on Gnome. Use QT_QPA_PLATFORM=wayland to run on Wayland anyway.
[1;31m[Err] [UserCommands.cc:1145] [0m[1;31mError Code [0m[1;31m19[0m[1;31m: [0m[1;31mMsg: [0m[1;31mA link named body has invalid inertia.[0m[1;31m[0m
[1;31m[Err] [UserCommands.cc:1145] [0m[1;31mError Code [0m[1;31m30[0m[1;31m: [0m[1;31mMsg: [0m[1;31mError parsing XML from string: Error=XML_ERROR_PARSING_TEXT ErrorID=8 (0x8) Line number=1[0m[1;31m[0m
[1;31m[Err] [UserCommands.cc:1145] [0m[1;31mError Code [0m[1;31m30[0m[1;31m: [0m[1;31mMsg: [0m[1;31mUnable to read SDF string: b"<sdf version="1.11">\n  <model name="model">\n    <static>false</static>\n    <self_collide>false</self_collide>\n    <allow_auto_disable>true</allow_auto_disable>\n    <enable_wind>true</enable_wind>\n    <pose>-4.8861555971941018 -1.9232512658904355 7.1327952961428709 0 0 0</pose>\n    <link name="link_3540">\n      <pose>2.1108086775543118 1.7923359993497066 3.4051044975854383 0 0 0</pose>\n      <inertial>\n        <pose>0 0 0 0 0 0</pose>\n        <mass>1</mass>\n        <inertia>\n          <ixx>1</ixx>\n          <ixy>0</ixy>\n          <ixz>0</ixz>\n          <iyy>1</iyy>\n          <iyz>0</iyz>\n          <izz>1</izz>\n        </inertia>\n      </inertial>\n      <enable_wind>false</enable_wind>\n      <collision name="collision_3540">\n        <pose>0 0 0 0 0 0</pose>\n        <geometry>\n          <box>\n            <size>1.3739759941344627 2.7414812175399965 1.9531010915068627</size>\n          </box>\n        </geometry>\n        <surface>\n          <contact>\n            <collide_bitmask>255</collide_bitmask>\n          </contact>\n          <friction>\n            <ode>\n              <mu>1</mu>\n              <mu2>1</mu2>\n              <slip1>0</slip1>\n              <slip2>0</slip2>\n              <fdir1>0 0 0</fdir1>\n            </ode>\n          </friction>\n        </surface>\n      </collision>\n      <visual name="visual_3540">\n        <pose>0 0 0 0 0 0</pose>\n        <geometry>\n          <box>\n            <size>1.3739759941344627 2.7414812175399965 1.9531010915068627</size>\n          </box>\n        </geometry>\n        <cast_shadows>true</cast_shadows>\n        <laser_retro>0</laser_retro>\n        <transparency>0</transparency>\n        <visibility_flags>4294967295</visibility_flags>\n        <material>\n          <ambient>0.412364542 0.690305829 0.176123634 1</ambient>\n          <diffuse>0.412364542 0.690305829 0.176123634 1</diffuse>\n          <specular>0 0 0 1</specular>\n          <emissive>0 0 0 1</emissive>\n          <render_order>0</render_order>\n          <lighting>true</lighting>\n          <double_sided>false</double_sided>\n          <shader type="pixel"/>\n        </material>\n      </visual>\n    </link>\n    <link name="link_3541">\n      <pose>8.3835004903378127 -3.360894207262497 5.9469728072693782 0 0 0</pose>\n      <inertial>\n        <pose>0 0 0 0 0 0</pose>\n        <mass>1</mass>\n        <inertia>\n          <ixx>1</ixx>\n          <ixy>0</ixy>\n          <ixz>0</ixz>\n          <iyy>1</iyy>\n          <iyz>0</iyz>\n          <izz>1</izz>\n        </inertia>\n      </inertial>\n      <enable_wind>false</enable_wind>\n      <collision name="collision_3541">\n        <pose>0 0 0 0 0 0</pose>\n        <geometry>\n          <box>\n            <size>1.9862134556506903 2.5714937704429133 2.3873813495781868</size>\n          </box>\n        </geometry>\n        <surface>\n          <contact>\n            <collide_bitmask>255</collide_bitmask>\n          </contact>\n          <friction>\n            <ode>\n              <mu>1</mu>\n              <mu2>1</mu2>\n              <slip1>0</slip1>\n              <slip2>0</slip2>\n              <fdir1>0 0 0</fdir1>\n            </ode>\n          </friction>\n        </surface>\n      </collision>\n      <visual name="visual_3541">\n        <pose>0 0 0 0 0 0</pose>\n        <geometry>\n          <box>\n            <size>1.9862134556506903 2.5714937704429133 2.3873813495781868</size>\n          </box>\n        </geometry>\n        <cast_shadows>true</cast_shadows>\n        <laser_retro>0</laser_retro>\n        <transparency>0</transparency>\n        <visibility_flags>4294967295</visibility_flags>\n        <material>\n          <ambient>0.305566847 0.789370298 0.0483000875 1</ambient>\n          <diffuse>0.305566847 0.789370298 0.0483000875 1</diffuse>\n          <specular>0 0 0 1</specular>\n          <emissive>0 0 0 1</emissive>\n          <render_order>0</render_order>\n          <lighting>true</lighting>\n          <double_sided>false</double_sided>\n          <shader type="pixel"/>\n        </material>\n      </visual>\n    </link>\n    <link name="link_3542">\n      <pose>2.8615608455630603 6.1148787422215776 2.655294358837482 0 0 0</pose>\n      <inertial>\n        <pose>0 0 0 0 0 0</pose>\n        <mass>1</mass>\n        <inertia>\n          <ixx>1</ixx>\n          <ixy>0</ixy>\n          <ixz>0</ixz>\n          <iyy>1</iyy>\n          <iyz>0</iyz>\n          <izz>1</izz>\n        </inertia>\n      </inertial>\n      <enable_wind>false</enable_wind>\n      <collision name="collision_3542">\n        <pose>0 0 0 0 0 0</pose>\n        <geometry>\n          <capsule>\n            <radius>1.1400303789457968</radius>\n            <length>2.4190954930277115</length>\n          </capsule>\n        </geometry>\n        <surface>\n          <contact>\n            <collide_bitmask>255</collide_bitmask>\n          </contact>\n          <friction>\n            <ode>\n              <mu>1</mu>\n              <mu2>1</mu2>\n              <slip1>0</slip1>\n              <slip2>0</slip2>\n              <fdir1>0 0 0</fdir1>\n            </ode>\n          </friction>\n        </surface>\n      </collision>\n      <visual name="visual_3542">\n        <pose>0 0 0 0 0 0</pose>\n        <geometry>\n          <capsule>\n            <radius>1.1400303789457968</radius>\n            <length>2.4190954930277115</length>\n          </capsule>\n        </geometry>\n        <cast_shadows>true</cast_shadows>\n        <laser_retro>0</laser_retro>\n        <transparency>0</transparency>\n        <visibility_flags>4294967295</visibility_flags>\n        <material>\n          <ambient>0.942998707 0.49920103 0.201169342 1</ambient>\n          <diffuse>0.942998707 0.49920103 0.201169342 1</diffuse>\n          <specular>0 0 0 1</specular>\n          <emissive>0 0 0 1</emissive>\n          <render_order>0</render_order>\n          <lighting>true</lighting>\n          <double_sided>false</double_sided>\n          <shader type="pixel"/>\n        </material>\n      </visual>\n    </link>\n    <joint name="joint_2360" type="screw">\n      <pose>0 0 0 0 0 0</pose>\n      <parent>link_3541</parent>\n      <child>link_3542</child>\n      <axis>\n        <xyz>0.037530862652928883 0.9309269003824121 0.36327199244219438</xyz>\n        <limit>\n          <lower>-inf</lower>\n          <upper>inf</upper>\n          <effort>inf</effort>\n          <velocity>5.8494189872173816</velocity>\n          <stiffness>100000000</stiffness>\n          <dissipation>1</dissipation>\n        </limit>\n        <dynamics>\n          <spring_reference>0</spring_reference>\n          <spring_stiffness>0</spring_stiffness>\n          <damping>0</damping>\n          <friction>0</friction>\n        </dynamics>\n      </axis>\n      <axis2>\n        <xyz>0.72132113767553563 0.46862267683203906 0.50998882644744781</xyz>\n        <limit>\n          <lower>-inf</lower>\n          <upper>inf</upper>\n          <effort>inf</effort>\n          <velocity>3.44418605822458</velocity>\n          <stiffness>100000000</stiffness>\n          <dissipation>1</dissipation>\n        </limit>\n        <dynamics>\n          <spring_reference>0</spring_reference>\n          <spring_stiffness>0</spring_stiffness>\n          <damping>0</damping>\n          <friction>0</friction>\n        </dynamics>\n      </axis2>\n      <thread_pitch>-6.2831853071795862</thread_pitch>\n    </joint>\n    <joint name="joint_2361" type="gearbox">\n      <pose>0 0 0 0 0 0</pose>\n      <parent>link_3541</parent>\n      <child>link_3540</child>\n      <axis>\n        <xyz>0.74316015224576071 0.57597995619795606 0.34052911501405952</xyz>\n        <limit>\n          <lower>-inf</lower>\n          <upper>inf</upper>\n          <effort>inf</effort>\n          <velocity>8.8139705941472162</velocity>\n          <stiffness>100000000</stiffness>\n          <dissipation>1</dissipation>\n        </limit>\n        <dynamics>\n          <spring_reference>0</spring_reference>\n          <spring_stiffness>0</spring_stiffness>\n          <damping>0</damping>\n          <friction>0</friction>\n        </dynamics>\n      </axis>\n      <axis2>\n        <xyz>0.02455835739009115 0.43860550618400568 0.89834408609806782</xyz>\n        <limit>\n          <lower>-inf</lower>\n          <upper>inf</upper>\n          <effort>inf</effort>\n          <velocity>6.1088165312491691</velocity>\n          <stiffness>100000000</stiffness>\n          <dissipation>1</dissipation>\n        </limit>\n        <dynamics>\n          <spring_reference>0</spring_reference>\n          <spring_stiffness>0</spring_stiffness>\n          <damping>0</damping>\n          <friction>0</friction>\n        </dynamics>\n      </axis2>\n    </joint>\n  </model>\n</sdf>\n"[0m[1;31m[0m
[1;31m[Err] [LiftDrag.cc:188] [0m[1;31mLink with name[[0m[1;31melevator[0m[1;31m] not found. [0m[1;31mThe LiftDrag will not generate forces[0m
[1;33mWarning [Utils.cc:132][0m [/sdf/plugin[@name="gz::sim::systems::ShaderParam"]:<data-string>:L1]: XML Element[plugin], child of element[sdf], not defined in SDF. Copying[plugin] as children of [sdf].
[1;33mWarning [Utils.cc:132][0m [/sdf/plugin[@name="gz::sim::systems::ShaderParam"]:<data-string>:L1]: XML Element[plugin], child of element[sdf], not defined in SDF. Copying[plugin] as children of [sdf].
[1;31m[Err] [LiftDrag.cc:188] [0m[1;31mLink with name[[0m[1;31mblade_2[0m[1;31m] not found. [0m[1;31mThe LiftDrag will not generate forces[0m
[1;33mWarning [Utils.cc:132][0m [/sdf/plugin[@name="gz::sim::systems::ShaderParam"]:<data-string>:L1]: XML Element[plugin], child of element[sdf], not defined in SDF. Copying[plugin] as children of [sdf].
[1;33mWarning [Utils.cc:132][0m [/sdf/plugin[@name="gz::sim::systems::ShaderParam"]:<data-string>:L1]: XML Element[plugin], child of element[sdf], not defined in SDF. Copying[plugin] as children of [sdf].
[1;33mWarning [Utils.cc:132][0m [/sdf/model[@name="propeller_plane"]/joint[@name="wheel_1_joint"]/axis/use_parent_model_frame:<data-string>:L345]: XML Element[use_parent_model_frame], child of element[axis], not defined in SDF. Copying[use_parent_model_frame] as children of [axis].
[1;33mWarning [Utils.cc:132][0m [/sdf/model[@name="propeller_plane"]/joint[@name="wheel_2_joint"]/axis/use_parent_model_frame:<data-string>:L366]: XML Element[use_parent_model_frame], child of element[axis], not defined in SDF. Copying[use_parent_model_frame] as children of [axis].
[1;33mWarning [Utils.cc:132][0m [/sdf/model[@name="propeller_plane"]/joint[@name="wheel_3_joint"]/axis/use_parent_model_frame:<data-string>:L387]: XML Element[use_parent_model_frame], child of element[axis], not defined in SDF. Copying[use_parent_model_frame] as children of [axis].
[1;33mWarning [Utils.cc:132][0m [/sdf/model[@name="propeller_plane"]/joint[@name="rod_1_joint"]/axis/use_parent_model_frame:<data-string>:L407]: XML Element[use_parent_model_frame], child of element[axis], not defined in SDF. Copying[use_parent_model_frame] as children of [axis].

ODE INTERNAL ERROR 1: assertion "aabbBound >= dMinIntExact && aabbBound < dMaxIntExact" failed in collide() [collision_space.cpp:460]
Stack trace (most recent call last):
#31   Object "/lib/x86_64-linux-gnu/libruby-3.0.so.3.0", at 0x723660631fc5, in 
#30   Object "/lib/x86_64-linux-gnu/libruby-3.0.so.3.0", at 0x72366062fc34, in 
#29   Object "/lib/x86_64-linux-gnu/libruby-3.0.so.3.0", at 0x72366057ba4e, in 
#28   Object "/lib/x86_64-linux-gnu/libruby-3.0.so.3.0", at 0x7236604a69ac, in rb_protect
#27   Object "/lib/x86_64-linux-gnu/libruby-3.0.so.3.0", at 0x72366063ec61, in rb_yield
#26   Object "/lib/x86_64-linux-gnu/libruby-3.0.so.3.0", at 0x72366063a30c, in rb_vm_exec
#25   Object "/lib/x86_64-linux-gnu/libruby-3.0.so.3.0", at 0x723660634c96, in 
#24   Object "/lib/x86_64-linux-gnu/libruby-3.0.so.3.0", at 0x723660631fc5, in 
#23   Object "/lib/x86_64-linux-gnu/libruby-3.0.so.3.0", at 0x72366062fc34, in 
#22   Object "/usr/lib/x86_64-linux-gnu/ruby/3.0.0/fiddle.so", at 0x72366025444b, in 
#21   Object "/lib/x86_64-linux-gnu/libruby-3.0.so.3.0", at 0x7236605fd088, in rb_nogvl
#20   Object "/usr/lib/x86_64-linux-gnu/ruby/3.0.0/fiddle.so", at 0x723660253d6b, in 
#19   Object "/lib/x86_64-linux-gnu/libffi.so.8", at 0x72365fef6492, in 
#18   Object "/lib/x86_64-linux-gnu/libffi.so.8", at 0x72365fef9e2d, in 
#17   Object "/usr/lib/x86_64-linux-gnu/libgz-sim8-gz.so.8.6.0", at 0x72365fea6605, in runServer
#16   Object "/lib/x86_64-linux-gnu/libgz-sim8.so.8", at 0x72365a93d485, in 
#15   Object "/lib/x86_64-linux-gnu/libgz-sim8.so.8", at 0x72365a94d8a2, in gz::sim::v8::SimulationRunner::Run(unsigned long)
#14   Object "/lib/x86_64-linux-gnu/libgz-sim8.so.8", at 0x72365a94ce60, in gz::sim::v8::SimulationRunner::Step(gz::sim::v8::UpdateInfo const&)
#13   Object "/lib/x86_64-linux-gnu/libgz-sim8.so.8", at 0x72365a94c0a2, in gz::sim::v8::SimulationRunner::UpdateSystems()
#12   Object "/usr/lib/x86_64-linux-gnu/gz-sim-8/plugins/libgz-sim-physics-system.so", at 0x723651d1f5b6, in gz::sim::v8::systems::Physics::Update(gz::sim::v8::UpdateInfo const&, gz::sim::v8::EntityComponentManager&)
#11   Object "/usr/lib/x86_64-linux-gnu/gz-sim-8/plugins/libgz-sim-physics-system.so", at 0x723651d1fc31, in gz::sim::v8::systems::PhysicsPrivate::Step(std::chrono::duration<long, std::ratio<1l, 1000000000l> > const&)
#10   Object "/usr/lib/x86_64-linux-gnu/gz-physics-7/engine-plugins/libgz-physics-dartsim-plugin.so", at 0x72361a80900b, in gz::physics::dartsim::SimulationFeatures::WorldForwardStep(gz::physics::Identity const&, gz::physics::SpecifyData<gz::physics::RequireData<gz::physics::WorldPoses>, gz::physics::ExpectData<gz::physics::ChangedWorldPoses, gz::physics::Contacts, gz::physics::JointPositions> >&, gz::physics::CompositeData&, gz::physics::ExpectData<gz::physics::ApplyExternalForceTorques, gz::physics::ApplyGeneralizedForces, gz::physics::VelocityControlCommands, gz::physics::ServoControlCommands, std::chrono::duration<long, std::ratio<1l, 1000000000l> > > const&)
#9    Object "/lib/x86_64-linux-gnu/libdart.so.6.13", at 0x72361a3936d3, in dart::simulation::World::step(bool)
#8    Object "/lib/x86_64-linux-gnu/libdart.so.6.13", at 0x72361a378ca5, in dart::constraint::ConstraintSolver::solve()
#7    Object "/lib/x86_64-linux-gnu/libdart.so.6.13", at 0x72361a377494, in dart::constraint::ConstraintSolver::updateConstraints()
#6    Object "/usr/lib/x86_64-linux-gnu/gz-physics-7/engine-plugins/libgz-physics-dartsim-plugin.so", at 0x72361a7d73b3, in dart::collision::GzOdeCollisionDetector::collide(dart::collision::CollisionGroup*, dart::collision::CollisionOption const&, dart::collision::CollisionResult*)
#5    Object "/lib/x86_64-linux-gnu/libdart-collision-ode.so.6.13", at 0x723648c47d1b, in dart::collision::OdeCollisionDetector::collide(dart::collision::CollisionGroup*, dart::collision::CollisionOption const&, dart::collision::CollisionResult*)
#4    Object "/lib/x86_64-linux-gnu/libode.so.8", at 0x723648249266, in dxHashSpace::collide(void*, void (*)(void*, dxGeom*, dxGeom*))
#3    Object "/lib/x86_64-linux-gnu/libode.so.8", at 0x7236482517b7, in dDebug
#2    Object "/lib/x86_64-linux-gnu/libc.so.6", at 0x7236600287f2, in abort
#1    Object "/lib/x86_64-linux-gnu/libc.so.6", at 0x723660042475, in raise
#0    Object "/lib/x86_64-linux-gnu/libc.so.6", at 0x7236600969fc, in pthread_kill
Aborted (Signal sent by tkill() 484985 1000)
