Warning: Ignoring XDG_SESSION_TYPE=wayland on Gnome. Use QT_QPA_PLATFORM=wayland to run on Wayland anyway.
[1;31m[Err] [UserCommands.cc:1145] [0m[1;31mError Code [0m[1;31m20[0m[1;31m: [0m[1;31mMsg: [0m[1;31mChild frame with name[J5QnS84ecf6Fm45] specified by joint with name[rear_left_wheel_joint] not found in model with name[vehicle_blue].[0m[1;31m[0m
[1;31m[Err] [UserCommands.cc:1145] [0m[1;31mError Code [0m[1;31m25[0m[1;31m: [0m[1;31mMsg: [0m[1;31mFrameAttachedToGraph error, Non-LINK vertex with name [vehicle_blue::rear_left_wheel_joint] is disconnected; it should have 1 outgoing edge in MODEL attached_to graph.[0m[1;31m[0m
[1;31m[Err] [UserCommands.cc:1145] [0m[1;31mError Code [0m[1;31m25[0m[1;31m: [0m[1;31mMsg: [0m[1;31mGraph has __model__ scope but sink vertex named [vehicle_blue::rear_left_wheel_joint] does not have FrameType LINK or STATIC_MODEL when starting from vertex with name [vehicle_blue::rear_left_wheel_joint].[0m[1;31m[0m
[1;31m[Err] [UserCommands.cc:1145] [0m[1;31mError Code [0m[1;31m26[0m[1;31m: [0m[1;31mMsg: [0m[1;31mrelative_to name[J5QnS84ecf6Fm45] specified by joint with name[rear_left_wheel_joint] does not match a nested model, link, joint, or frame name in model with name[vehicle_blue].[0m[1;31m[0m
[1;31m[Err] [UserCommands.cc:1145] [0m[1;31mError Code [0m[1;31m28[0m[1;31m: [0m[1;31mMsg: [0m[1;31mPoseRelativeToGraph error, Vertex with name [vehicle_blue::rear_left_wheel_joint] is disconnected; it should have 1 incoming edge in MODEL relative_to graph.[0m[1;31m[0m
[1;31m[Err] [UserCommands.cc:1145] [0m[1;31mError Code [0m[1;31m28[0m[1;31m: [0m[1;31mMsg: [0m[1;31mPoseRelativeToGraph unable to find path to source vertex when starting from vertex with id [10].[0m[1;31m[0m
[1;31m[Err] [UserCommands.cc:1145] [0m[1;31mError Code [0m[1;31m20[0m[1;31m: [0m[1;31mMsg: [0m[1;31mchild frame with name[J5QnS84ecf6Fm45] specified by joint with name[rear_left_wheel_joint] not found in model with name[vehicle_blue].[0m[1;31m[0m
[1;31m[Err] [UserCommands.cc:1145] [0m[1;31mError Code [0m[1;31m23[0m[1;31m: [0m[1;31mMsg: [0m[1;31mFrameAttachedToGraph unable to find unique frame with name [J5QnS84ecf6Fm45] in graph.[0m[1;31m[0m
[1;31m[Err] [UserCommands.cc:1145] [0m[1;31mError Code [0m[1;31m28[0m[1;31m: [0m[1;31mMsg: [0m[1;31mPoseRelativeToGraph unable to find path to source vertex when starting from vertex with id [10].[0m[1;31m[0m
[1;31m[Err] [UserCommands.cc:1145] [0m[1;31mError Code [0m[1;31m28[0m[1;31m: [0m[1;31mMsg: [0m[1;31mPoseRelativeToGraph unable to find path to source vertex when starting from vertex with id [10].[0m[1;31m[0m
[1;31m[Err] [UserCommands.cc:1145] [0m[1;31mError Code [0m[1;31m30[0m[1;31m: [0m[1;31mMsg: [0m[1;31mError parsing XML from string: Error=XML_ERROR_PARSING_TEXT ErrorID=8 (0x8) Line number=1[0m[1;31m[0m
[1;31m[Err] [UserCommands.cc:1145] [0m[1;31mError Code [0m[1;31m30[0m[1;31m: [0m[1;31mMsg: [0m[1;31mUnable to read SDF string: b"<sdf version="1.11">\n  <model name="model">\n    <static>false</static>\n    <self_collide>true</self_collide>\n    <allow_auto_disable>true</allow_auto_disable>\n    <enable_wind>false</enable_wind>\n    <pose>-0.96909119867389926 -5.3591085158370522 1.7955694988916848 0 0 0</pose>\n    <link name="link_1392">\n      <pose>6.2828519028422321 3.3022331290219338 1.1726830268289701 0 0 0</pose>\n      <inertial>\n        <pose>0 0 0 0 0 0</pose>\n        <mass>1</mass>\n        <inertia>\n          <ixx>1</ixx>\n          <ixy>0</ixy>\n          <ixz>0</ixz>\n          <iyy>1</iyy>\n          <iyz>0</iyz>\n          <izz>1</izz>\n        </inertia>\n      </inertial>\n      <enable_wind>false</enable_wind>\n      <collision name="collision_1392">\n        <pose>0 0 0 0 0 0</pose>\n        <geometry>\n          <box>\n            <size>1.7019665337683429 1.8201699639710567 2.7835344483306028</size>\n          </box>\n        </geometry>\n        <surface>\n          <contact>\n            <collide_bitmask>255</collide_bitmask>\n          </contact>\n          <friction>\n            <ode>\n              <mu>1</mu>\n              <mu2>1</mu2>\n              <slip1>0</slip1>\n              <slip2>0</slip2>\n              <fdir1>0 0 0</fdir1>\n            </ode>\n          </friction>\n        </surface>\n      </collision>\n      <visual name="visual_1392">\n        <pose>0 0 0 0 0 0</pose>\n        <geometry>\n          <box>\n            <size>1.7019665337683429 1.8201699639710567 2.7835344483306028</size>\n          </box>\n        </geometry>\n        <cast_shadows>true</cast_shadows>\n        <laser_retro>0</laser_retro>\n        <transparency>0</transparency>\n        <visibility_flags>4294967295</visibility_flags>\n        <material>\n          <ambient>0.730998397 0.211344838 0.945913374 1</ambient>\n          <diffuse>0.730998397 0.211344838 0.945913374 1</diffuse>\n          <specular>0 0 0 1</specular>\n          <emissive>0 0 0 1</emissive>\n          <render_order>0</render_order>\n          <lighting>true</lighting>\n          <double_sided>false</double_sided>\n          <shader type="pixel"/>\n        </material>\n      </visual>\n    </link>\n    <link name="link_1393">\n      <pose>-5.4561841508493636 -5.3209870129586978 9.0864793121853396 0 0 0</pose>\n      <inertial>\n        <pose>0 0 0 0 0 0</pose>\n        <mass>1</mass>\n        <inertia>\n          <ixx>1</ixx>\n          <ixy>0</ixy>\n          <ixz>0</ixz>\n          <iyy>1</iyy>\n          <iyz>0</iyz>\n          <izz>1</izz>\n        </inertia>\n      </inertial>\n      <enable_wind>false</enable_wind>\n      <collision name="collision_1393">\n        <pose>0 0 0 0 0 0</pose>\n        <geometry>\n          <box>\n            <size>2.775525799504992 1.6683732303805019 2.7586943472475327</size>\n          </box>\n        </geometry>\n        <surface>\n          <contact>\n            <collide_bitmask>255</collide_bitmask>\n          </contact>\n          <friction>\n            <ode>\n              <mu>1</mu>\n              <mu2>1</mu2>\n              <slip1>0</slip1>\n              <slip2>0</slip2>\n              <fdir1>0 0 0</fdir1>\n            </ode>\n          </friction>\n        </surface>\n      </collision>\n      <visual name="visual_1393">\n        <pose>0 0 0 0 0 0</pose>\n        <geometry>\n          <box>\n            <size>2.775525799504992 1.6683732303805019 2.7586943472475327</size>\n          </box>\n        </geometry>\n        <cast_shadows>true</cast_shadows>\n        <laser_retro>0</laser_retro>\n        <transparency>0</transparency>\n        <visibility_flags>4294967295</visibility_flags>\n        <material>\n          <ambient>0.811238647 0.763852954 0.943239689 1</ambient>\n          <diffuse>0.811238647 0.763852954 0.943239689 1</diffuse>\n          <specular>0 0 0 1</specular>\n          <emissive>0 0 0 1</emissive>\n          <render_order>0</render_order>\n          <lighting>true</lighting>\n          <double_sided>false</double_sided>\n          <shader type="pixel"/>\n        </material>\n      </visual>\n    </link>\n    <link name="link_1394">\n      <pose>-9.958086667678236 7.9883356352296957 6.6291561656429945 0 0 0</pose>\n      <inertial>\n        <pose>0 0 0 0 0 0</pose>\n        <mass>1</mass>\n        <inertia>\n          <ixx>1</ixx>\n          <ixy>0</ixy>\n          <ixz>0</ixz>\n          <iyy>1</iyy>\n          <iyz>0</iyz>\n          <izz>1</izz>\n        </inertia>\n      </inertial>\n      <enable_wind>false</enable_wind>\n      <collision name="collision_1394">\n        <pose>0 0 0 0 0 0</pose>\n        <geometry>\n          <capsule>\n            <radius>2.7726322680146707</radius>\n            <length>2.618427715692937</length>\n          </capsule>\n        </geometry>\n        <surface>\n          <contact>\n            <collide_bitmask>255</collide_bitmask>\n          </contact>\n          <friction>\n            <ode>\n              <mu>1</mu>\n              <mu2>1</mu2>\n              <slip1>0</slip1>\n              <slip2>0</slip2>\n              <fdir1>0 0 0</fdir1>\n            </ode>\n          </friction>\n        </surface>\n      </collision>\n      <visual name="visual_1394">\n        <pose>0 0 0 0 0 0</pose>\n        <geometry>\n          <capsule>\n            <radius>2.7726322680146707</radius>\n            <length>2.618427715692937</length>\n          </capsule>\n        </geometry>\n        <cast_shadows>true</cast_shadows>\n        <laser_retro>0</laser_retro>\n        <transparency>0</transparency>\n        <visibility_flags>4294967295</visibility_flags>\n        <material>\n          <ambient>0.356077462 0.724557996 0.59179461 1</ambient>\n          <diffuse>0.356077462 0.724557996 0.59179461 1</diffuse>\n          <specular>0 0 0 1</specular>\n          <emissive>0 0 0 1</emissive>\n          <render_order>0</render_order>\n          <lighting>true</lighting>\n          <double_sided>false</double_sided>\n          <shader type="pixel"/>\n        </material>\n      </visual>\n    </link>\n    <joint name="joint_928" type="ball">\n      <pose>0 0 0 0 0 0</pose>\n      <parent>link_1393</parent>\n      <child>link_1392</child>\n      <axis>\n        <xyz>0.22539054041605464 0.68634295021318048 0.69147122787837423</xyz>\n        <limit>\n          <lower>-inf</lower>\n          <upper>inf</upper>\n          <effort>inf</effort>\n          <velocity>1.9683475336308565</velocity>\n          <stiffness>100000000</stiffness>\n          <dissipation>1</dissipation>\n        </limit>\n        <dynamics>\n          <spring_reference>0</spring_reference>\n          <spring_stiffness>0</spring_stiffness>\n          <damping>0</damping>\n          <friction>0</friction>\n        </dynamics>\n      </axis>\n      <axis2>\n        <xyz>0.82135719912806349 0.13331799009242151 0.55461578138222822</xyz>\n        <limit>\n          <lower>-inf</lower>\n          <upper>P4K</upper>\n          <effort>inf</effort>\n          <velocity>7.861977189966427</velocity>\n          <stiffness>100000000</stiffness>\n          <dissipation>1</dissipation>\n        </limit>\n        <dynamics>\n          <spring_reference>0</spring_reference>\n          <spring_stiffness>0</spring_stiffness>\n          <damping>0</damping>\n          <friction>0</friction>\n        </dynamics>\n      </axis2>\n    </joint>\n    <joint name="joint_929" type="continuous">\n      <pose>0 0 0 0 0 0</pose>\n      <parent>link_1393</parent>\n      <child>link_1392</child>\n      <axis>\n        <xyz>0.42853761780423444 0.88897200164398049 0.16150631696551865</xyz>\n        <limit>\n          <lower>-inf</lower>\n          <upper>inf</upper>\n          <effort>inf</effort>\n          <velocity>8.9471482359307331</velocity>\n          <stiffness>100000000</stiffness>\n          <dissipation>1</dissipation>\n        </limit>\n        <dynamics>\n          <spring_reference>0</spring_reference>\n          <spring_stiffness>0</spring_stiffness>\n          <damping>0</damping>\n          <friction>0</friction>\n        </dynamics>\n      </axis>\n      <axis2>\n        <xyz>0.22887661764586675 0.21274016326344419 0.94992479535468011</xyz>\n        <limit>\n          <lower>-inf</lower>\n          <upper>inf</upper>\n          <effort>inf</effort>\n          <velocity>3.4939853853501712</velocity>\n          <stiffness>100000000</stiffness>\n          <dissipation>1</dissipation>\n        </limit>\n        <dynamics>\n          <spring_reference>0</spring_reference>\n          <spring_stiffness>0</spring_stiffness>\n          <damping>0</damping>\n          <friction>0</friction>\n        </dynamics>\n      </axis2>\n    </joint>\n  </model>\n</sdf>\n"[0m[1;31m[0m
Stack trace (most recent call last):
#28   Object "[0xffffffffffffffff]", at 0xffffffffffffffff, in 
#27   Object "gz sim server", at 0x599c0bafa1c4, in _start
#26   Object "/lib/x86_64-linux-gnu/libc.so.6", at 0x7640ecc29e3f, in __libc_start_main
#25   Object "/lib/x86_64-linux-gnu/libc.so.6", at 0x7640ecc29d8f, in 
#24   Object "gz sim server", at 0x599c0bafa17e, in 
#23   Object "/lib/x86_64-linux-gnu/libruby-3.0.so.3.0", at 0x7640ed0a8e19, in ruby_run_node
#22   Object "/lib/x86_64-linux-gnu/libruby-3.0.so.3.0", at 0x7640ed0a5317, in 
#21   Object "/lib/x86_64-linux-gnu/libruby-3.0.so.3.0", at 0x7640ed23a30c, in rb_vm_exec
#20   Object "/lib/x86_64-linux-gnu/libruby-3.0.so.3.0", at 0x7640ed234c96, in 
#19   Object "/lib/x86_64-linux-gnu/libruby-3.0.so.3.0", at 0x7640ed231fc5, in 
#18   Object "/lib/x86_64-linux-gnu/libruby-3.0.so.3.0", at 0x7640ed22fc34, in 
#17   Object "/lib/x86_64-linux-gnu/libruby-3.0.so.3.0", at 0x7640ed17ba4e, in 
#16   Object "/lib/x86_64-linux-gnu/libruby-3.0.so.3.0", at 0x7640ed0a69ac, in rb_protect
#15   Object "/lib/x86_64-linux-gnu/libruby-3.0.so.3.0", at 0x7640ed23ec61, in rb_yield
#14   Object "/lib/x86_64-linux-gnu/libruby-3.0.so.3.0", at 0x7640ed23a30c, in rb_vm_exec
#13   Object "/lib/x86_64-linux-gnu/libruby-3.0.so.3.0", at 0x7640ed234c96, in 
#12   Object "/lib/x86_64-linux-gnu/libruby-3.0.so.3.0", at 0x7640ed231fc5, in 
#11   Object "/lib/x86_64-linux-gnu/libruby-3.0.so.3.0", at 0x7640ed22fc34, in 
#10   Object "/usr/lib/x86_64-linux-gnu/ruby/3.0.0/fiddle.so", at 0x7640ed3a344b, in 
#9    Object "/lib/x86_64-linux-gnu/libruby-3.0.so.3.0", at 0x7640ed1fd088, in rb_nogvl
#8    Object "/usr/lib/x86_64-linux-gnu/ruby/3.0.0/fiddle.so", at 0x7640ed3a2d6b, in 
#7    Object "/lib/x86_64-linux-gnu/libffi.so.8", at 0x7640ecf10492, in 
#6    Object "/lib/x86_64-linux-gnu/libffi.so.8", at 0x7640ecf13e2d, in 
#5    Object "/usr/lib/x86_64-linux-gnu/libgz-sim8-gz.so.8.6.0", at 0x7640eceb4605, in runServer
#4    Object "/lib/x86_64-linux-gnu/libgz-sim8.so.8", at 0x7640e753d485, in 
#3    Object "/lib/x86_64-linux-gnu/libgz-sim8.so.8", at 0x7640e754d8a2, in gz::sim::v8::SimulationRunner::Run(unsigned long)
#2    Object "/lib/x86_64-linux-gnu/libgz-sim8.so.8", at 0x7640e754ce60, in gz::sim::v8::SimulationRunner::Step(gz::sim::v8::UpdateInfo const&)
#1    Object "/lib/x86_64-linux-gnu/libgz-sim8.so.8", at 0x7640e754c031, in gz::sim::v8::SimulationRunner::UpdateSystems()
#0    Object "/usr/lib/x86_64-linux-gnu/gz-sim-8/plugins/libgz-sim-follow-actor-system.so", at 0x7640d56269b3, in gz::sim::v8::systems::FollowActor::PreUpdate(gz::sim::v8::UpdateInfo const&, gz::sim::v8::EntityComponentManager&)
Segmentation fault (Address not mapped to object [0x10])
