<sdf version='1.11'>
  <world name='world_0'>
    <gravity>0 0 -9.8066499999999994</gravity>
    <magnetic_field>5.5644999999999998e-06 2.2875799999999999e-05 -4.2388400000000002e-05</magnetic_field>
    <wind>
      <linear_velocity>5 4 8</linear_velocity>
    </wind>
    <physics default='false' type='ode'>
      <max_step_size>0.001</max_step_size>
      <real_time_factor>1</real_time_factor>
      <max_contacts>20</max_contacts>
    </physics>
    <model name='model_0'>
      <static>false</static>
      <self_collide>false</self_collide>
      <allow_auto_disable>true</allow_auto_disable>
      <enable_wind>true</enable_wind>
      <pose>-1.7013108285399188 3.9956847300309146 7.6209165316334158 0 0 0</pose>
      <link name='link_0'>
        <pose>8.8026901692493595 9.7347208413973974 3.0396011883190424 0 0 0</pose>
        <inertial>
          <pose>0 0 0 0 0 0</pose>
          <mass>1</mass>
          <inertia>
            <ixx>1</ixx>
            <ixy>0</ixy>
            <ixz>0</ixz>
            <iyy>1</iyy>
            <iyz>0</iyz>
            <izz>1</izz>
          </inertia>
        </inertial>
        <enable_wind>false</enable_wind>
        <collision name='collision_0'>
          <pose>0 0 0 0 0 0</pose>
          <geometry>
            <sphere>
              <radius>1.9818578104661868</radius>
            </sphere>
          </geometry>
          <surface>
            <contact>
              <collide_bitmask>255</collide_bitmask>
            </contact>
            <friction>
              <ode>
                <mu>1</mu>
                <mu2>1</mu2>
                <slip1>0</slip1>
                <slip2>0</slip2>
                <fdir1>0 0 0</fdir1>
              </ode>
            </friction>
          </surface>
        </collision>
        <visual name='visual_0'>
          <pose>0 0 0 0 0 0</pose>
          <geometry>
            <sphere>
              <radius>1.9818578104661868</radius>
            </sphere>
          </geometry>
          <cast_shadows>true</cast_shadows>
          <laser_retro>0</laser_retro>
          <transparency>0</transparency>
          <visibility_flags>4294967295</visibility_flags>
          <material>
            <ambient>0.441234916 0.824859083 0.671233833 1</ambient>
            <diffuse>0.441234916 0.824859083 0.671233833 1</diffuse>
            <specular>0 0 0 1</specular>
            <emissive>0 0 0 1</emissive>
            <render_order>0</render_order>
            <lighting>true</lighting>
            <double_sided>false</double_sided>
            <shader type='pixel'/>
          </material>
        </visual>
      </link>
      <link name='link_1'>
        <pose>3.5573320959519066 0.43834809803141184 6.2296417556323398 0 0 0</pose>
        <inertial>
          <pose>0 0 0 0 0 0</pose>
          <mass>1</mass>
          <inertia>
            <ixx>1</ixx>
            <ixy>0</ixy>
            <ixz>0</ixz>
            <iyy>1</iyy>
            <iyz>0</iyz>
            <izz>1</izz>
          </inertia>
        </inertial>
        <enable_wind>false</enable_wind>
        <collision name='collision_1'>
          <pose>0 0 0 0 0 0</pose>
          <geometry>
            <cylinder>
              <radius>1.3228815557502744</radius>
              <length>2.0532741449490342</length>
            </cylinder>
          </geometry>
          <surface>
            <contact>
              <collide_bitmask>255</collide_bitmask>
            </contact>
            <friction>
              <ode>
                <mu>1</mu>
                <mu2>1</mu2>
                <slip1>0</slip1>
                <slip2>0</slip2>
                <fdir1>0 0 0</fdir1>
              </ode>
            </friction>
          </surface>
        </collision>
        <visual name='visual_1'>
          <pose>0 0 0 0 0 0</pose>
          <geometry>
            <cylinder>
              <radius>1.3228815557502744</radius>
              <length>2.0532741449490342</length>
            </cylinder>
          </geometry>
          <cast_shadows>true</cast_shadows>
          <laser_retro>0</laser_retro>
          <transparency>0</transparency>
          <visibility_flags>4294967295</visibility_flags>
          <material>
            <ambient>0.5432356 0.909838498 0.29657802 1</ambient>
            <diffuse>0.5432356 0.909838498 0.29657802 1</diffuse>
            <specular>0 0 0 1</specular>
            <emissive>0 0 0 1</emissive>
            <render_order>0</render_order>
            <lighting>true</lighting>
            <double_sided>false</double_sided>
            <shader type='pixel'/>
          </material>
        </visual>
      </link>
      <link name='link_2'>
        <pose>7.849859054883062 4.9029477625384352 6.8431989123165762 0 0 0</pose>
        <inertial>
          <pose>0 0 0 0 0 0</pose>
          <mass>1</mass>
          <inertia>
            <ixx>1</ixx>
            <ixy>0</ixy>
            <ixz>0</ixz>
            <iyy>1</iyy>
            <iyz>0</iyz>
            <izz>1</izz>
          </inertia>
        </inertial>
        <enable_wind>false</enable_wind>
        <collision name='collision_2'>
          <pose>0 0 0 0 0 0</pose>
          <geometry>
            <cylinder>
              <radius>2.8594987127424369</radius>
              <length>1.3510457653348986</length>
            </cylinder>
          </geometry>
          <surface>
            <contact>
              <collide_bitmask>255</collide_bitmask>
            </contact>
            <friction>
              <ode>
                <mu>1</mu>
                <mu2>1</mu2>
                <slip1>0</slip1>
                <slip2>0</slip2>
                <fdir1>0 0 0</fdir1>
              </ode>
            </friction>
          </surface>
        </collision>
        <visual name='visual_2'>
          <pose>0 0 0 0 0 0</pose>
          <geometry>
            <cylinder>
              <radius>2.8594987127424369</radius>
              <length>1.3510457653348986</length>
            </cylinder>
          </geometry>
          <cast_shadows>true</cast_shadows>
          <laser_retro>0</laser_retro>
          <transparency>0</transparency>
          <visibility_flags>4294967295</visibility_flags>
          <material>
            <ambient>0.802482784 0.035339199 0.339993328 1</ambient>
            <diffuse>0.802482784 0.035339199 0.339993328 1</diffuse>
            <specular>0 0 0 1</specular>
            <emissive>0 0 0 1</emissive>
            <render_order>0</render_order>
            <lighting>true</lighting>
            <double_sided>false</double_sided>
            <shader type='pixel'/>
          </material>
        </visual>
      </link>
      <joint name='joint_0' type='prismatic'>
        <pose>0 0 0 0 0 0</pose>
        <parent>link_1</parent>
        <child>link_0</child>
        <axis>
          <xyz>0.24355268258616844 0.28353632706645404 0.92751778529511009</xyz>
          <limit>
            <lower>-inf</lower>
            <upper>inf</upper>
            <effort>inf</effort>
            <velocity>8.8048851247876989</velocity>
            <stiffness>100000000</stiffness>
            <dissipation>1</dissipation>
          </limit>
          <dynamics>
            <spring_reference>0</spring_reference>
            <spring_stiffness>0</spring_stiffness>
            <damping>0</damping>
            <friction>0</friction>
          </dynamics>
        </axis>
        <axis2>
          <xyz>0.49345998424115528 0.33595371397339874 0.8022670041951111</xyz>
          <limit>
            <lower>-inf</lower>
            <upper>inf</upper>
            <effort>inf</effort>
            <velocity>0.0804402775461599</velocity>
            <stiffness>100000000</stiffness>
            <dissipation>1</dissipation>
          </limit>
          <dynamics>
            <spring_reference>0</spring_reference>
            <spring_stiffness>0</spring_stiffness>
            <damping>0</damping>
            <friction>0</friction>
          </dynamics>
        </axis2>
      </joint>
      <joint name='joint_1' type='ball'>
        <pose>0 0 0 0 0 0</pose>
        <parent>link_0</parent>
        <child>link_2</child>
        <axis>
          <xyz>0.49468496226503572 0.48049118802374413 0.72416504081622945</xyz>
          <limit>
            <lower>-inf</lower>
            <upper>inf</upper>
            <effort>inf</effort>
            <velocity>2.3417124976492887</velocity>
            <stiffness>100000000</stiffness>
            <dissipation>1</dissipation>
          </limit>
          <dynamics>
            <spring_reference>0</spring_reference>
            <spring_stiffness>0</spring_stiffness>
            <damping>0</damping>
            <friction>0</friction>
          </dynamics>
        </axis>
        <axis2>
          <xyz>0.77970190112544957 0.44689896712339106 0.4385729797484178</xyz>
          <limit>
            <lower>-inf</lower>
            <upper>inf</upper>
            <effort>inf</effort>
            <velocity>8.8060282790959228</velocity>
            <stiffness>100000000</stiffness>
            <dissipation>1</dissipation>
          </limit>
          <dynamics>
            <spring_reference>0</spring_reference>
            <spring_stiffness>0</spring_stiffness>
            <damping>0</damping>
            <friction>0</friction>
          </dynamics>
        </axis2>
      </joint>
      <plugin name='gz::sim::systems::PythonSystemLoader' filename='gz-sim-python-system-loader-system'>
        <module_name>driver</module_name>
        <force>100</force>
      </plugin>
    </model>
    <model name='model_1'>
      <static>false</static>
      <self_collide>true</self_collide>
      <allow_auto_disable>true</allow_auto_disable>
      <enable_wind>false</enable_wind>
      <pose>-9.3107050075354252 -9.284771818406135 0.029780641123310359 0 0 0</pose>
      <link name='link_3'>
        <pose>-4.5634531299655574 9.5816024637839305 9.1545967563429329 0 0 0</pose>
        <inertial>
          <pose>0 0 0 0 0 0</pose>
          <mass>1</mass>
          <inertia>
            <ixx>1</ixx>
            <ixy>0</ixy>
            <ixz>0</ixz>
            <iyy>1</iyy>
            <iyz>0</iyz>
            <izz>1</izz>
          </inertia>
        </inertial>
        <enable_wind>false</enable_wind>
        <collision name='collision_3'>
          <pose>0 0 0 0 0 0</pose>
          <geometry>
            <box>
              <size>2.8970717544730475 1.0254013076090103 2.6382851028430689</size>
            </box>
          </geometry>
          <surface>
            <contact>
              <collide_bitmask>255</collide_bitmask>
            </contact>
            <friction>
              <ode>
                <mu>1</mu>
                <mu2>1</mu2>
                <slip1>0</slip1>
                <slip2>0</slip2>
                <fdir1>0 0 0</fdir1>
              </ode>
            </friction>
          </surface>
        </collision>
        <visual name='visual_3'>
          <pose>0 0 0 0 0 0</pose>
          <geometry>
            <box>
              <size>2.8970717544730475 1.0254013076090103 2.6382851028430689</size>
            </box>
          </geometry>
          <cast_shadows>true</cast_shadows>
          <laser_retro>0</laser_retro>
          <transparency>0</transparency>
          <visibility_flags>4294967295</visibility_flags>
          <material>
            <ambient>0.0662431493 0.554073393 0.606732666 1</ambient>
            <diffuse>0.0662431493 0.554073393 0.606732666 1</diffuse>
            <specular>0 0 0 1</specular>
            <emissive>0 0 0 1</emissive>
            <render_order>0</render_order>
            <lighting>true</lighting>
            <double_sided>false</double_sided>
            <shader type='pixel'/>
          </material>
        </visual>
      </link>
      <link name='link_4'>
        <pose>-1.1965734320630972 9.4924649462711024 2.4833062582573282 0 0 0</pose>
        <inertial>
          <pose>0 0 0 0 0 0</pose>
          <mass>1</mass>
          <inertia>
            <ixx>1</ixx>
            <ixy>0</ixy>
            <ixz>0</ixz>
            <iyy>1</iyy>
            <iyz>0</iyz>
            <izz>1</izz>
          </inertia>
        </inertial>
        <enable_wind>false</enable_wind>
        <collision name='collision_4'>
          <pose>0 0 0 0 0 0</pose>
          <geometry>
            <capsule>
              <radius>1.2169402696099345</radius>
              <length>1.470173779834387</length>
            </capsule>
          </geometry>
          <surface>
            <contact>
              <collide_bitmask>255</collide_bitmask>
            </contact>
            <friction>
              <ode>
                <mu>1</mu>
                <mu2>1</mu2>
                <slip1>0</slip1>
                <slip2>0</slip2>
                <fdir1>0 0 0</fdir1>
              </ode>
            </friction>
          </surface>
        </collision>
        <visual name='visual_4'>
          <pose>0 0 0 0 0 0</pose>
          <geometry>
            <capsule>
              <radius>1.2169402696099345</radius>
              <length>1.470173779834387</length>
            </capsule>
          </geometry>
          <cast_shadows>true</cast_shadows>
          <laser_retro>0</laser_retro>
          <transparency>0</transparency>
          <visibility_flags>4294967295</visibility_flags>
          <material>
            <ambient>0.521678746 0.393017143 0.125432953 1</ambient>
            <diffuse>0.521678746 0.393017143 0.125432953 1</diffuse>
            <specular>0 0 0 1</specular>
            <emissive>0 0 0 1</emissive>
            <render_order>0</render_order>
            <lighting>true</lighting>
            <double_sided>false</double_sided>
            <shader type='pixel'/>
          </material>
        </visual>
      </link>
      <link name='link_5'>
        <pose>-8.4823081053406142 -7.7756533471167995 3.38897248203922 0 0 0</pose>
        <inertial>
          <pose>0 0 0 0 0 0</pose>
          <mass>1</mass>
          <inertia>
            <ixx>1</ixx>
            <ixy>0</ixy>
            <ixz>0</ixz>
            <iyy>1</iyy>
            <iyz>0</iyz>
            <izz>1</izz>
          </inertia>
        </inertial>
        <enable_wind>false</enable_wind>
        <collision name='collision_5'>
          <pose>0 0 0 0 0 0</pose>
          <geometry>
            <sphere>
              <radius>2.1770764977502219</radius>
            </sphere>
          </geometry>
          <surface>
            <contact>
              <collide_bitmask>255</collide_bitmask>
            </contact>
            <friction>
              <ode>
                <mu>1</mu>
                <mu2>1</mu2>
                <slip1>0</slip1>
                <slip2>0</slip2>
                <fdir1>0 0 0</fdir1>
              </ode>
            </friction>
          </surface>
        </collision>
        <visual name='visual_5'>
          <pose>0 0 0 0 0 0</pose>
          <geometry>
            <sphere>
              <radius>2.1770764977502219</radius>
            </sphere>
          </geometry>
          <cast_shadows>true</cast_shadows>
          <laser_retro>0</laser_retro>
          <transparency>0</transparency>
          <visibility_flags>4294967295</visibility_flags>
          <material>
            <ambient>0.85862571 0.763404191 0.270434558 1</ambient>
            <diffuse>0.85862571 0.763404191 0.270434558 1</diffuse>
            <specular>0 0 0 1</specular>
            <emissive>0 0 0 1</emissive>
            <render_order>0</render_order>
            <lighting>true</lighting>
            <double_sided>false</double_sided>
            <shader type='pixel'/>
          </material>
        </visual>
      </link>
      <joint name='joint_2' type='revolute'>
        <pose>0 0 0 0 0 0</pose>
        <parent>link_3</parent>
        <child>link_5</child>
        <axis>
          <xyz>0.65511730257367962 0.66657281751102726 0.35567119481903026</xyz>
          <limit>
            <lower>-inf</lower>
            <upper>inf</upper>
            <effort>inf</effort>
            <velocity>5.6441543016538196</velocity>
            <stiffness>100000000</stiffness>
            <dissipation>1</dissipation>
          </limit>
          <dynamics>
            <spring_reference>0</spring_reference>
            <spring_stiffness>0</spring_stiffness>
            <damping>0</damping>
            <friction>0</friction>
          </dynamics>
        </axis>
        <axis2>
          <xyz>0.39131157044948317 0.91856845511110419 0.055742695549806751</xyz>
          <limit>
            <lower>-inf</lower>
            <upper>inf</upper>
            <effort>inf</effort>
            <velocity>6.1432234725110071</velocity>
            <stiffness>100000000</stiffness>
            <dissipation>1</dissipation>
          </limit>
          <dynamics>
            <spring_reference>0</spring_reference>
            <spring_stiffness>0</spring_stiffness>
            <damping>0</damping>
            <friction>0</friction>
          </dynamics>
        </axis2>
      </joint>
      <joint name='joint_3' type='gearbox'>
        <pose>0 0 0 0 0 0</pose>
        <parent>link_5</parent>
        <child>link_3</child>
        <axis>
          <xyz>0.36158081687766158 0.33845621524487368 0.86873857012809008</xyz>
          <limit>
            <lower>-inf</lower>
            <upper>inf</upper>
            <effort>inf</effort>
            <velocity>5.2415810411832755</velocity>
            <stiffness>100000000</stiffness>
            <dissipation>1</dissipation>
          </limit>
          <dynamics>
            <spring_reference>0</spring_reference>
            <spring_stiffness>0</spring_stiffness>
            <damping>0</damping>
            <friction>0</friction>
          </dynamics>
        </axis>
        <axis2>
          <xyz>0.68637706955839028 0.12537949667854201 0.7163564058463302</xyz>
          <limit>
            <lower>-inf</lower>
            <upper>inf</upper>
            <effort>inf</effort>
            <velocity>2.9402020787188707</velocity>
            <stiffness>100000000</stiffness>
            <dissipation>1</dissipation>
          </limit>
          <dynamics>
            <spring_reference>0</spring_reference>
            <spring_stiffness>0</spring_stiffness>
            <damping>0</damping>
            <friction>0</friction>
          </dynamics>
        </axis2>
      </joint>
      <plugin name='gz::sim::systems::PythonSystemLoader' filename='gz-sim-python-system-loader-system'>
        <module_name>driver</module_name>
        <force>100</force>
      </plugin>
    </model>
    <model name='ground_model'>
      <static>true</static>
      <self_collide>false</self_collide>
      <allow_auto_disable>true</allow_auto_disable>
      <enable_wind>false</enable_wind>
      <pose>0 0 0 0 0 0</pose>
      <link name='ground_link'>
        <pose>0 0 0 0 0 0</pose>
        <inertial>
          <pose>0 0 0 0 0 0</pose>
          <mass>1</mass>
          <inertia>
            <ixx>1</ixx>
            <ixy>0</ixy>
            <ixz>0</ixz>
            <iyy>1</iyy>
            <iyz>0</iyz>
            <izz>1</izz>
          </inertia>
        </inertial>
        <enable_wind>false</enable_wind>
        <collision name='ground_collision'>
          <pose>0 0 0 0 0 0</pose>
          <geometry>
            <plane>
              <normal>0 0 1</normal>
              <size>100 100</size>
            </plane>
          </geometry>
          <surface>
            <contact>
              <collide_bitmask>255</collide_bitmask>
            </contact>
            <friction>
              <ode>
                <mu>1</mu>
                <mu2>1</mu2>
                <slip1>0</slip1>
                <slip2>0</slip2>
                <fdir1>0 0 0</fdir1>
              </ode>
            </friction>
          </surface>
        </collision>
      </link>
    </model>
    <model name='ceiling_model'>
      <static>true</static>
      <self_collide>false</self_collide>
      <allow_auto_disable>true</allow_auto_disable>
      <enable_wind>false</enable_wind>
      <pose>0 0 100 0 0 0</pose>
      <link name='ceiling_link'>
        <pose>0 0 0 0 0 0</pose>
        <inertial>
          <pose>0 0 0 0 0 0</pose>
          <mass>1</mass>
          <inertia>
            <ixx>1</ixx>
            <ixy>0</ixy>
            <ixz>0</ixz>
            <iyy>1</iyy>
            <iyz>0</iyz>
            <izz>1</izz>
          </inertia>
        </inertial>
        <enable_wind>false</enable_wind>
        <collision name='ceiling_collision'>
          <pose>0 0 0 0 0 0</pose>
          <geometry>
            <box>
              <size>102 102 3</size>
            </box>
          </geometry>
          <surface>
            <contact>
              <collide_bitmask>255</collide_bitmask>
            </contact>
            <friction>
              <ode>
                <mu>1</mu>
                <mu2>1</mu2>
                <slip1>0</slip1>
                <slip2>0</slip2>
                <fdir1>0 0 0</fdir1>
              </ode>
            </friction>
          </surface>
        </collision>
        <visual name='ceiling_visual'>
          <pose>0 0 0 0 0 0</pose>
          <geometry>
            <box>
              <size>102 102 3</size>
            </box>
          </geometry>
          <cast_shadows>true</cast_shadows>
          <laser_retro>0</laser_retro>
          <transparency>0</transparency>
          <visibility_flags>4294967295</visibility_flags>
          <material>
            <ambient>0.200000003 0.200000003 0.200000003 0.200000003</ambient>
            <diffuse>0.200000003 0.200000003 0.200000003 0.200000003</diffuse>
            <specular>0 0 0 1</specular>
            <emissive>0 0 0 1</emissive>
            <render_order>0</render_order>
            <lighting>true</lighting>
            <double_sided>false</double_sided>
            <shader type='pixel'/>
          </material>
        </visual>
      </link>
    </model>
    <model name='west_model'>
      <static>true</static>
      <self_collide>false</self_collide>
      <allow_auto_disable>true</allow_auto_disable>
      <enable_wind>false</enable_wind>
      <pose>0 50 50 0 0 0</pose>
      <link name='west_link'>
        <pose>0 0 0 0 0 0</pose>
        <inertial>
          <pose>0 0 0 0 0 0</pose>
          <mass>1</mass>
          <inertia>
            <ixx>1</ixx>
            <ixy>0</ixy>
            <ixz>0</ixz>
            <iyy>1</iyy>
            <iyz>0</iyz>
            <izz>1</izz>
          </inertia>
        </inertial>
        <enable_wind>false</enable_wind>
        <collision name='west_collision'>
          <pose>0 0 0 0 0 0</pose>
          <geometry>
            <box>
              <size>102 3 102</size>
            </box>
          </geometry>
          <surface>
            <contact>
              <collide_bitmask>255</collide_bitmask>
            </contact>
            <friction>
              <ode>
                <mu>1</mu>
                <mu2>1</mu2>
                <slip1>0</slip1>
                <slip2>0</slip2>
                <fdir1>0 0 0</fdir1>
              </ode>
            </friction>
          </surface>
        </collision>
        <visual name='west_visual'>
          <pose>0 0 0 0 0 0</pose>
          <geometry>
            <box>
              <size>102 3 102</size>
            </box>
          </geometry>
          <cast_shadows>true</cast_shadows>
          <laser_retro>0</laser_retro>
          <transparency>0</transparency>
          <visibility_flags>4294967295</visibility_flags>
          <material>
            <ambient>0.200000003 0.200000003 0.200000003 0.200000003</ambient>
            <diffuse>0.200000003 0.200000003 0.200000003 0.200000003</diffuse>
            <specular>0 0 0 1</specular>
            <emissive>0 0 0 1</emissive>
            <render_order>0</render_order>
            <lighting>true</lighting>
            <double_sided>false</double_sided>
            <shader type='pixel'/>
          </material>
        </visual>
      </link>
    </model>
    <model name='east_model'>
      <static>true</static>
      <self_collide>false</self_collide>
      <allow_auto_disable>true</allow_auto_disable>
      <enable_wind>false</enable_wind>
      <pose>0 -50 50 0 0 0</pose>
      <link name='east_link'>
        <pose>0 0 0 0 0 0</pose>
        <inertial>
          <pose>0 0 0 0 0 0</pose>
          <mass>1</mass>
          <inertia>
            <ixx>1</ixx>
            <ixy>0</ixy>
            <ixz>0</ixz>
            <iyy>1</iyy>
            <iyz>0</iyz>
            <izz>1</izz>
          </inertia>
        </inertial>
        <enable_wind>false</enable_wind>
        <collision name='east_collision'>
          <pose>0 0 0 0 0 0</pose>
          <geometry>
            <box>
              <size>102 3 102</size>
            </box>
          </geometry>
          <surface>
            <contact>
              <collide_bitmask>255</collide_bitmask>
            </contact>
            <friction>
              <ode>
                <mu>1</mu>
                <mu2>1</mu2>
                <slip1>0</slip1>
                <slip2>0</slip2>
                <fdir1>0 0 0</fdir1>
              </ode>
            </friction>
          </surface>
        </collision>
        <visual name='east_visual'>
          <pose>0 0 0 0 0 0</pose>
          <geometry>
            <box>
              <size>102 3 102</size>
            </box>
          </geometry>
          <cast_shadows>true</cast_shadows>
          <laser_retro>0</laser_retro>
          <transparency>0</transparency>
          <visibility_flags>4294967295</visibility_flags>
          <material>
            <ambient>0.200000003 0.200000003 0.200000003 0.200000003</ambient>
            <diffuse>0.200000003 0.200000003 0.200000003 0.200000003</diffuse>
            <specular>0 0 0 1</specular>
            <emissive>0 0 0 1</emissive>
            <render_order>0</render_order>
            <lighting>true</lighting>
            <double_sided>false</double_sided>
            <shader type='pixel'/>
          </material>
        </visual>
      </link>
    </model>
    <model name='north_model'>
      <static>true</static>
      <self_collide>false</self_collide>
      <allow_auto_disable>true</allow_auto_disable>
      <enable_wind>false</enable_wind>
      <pose>50 0 50 0 0 0</pose>
      <link name='north_link'>
        <pose>0 0 0 0 0 0</pose>
        <inertial>
          <pose>0 0 0 0 0 0</pose>
          <mass>1</mass>
          <inertia>
            <ixx>1</ixx>
            <ixy>0</ixy>
            <ixz>0</ixz>
            <iyy>1</iyy>
            <iyz>0</iyz>
            <izz>1</izz>
          </inertia>
        </inertial>
        <enable_wind>false</enable_wind>
        <collision name='north_collision'>
          <pose>0 0 0 0 0 0</pose>
          <geometry>
            <box>
              <size>3 102 102</size>
            </box>
          </geometry>
          <surface>
            <contact>
              <collide_bitmask>255</collide_bitmask>
            </contact>
            <friction>
              <ode>
                <mu>1</mu>
                <mu2>1</mu2>
                <slip1>0</slip1>
                <slip2>0</slip2>
                <fdir1>0 0 0</fdir1>
              </ode>
            </friction>
          </surface>
        </collision>
        <visual name='north_visual'>
          <pose>0 0 0 0 0 0</pose>
          <geometry>
            <box>
              <size>3 102 102</size>
            </box>
          </geometry>
          <cast_shadows>true</cast_shadows>
          <laser_retro>0</laser_retro>
          <transparency>0</transparency>
          <visibility_flags>4294967295</visibility_flags>
          <material>
            <ambient>0.200000003 0.200000003 0.200000003 0.200000003</ambient>
            <diffuse>0.200000003 0.200000003 0.200000003 0.200000003</diffuse>
            <specular>0 0 0 1</specular>
            <emissive>0 0 0 1</emissive>
            <render_order>0</render_order>
            <lighting>true</lighting>
            <double_sided>false</double_sided>
            <shader type='pixel'/>
          </material>
        </visual>
      </link>
    </model>
    <model name='south_model'>
      <static>true</static>
      <self_collide>false</self_collide>
      <allow_auto_disable>true</allow_auto_disable>
      <enable_wind>false</enable_wind>
      <pose>-50 0 50 0 0 0</pose>
      <link name='south_link'>
        <pose>0 0 0 0 0 0</pose>
        <inertial>
          <pose>0 0 0 0 0 0</pose>
          <mass>1</mass>
          <inertia>
            <ixx>1</ixx>
            <ixy>0</ixy>
            <ixz>0</ixz>
            <iyy>1</iyy>
            <iyz>0</iyz>
            <izz>1</izz>
          </inertia>
        </inertial>
        <enable_wind>false</enable_wind>
        <collision name='south_collision'>
          <pose>0 0 0 0 0 0</pose>
          <geometry>
            <box>
              <size>3 102 102</size>
            </box>
          </geometry>
          <surface>
            <contact>
              <collide_bitmask>255</collide_bitmask>
            </contact>
            <friction>
              <ode>
                <mu>1</mu>
                <mu2>1</mu2>
                <slip1>0</slip1>
                <slip2>0</slip2>
                <fdir1>0 0 0</fdir1>
              </ode>
            </friction>
          </surface>
        </collision>
        <visual name='south_visual'>
          <pose>0 0 0 0 0 0</pose>
          <geometry>
            <box>
              <size>3 102 102</size>
            </box>
          </geometry>
          <cast_shadows>true</cast_shadows>
          <laser_retro>0</laser_retro>
          <transparency>0</transparency>
          <visibility_flags>4294967295</visibility_flags>
          <material>
            <ambient>0.200000003 0.200000003 0.200000003 0.200000003</ambient>
            <diffuse>0.200000003 0.200000003 0.200000003 0.200000003</diffuse>
            <specular>0 0 0 1</specular>
            <emissive>0 0 0 1</emissive>
            <render_order>0</render_order>
            <lighting>true</lighting>
            <double_sided>false</double_sided>
            <shader type='pixel'/>
          </material>
        </visual>
      </link>
    </model>
    <atmosphere type='adiabatic'>
      <temperature>288.14999999999998</temperature>
      <pressure>101325</pressure>
      <temperature_gradient>-0.0064999999999999997</temperature_gradient>
    </atmosphere>
    <scene>
      <ambient>0.400000006 0.400000006 0.400000006 1</ambient>
      <background>0.699999988 0.699999988 0.699999988 1</background>
      <grid>true</grid>
      <origin_visual>true</origin_visual>
      <shadows>true</shadows>
    </scene>
  </world>
</sdf>
