Warning: Ignoring XDG_SESSION_TYPE=wayland on Gnome. Use QT_QPA_PLATFORM=wayland to run on Wayland anyway.
[1;31m[Err] [EntityComponentManager.cc:1083] [0m[1;31mTrying to create a component of type [[0m[1;31m9804972768940264239[0m[1;31m] attached to entity [[0m[1;31m2481290408[0m[1;31m], but this entity does not [0m[1;31mexist. This create component request will be ignored.[0m[1;31m[0m
[1;31m[Err] [UserCommands.cc:1145] [0m[1;31mError Code [0m[1;31m30[0m[1;31m: [0m[1;31mMsg: [0m[1;31mError parsing XML from string: Error=XML_ERROR_PARSING_TEXT ErrorID=8 (0x8) Line number=1[0m[1;31m[0m
[1;31m[Err] [UserCommands.cc:1145] [0m[1;31mError Code [0m[1;31m30[0m[1;31m: [0m[1;31mMsg: [0m[1;31mUnable to read SDF string: b"<sdf version="1.11">\n  <model name="model">\n    <static>true</static>\n    <self_collide>false</self_collide>\n    <allow_auto_disable>true</allow_auto_disable>\n    <enable_wind>false</enable_wind>\n    <pose>-0.5609220750089623 -3.5547783983175263 4.1517983685401472 0 0 0</pose>\n    <link name="link_4470">\n      <pose>4.2592232828144017 -9.4705194366478942 0.42256708536511645 0 0 0</pose>\n      <inertial>\n        <pose>0 0 0 0 0 0</pose>\n        <mass>1</mass>\n        <inertia>\n          <ixx>1</ixx>\n          <ixy>0</ixy>\n          <ixz>0</ixz>\n          <iyy>1</iyy>\n          <iyz>0</iyz>\n          <izz>1</izz>\n        </inertia>\n      </inertial>\n      <enable_wind>false</enable_wind>\n      <collision name="collision_4470">\n        <pose>0 0 0 0 0 0</pose>\n        <geometry>\n          <box>\n            <size>1.6872399864853271 1.9390790119153225 1.7318027058100314</size>\n          </box>\n        </geometry>\n        <surface>\n          <contact>\n            <collide_bitmask>255</collide_bitmask>\n          </contact>\n          <friction>\n            <ode>\n              <mu>1</mu>\n              <mu2>1</mu2>\n              <slip1>0</slip1>\n              <slip2>0</slip2>\n              <fdir1>0 0 0</fdir1>\n            </ode>\n          </friction>\n        </surface>\n      </collision>\n      <visual name="visual_4470">\n        <pose>0 0 0 0 0 0</pose>\n        <geometry>\n          <box>\n            <size>1.6872399864853271 1.9390790119153225 1.7318027058100314</size>\n          </box>\n        </geometry>\n        <cast_shadows>true</cast_shadows>\n        <laser_retro>0</laser_retro>\n        <transparency>0</transparency>\n        <visibility_flags>4294967295</visibility_flags>\n        <material>\n          <ambient>0.874411643 0.653332353 0.124142013 1</ambient>\n          <diffuse>0.874411643 0.653332353 0.124142013 1</diffuse>\n          <specular>0 0 0 1</specular>\n          <emissive>0 0 0 1</emissive>\n          <render_order>0</render_order>\n          <lighting>true</lighting>\n          <double_sided>false</double_sided>\n          <shader type="pixel"/>\n        </material>\n      </visual>\n    </link>\n    <link name="link_4471">\n      <pose>5.5686727163930172 -0.19005140897213124 0.36109531231368064 0 0 0</pose>\n      <inertial>\n        <pose>0 0 0 0 0 0</pose>\n        <mass>1</mass>\n        <inertia>\n          <ixx>1</ixx>\n          <ixy>0</ixy>\n          <ixz>0</ixz>\n          <iyy>1</iyy>\n          <iyz>0</iyz>\n          <izz>1</izz>\n        </inertia>\n      </inertial>\n      <enable_wind>false</enable_wind>\n      <collision name="collision_4471">\n        <pose>0 0 0 0 0 0</pose>\n        <geometry>\n          <box>\n            <size>1.0599677345639706 1.5025107519783063 2.3958778417992228</size>\n          </box>\n        </geometry>\n        <surface>\n          <contact>\n            <collide_bitmask>255</collide_bitmask>\n          </contact>\n          <friction>\n            <ode>\n              <mu>1</mu>\n              <mu2>1</mu2>\n              <slip1>0</slip1>\n              <slip2>0</slip2>\n              <fdir1>0 0 0</fdir1>\n            </ode>\n          </friction>\n        </surface>\n      </collision>\n      <visual name="visual_4471">\n        <pose>0 0 0 0 0 0</pose>\n        <geometry>\n          <box>\n            <size>1.0599677345639706 1.5025107519783063 2.3958778417992228</size>\n          </box>\n        </geometry>\n        <cast_shadows>true</cast_shadows>\n        <laser_retro>0</laser_retro>\n        <transparency>0</transparency>\n        <visibility_flags>4294967295</visibility_flags>\n        <material>\n          <ambient>0.290144503 0.136790678 0.374361545 1</ambient>\n          <diffuse>0.290144503 0.136790678 0.374361545 1</diffuse>\n          <specular>0 0 0 1</specular>\n          <emissive>0 0 0 1</emissive>\n          <render_order>0</render_order>\n          <lighting>true</lighting>\n          <double_sided>false</double_sided>\n          <shader type="pixel"/>\n        </material>\n      </visual>\n    </link>\n    <link name="link_4472">\n      <pose>9.6101961553833881 9.346000391749854 1.0904284626025618 0 0 0</pose>\n      <inertial>\n        <pose>0 0 0 0 0 0</pose>\n        <mass>1</mass>\n        <inertia>\n          <ixx>1</ixx>\n          <ixy>0</ixy>\n          <ixz>0</ixz>\n          <iyy>1</iyy>\n          <iyz>0</iyz>\n          <izz>1</izz>\n        </inertia>\n      </inertial>\n      <enable_wind>false</enable_wind>\n      <collision name="collision_4472">\n        <pose>0 0 0 0 0 0</pose>\n        <geometry>\n          <cylinder>\n            <radius>2.6761457427695898</radius>\n            <length>2.5983406892577703</length>\n          </cylinder>\n        </geometry>\n        <surface>\n          <contact>\n            <collide_bitmask>255</collide_bitmask>\n          </contact>\n          <friction>\n            <ode>\n              <mu>1</mu>\n              <mu2>1</mu2>\n              <slip1>0</slip1>\n              <slip2>0</slip2>\n              <fdir1>0 0 0</fdir1>\n            </ode>\n          </friction>\n        </surface>\n      </collision>\n      <visual name="visual_4472">\n        <pose>0 0 0 0 0 0</pose>\n        <geometry>\n          <cylinder>\n            <radius>2.6761457427695898</radius>\n            <length>2.5983406892577703</length>\n          </cylinder>\n        </geometry>\n        <cast_shadows>true</cast_shadows>\n        <laser_retro>0</laser_retro>\n        <transparency>0</transparency>\n        <visibility_flags>4294967295</visibility_flags>\n        <material>\n          <ambient>0.987398982 0.66373992 0.111828744 1</ambient>\n          <diffuse>0.987398982 0.66373992 0.111828744 1</diffuse>\n          <specular>0 0 0 1</specular>\n          <emissive>0 0 0 1</emissive>\n          <render_order>0</render_order>\n          <lighting>true</lighting>\n          <double_sided>false</double_sided>\n          <shader type="pixel"/>\n        </material>\n      </visual>\n    </link>\n    <joint name="joint_2980" type="ball">\n      <pose>0 0 0 0 0 0</pose>\n      <parent>link_4472</parent>\n      <child>link_4471</child>\n      <axis>\n        <xyz>0.68202077700716901 0.12948826400615396 0.71977805552490282</xyz>\n        <limit>\n          <lower>-inf</lower>\n          <upper>inf</upper>\n          <effort>inf</effort>\n          <velocity>4.7631077192502289</velocity>\n          <stiffness>100000000</stiffness>\n          <dissipation>1</dissipation>\n        </limit>\n        <dynamics>\n          <spring_reference>0</spring_reference>\n          <spring_stiffness>0</spring_stiffness>\n          <damping>0</damping>\n          <friction>0</friction>\n        </dynamics>\n      </axis>\n      <axis2>\n        <xyz>0.18723212914023174 0.46449498673909712 0.86555677867593495</xyz>\n        <limit>\n          <lower>-inf</lower>\n          <upper>inf</upper>\n          <effort>inf</effort>\n          <velocity>7.6967082197641021</velocity>\n          <stiffness>100000000</stiffness>\n          <dissipation>1</dissipation>\n        </limit>\n        <dynamics>\n          <spring_reference>0</spring_reference>\n          <spring_stiffness>0</spring_stiffness>\n          <damping>0</damping>\n          <friction>0</friction>\n        </dynamics>\n      </axis2>\n    </joint>\n    <joint name="joint_2981" type="screw">\n      <pose>0 0 0 0 0 0</pose>\n      <parent>link_4472</parent>\n      <child>link_4470</child>\n      <axis>\n        <xyz>0.69520712324584966 0.12410823355945728 0.70801426691203151</xyz>\n        <limit>\n          <lower>-inf</lower>\n          <upper>inf</upper>\n          <effort>inf</effort>\n          <velocity>1.8451124926678864</velocity>\n          <stiffness>100000000</stiffness>\n          <dissipation>1</dissipation>\n        </limit>\n        <dynamics>\n          <spring_reference>-1290</spring_reference>\n          <spring_stiffness>0</spring_stiffness>\n          <damping>0</damping>\n          <friction>0</friction>\n        </dynamics>\n      </axis>\n      <axis2>\n        <xyz>0.69429721902115882 0.48022187030456975 0.53603948263226475</xyz>\n        <limit>\n          <lower>-inf</lower>\n          <upper>inf</upper>\n          <effort>inf</effort>\n          <velocity>3.7171108067258962</velocity>\n          <stiffness>100000000</stiffness>\n          <dissipation>1</dissipation>\n        </limit>\n        <dynamics>\n          <spring_reference>0</spring_reference>\n          <spring_stiffness>0</spring_stiffness>\n          <damping>0</damping>\n          <friction>0</friction>\n        </dynamics>\n      </axis2>\n      <thread_pitch>-6.2831853071795862</thread_pitch>\n    </joint>\n  </model>\n</sdf>\n"[0m[1;31m[0m
[1;31m[Err] [UserCommands.cc:1145] [0m[1;31mError Code [0m[1;31m30[0m[1;31m: [0m[1;31mMsg: [0m[1;31mError parsing XML from string: Error=XML_ERROR_PARSING_TEXT ErrorID=8 (0x8) Line number=1[0m[1;31m[0m
[1;31m[Err] [UserCommands.cc:1145] [0m[1;31mError Code [0m[1;31m30[0m[1;31m: [0m[1;31mMsg: [0m[1;31mUnable to read SDF string: b"<sdf version="1.11">\n  <model name="model">\n    <static>true</static>\n    <self_collide>true</self_collide>\n    <allow_auto_disable>true</allow_auto_disable>\n    <enable_wind>false</enable_wind>\n    <pose>8.5909817892650722 -5.3610369231330868 2.1353848542282581 0 0 0</pose>\n    <link name="link_4473">\n      <pose>-8.0135241947746216 -2.5350868261356378 3.5591667628230339 0 0 0</pose>\n      <inertial>\n        <pose>0 0 0 0 0 0</pose>\n        <mass>1</mass>\n        <inertia>\n          <ixx>1</ixx>\n          <ixy>0</ixy>\n          <ixz>0</ixz>\n          <iyy>1</iyy>\n          <iyz>0</iyz>\n          <izz>1</izz>\n        </inertia>\n      </inertial>\n      <enable_wind>false</enable_wind>\n      <collision name="collision_4473">\n        <pose>0 0 0 0 0 0</pose>\n        <geometry>\n          <sphere>\n            <radius>1.3081449201593791</radius>\n          </sphere>\n        </geometry>\n        <surface>\n          <contact>\n            <collide_bitmask>255</collide_bitmask>\n          </contact>\n          <friction>\n            <ode>\n              <mu>1</mu>\n              <mu2>1</mu2>\n              <slip1>0</slip1>\n              <slip2>0</slip2>\n              <fdir1>0 0 0</fdir1>\n            </ode>\n          </friction>\n        </surface>\n      </collision>\n      <visual name="visual_4473">\n        <pose>0 0 0 0 0 0</pose>\n        <geometry>\n          <sphere>\n            <radius>1.3081449201593791</radius>\n          </sphere>\n        </geometry>\n        <cast_shadows>true</cast_shadows>\n        <laser_retro>0</laser_retro>\n        <transparency>0</transparency>\n        <visibility_flags>4294967295</visibility_flags>\n        <material>\n          <ambient>0.574124098 0.23477459 0.524191141 1</ambient>\n          <diffuse>0.574124098 0.23477459 0.524191141 1</diffuse>\n          <specular>0 0 0 1</specular>\n          <emissive>0 0 0 1</emissive>\n          <render_order>0</render_order>\n          <lighting>true</lighting>\n          <double_sided>false</double_sided>\n          <shader type="pixel"/>\n        </material>\n      </visual>\n    </link>\n    <link name="link_4474">\n      <pose>5.9272112867130478 -0.77559798227501808 6.809040684630741 0 0 0</pose>\n      <inertial>\n        <pose>0 0 0 0 0 0</pose>\n        <mass>1</mass>\n        <inertia>\n          <ixx>1</ixx>\n          <ixy>0</ixy>\n          <ixz>0</ixz>\n          <iyy>1</iyy>\n          <iyz>0</iyz>\n          <izz>1</izz>\n        </inertia>\n      </inertial>\n      <enable_wind>false</enable_wind>\n      <collision name="collision_4474">\n        <pose>0 0 0 0 0 0</pose>\n        <geometry>\n          <capsule>\n            <radius>1.8455626209205334</radius>\n            <length>2.9926052813769859</length>\n          </capsule>\n        </geometry>\n        <surface>\n          <contact>\n            <collide_bitmask>255</collide_bitmask>\n          </contact>\n          <friction>\n            <ode>\n              <mu>1</mu>\n              <mu2>1</mu2>\n              <slip1>0</slip1>\n              <slip2>0</slip2>\n              <fdir1>0 0 0</fdir1>\n            </ode>\n          </friction>\n        </surface>\n      </collision>\n      <visual name="visual_4474">\n        <pose>0 0 0 0 0 0</pose>\n        <geometry>\n          <capsule>\n            <radius>1.8455626209205334</radius>\n            <length>2.9926052813769859</length>\n          </capsule>\n        </geometry>\n        <cast_shadows>true</cast_shadows>\n        <laser_retro>0</laser_retro>\n        <transparency>0</transparency>\n        <visibility_flags>4294967295</visibility_flags>\n        <material>\n          <ambient>0.298246741 0.948457062 0.66942811 1</ambient>\n          <diffuse>0.298246741 0.948457062 0.66942811 1</diffuse>\n          <specular>0 0 0 1</specular>\n          <emissive>0 0 0 1</emissive>\n          <render_order>0</render_order>\n          <lighting>true</lighting>\n          <double_sided>false</double_sided>\n          <shader type="pixel"/>\n        </material>\n      </visual>\n    </link>\n    <link name="link_4475">\n      <pose>-0.42448949155859239 1.2772921024512147 7.430406824026071 0 0 0</pose>\n      <inertial>\n        <pose>0 0 0 0 0 0</pose>\n        <mass>1</mass>\n        <inertia>\n          <ixx>1</ixx>\n          <ixy>0</ixy>\n          <ixz>0</ixz>\n          <iyy>1</iyy>\n          <iyz>0</iyz>\n          <izz>1</izz>\n        </inertia>\n      </inertial>\n      <enable_wind>false</enable_wind>\n      <collision name="collision_4475">\n        <pose>0 0 0 0 0 0</pose>\n        <geometry>\n          <capsule>\n            <radius>1.3656097943411598</radius>\n            <length>1.415227171492103</length>\n          </capsule>\n        </geometry>\n        <surface>\n          <contact>\n            <collide_bitmask>255</collide_bitmask>\n          </contact>\n          <friction>\n            <ode>\n              <mu>1</mu>\n              <mu2>1</mu2>\n              <slip1>0</slip1>\n              <slip2>0</slip2>\n              <fdir1>0 0 0</fdir1>\n            </ode>\n          </friction>\n        </surface>\n      </collision>\n      <visual name="visual_4475">\n        <pose>0 0 0 0 0 0</pose>\n        <geometry>\n          <capsule>\n            <radius>1.3656097943411598</radius>\n            <length>1.415227171492103</length>\n          </capsule>\n        </geometry>\n        <cast_shadows>true</cast_shadows>\n        <laser_retro>0</laser_retro>\n        <transparency>0</transparency>\n        <visibility_flags>4294967295</visibility_flags>\n        <material>\n          <ambient>0.933782279 0.466368794 0.11444968 1</ambient>\n          <diffuse>0.933782279 0.466368794 0.11444968 1</diffuse>\n          <specular>0 0 0 1</specular>\n          <emissive>0 0 0 1</emissive>\n          <render_order>0</render_order>\n          <lighting>true</lighting>\n          <double_sided>false</double_sided>\n          <shader type="pixel"/>\n        </material>\n      </visual>\n    </link>\n    <joint name="joint_2982" type="gearbox">\n      <pose>0 0 0 0 0 0</pose>\n      <parent>link_4474</parent>\n      <child>link_4475</child>\n      <axis>\n        <xyz>0.65767990937605136 0.69599203999658898 0.2881878156072798</xyz>\n        <limit>\n          <lower>-inf</lower>\n          <upper>inf</upper>\n          <effort>inf</effort>\n          <velocity>5.9868012015149095</velocity>\n          <stiffness>100000000</stiffness>\n          <dissipation>1</dissipation>\n        </limit>\n        <dynamics>\n          <spring_reference>0</spring_reference>\n          <spring_stiffness>0</spring_stiffness>\n          <damping>0</damping>\n          <friction>0</friction>\n        </dynamics>\n      </axis>\n      <axis2>\n        <xyz>0.012669397244267029 0.43911542976908219 0.89834131916114224</xyz>\n        <limit>\n          <lower>-inf</lower>\n          <upper>inf</upper>\n          <effort>inf</effort>\n          <velocity>6.7097203485361163</velocity>\n          <stiffness>100000000</stiffness>\n          <dissipation>1</dissipation>\n        </limit>\n        <dynamics>\n          <spring_reference>0</spring_reference>\n          <spring_stiffness>0</spring_stiffness>\n          <damping>0</damping>\n          <friction>0</friction>\n        </dynamics>\n      </axis2>\n    </joint>\n    <joint name="joint_2983" type="continuous">\n      <pose>0 0 0 0 0 0</pose>\n      <parent>link_4474</parent>\n      <child>link_4475</child>\n      <axis>\n        <xyz>0.27268237040591048 0.87500553074141063 0.40001205737046974</xyz>\n        <limit>\n          <lower>-inf</lower>\n          <upper>inf</upper>\n          <effort>inf</effort>\n          <velocity>3.8338017014986949</velocity>\n          <stiffness>100000000</stiffness>\n          <dissipation>1</dissipation>\n        </limit>\n        <dynamics>\n          <spring_reference>0</spring_reference>\n          <spring_stiffness>0</spring_stiffness>\n          <damping>0</damping>\n          <friction>0</friction>\n        </dynamics>\n      </axis>\n      <axis2>\n        <xyz>0.2180688435043214 0.47464831487410841 0.85273381349624977</xyz>\n        <limit>\n          <lower>-inf</lower>\n          <upper>inf</upper>\n          <effort>inf</effort>\n          <velocity>2.9817940692189318</velocity>\n          <stiffness>100000000</stiffness>\n          <dissipation>1</dissipation>\n        </limit>\n        <dynamics>\n          <spring_reference>0</spring_reference>\n          <spring_stiffness>0</spring_stiffness>\n          <damping>0</damping>\n          <friction>0</friction>\n        </dynamics>\n      </axis2>\n    </joint>\n  </model>\n</sdf>\n"[0m[1;31m[0m
[1;33mWarning [Utils.cc:132][0m [/sdf/model[@name="submarine"]/joint[@name="propeller_joint"]/axis/use_parent_model_frame:<data-string>:L136]: XML Element[use_parent_model_frame], child of element[axis], not defined in SDF. Copying[use_parent_model_frame] as children of [axis].
gz sim server: ./dart/dynamics/CylinderShape.cpp:47: dart::dynamics::CylinderShape::CylinderShape(double, double): Assertion `0.0 < _height' failed.
Stack trace (most recent call last):
#31   Object "/lib/x86_64-linux-gnu/libruby-3.0.so.3.0", at 0x727b9b0a69ac, in rb_protect
#30   Object "/lib/x86_64-linux-gnu/libruby-3.0.so.3.0", at 0x727b9b23ec61, in rb_yield
#29   Object "/lib/x86_64-linux-gnu/libruby-3.0.so.3.0", at 0x727b9b23a30c, in rb_vm_exec
#28   Object "/lib/x86_64-linux-gnu/libruby-3.0.so.3.0", at 0x727b9b234c96, in 
#27   Object "/lib/x86_64-linux-gnu/libruby-3.0.so.3.0", at 0x727b9b231fc5, in 
#26   Object "/lib/x86_64-linux-gnu/libruby-3.0.so.3.0", at 0x727b9b22fc34, in 
#25   Object "/usr/lib/x86_64-linux-gnu/ruby/3.0.0/fiddle.so", at 0x727b9b38c44b, in 
#24   Object "/lib/x86_64-linux-gnu/libruby-3.0.so.3.0", at 0x727b9b1fd088, in rb_nogvl
#23   Object "/usr/lib/x86_64-linux-gnu/ruby/3.0.0/fiddle.so", at 0x727b9b38bd6b, in 
#22   Object "/lib/x86_64-linux-gnu/libffi.so.8", at 0x727b9b37d492, in 
#21   Object "/lib/x86_64-linux-gnu/libffi.so.8", at 0x727b9b380e2d, in 
#20   Object "/usr/lib/x86_64-linux-gnu/libgz-sim8-gz.so.8.6.0", at 0x727b9ae83605, in runServer
#19   Object "/lib/x86_64-linux-gnu/libgz-sim8.so.8", at 0x727b9553d485, in 
#18   Object "/lib/x86_64-linux-gnu/libgz-sim8.so.8", at 0x727b9554d8a2, in gz::sim::v8::SimulationRunner::Run(unsigned long)
#17   Object "/lib/x86_64-linux-gnu/libgz-sim8.so.8", at 0x727b9554ce60, in gz::sim::v8::SimulationRunner::Step(gz::sim::v8::UpdateInfo const&)
#16   Object "/lib/x86_64-linux-gnu/libgz-sim8.so.8", at 0x727b9554c0a2, in gz::sim::v8::SimulationRunner::UpdateSystems()
#15   Object "/usr/lib/x86_64-linux-gnu/gz-sim-8/plugins/libgz-sim-physics-system.so", at 0x727b8c11f585, in gz::sim::v8::systems::Physics::Update(gz::sim::v8::UpdateInfo const&, gz::sim::v8::EntityComponentManager&)
#14   Object "/usr/lib/x86_64-linux-gnu/gz-sim-8/plugins/libgz-sim-physics-system.so", at 0x727b8c11f4b2, in gz::sim::v8::systems::PhysicsPrivate::CreatePhysicsEntities(gz::sim::v8::EntityComponentManager const&, bool)
#13   Object "/usr/lib/x86_64-linux-gnu/gz-sim-8/plugins/libgz-sim-physics-system.so", at 0x727b8c119544, in gz::sim::v8::systems::PhysicsPrivate::CreateModelEntities(gz::sim::v8::EntityComponentManager const&, bool)
#12   Object "/usr/lib/x86_64-linux-gnu/gz-sim-8/plugins/libgz-sim-physics-system.so", at 0x727b8c198f06, in 
#11   Object "/usr/lib/x86_64-linux-gnu/gz-physics-7/engine-plugins/libgz-physics-dartsim-plugin.so", at 0x727b555f1fb3, in virtual thunk to gz::physics::dartsim::SDFFeatures::ConstructSdfModel(gz::physics::Identity const&, sdf::v14::Model const&)
#10   Object "/usr/lib/x86_64-linux-gnu/gz-physics-7/engine-plugins/libgz-physics-dartsim-plugin.so", at 0x727b555f13fa, in gz::physics::dartsim::SDFFeatures::ConstructSdfModelImpl(unsigned long, sdf::v14::Model const&)
#9    Object "/usr/lib/x86_64-linux-gnu/gz-physics-7/engine-plugins/libgz-physics-dartsim-plugin.so", at 0x727b555ed384, in gz::physics::dartsim::SDFFeatures::FindOrConstructLink(std::shared_ptr<dart::dynamics::Skeleton> const&, gz::physics::Identity const&, sdf::v14::Model const&, std::__cxx11::basic_string<char, std::char_traits<char>, std::allocator<char> > const&)
#8    Object "/usr/lib/x86_64-linux-gnu/gz-physics-7/engine-plugins/libgz-physics-dartsim-plugin.so", at 0x727b555ecdc4, in gz::physics::dartsim::SDFFeatures::ConstructSdfLink(gz::physics::Identity const&, sdf::v14::Link const&)
#7    Object "/usr/lib/x86_64-linux-gnu/gz-physics-7/engine-plugins/libgz-physics-dartsim-plugin.so", at 0x727b555f3a6e, in gz::physics::dartsim::SDFFeatures::ConstructSdfCollision(gz::physics::Identity const&, sdf::v14::Collision const&)
#6    Object "/usr/lib/x86_64-linux-gnu/gz-physics-7/engine-plugins/libgz-physics-dartsim-plugin.so", at 0x727b555f2f2d, in 
#5    Object "/lib/x86_64-linux-gnu/libdart.so.6.13", at 0x727b5500e1b4, in dart::dynamics::CylinderShape::CylinderShape(double, double)
#4    Object "/lib/x86_64-linux-gnu/libc.so.6", at 0x727b9ac39e95, in __assert_fail
#3    Object "/lib/x86_64-linux-gnu/libc.so.6", at 0x727b9ac2871a, in 
#2    Object "/lib/x86_64-linux-gnu/libc.so.6", at 0x727b9ac287f2, in abort
#1    Object "/lib/x86_64-linux-gnu/libc.so.6", at 0x727b9ac42475, in raise
#0    Object "/lib/x86_64-linux-gnu/libc.so.6", at 0x727b9ac969fc, in pthread_kill
Aborted (Signal sent by tkill() 477395 1000)
