<sdf version='1.11'>
  <world name='world_0'>
    <gravity>0 0 -9.8066499999999994</gravity>
    <magnetic_field>5.5644999999999998e-06 2.2875799999999999e-05 -4.2388400000000002e-05</magnetic_field>
    <wind>
      <linear_velocity>2 9 4</linear_velocity>
    </wind>
    <physics default='false' type='ode'>
      <max_step_size>0.001</max_step_size>
      <real_time_factor>1</real_time_factor>
      <max_contacts>20</max_contacts>
    </physics>
    <model name='model_0'>
      <static>false</static>
      <self_collide>true</self_collide>
      <allow_auto_disable>true</allow_auto_disable>
      <enable_wind>true</enable_wind>
      <pose>2.9928030573800868 4.4880694525290483 0.78323624501787648 0 0 0</pose>
      <link name='link_0'>
        <pose>-5.9890042839301794 -7.1125745155734998 0.43285546917182116 0 0 0</pose>
        <inertial>
          <pose>0 0 0 0 0 0</pose>
          <mass>1</mass>
          <inertia>
            <ixx>1</ixx>
            <ixy>0</ixy>
            <ixz>0</ixz>
            <iyy>1</iyy>
            <iyz>0</iyz>
            <izz>1</izz>
          </inertia>
        </inertial>
        <enable_wind>false</enable_wind>
        <collision name='collision_0'>
          <pose>0 0 0 0 0 0</pose>
          <geometry>
            <capsule>
              <radius>2.4501565737872215</radius>
              <length>1.2356679831967681</length>
            </capsule>
          </geometry>
          <surface>
            <contact>
              <collide_bitmask>255</collide_bitmask>
            </contact>
            <friction>
              <ode>
                <mu>1</mu>
                <mu2>1</mu2>
                <slip1>0</slip1>
                <slip2>0</slip2>
                <fdir1>0 0 0</fdir1>
              </ode>
            </friction>
          </surface>
        </collision>
        <visual name='visual_0'>
          <pose>0 0 0 0 0 0</pose>
          <geometry>
            <capsule>
              <radius>2.4501565737872215</radius>
              <length>1.2356679831967681</length>
            </capsule>
          </geometry>
          <cast_shadows>true</cast_shadows>
          <laser_retro>0</laser_retro>
          <transparency>0</transparency>
          <visibility_flags>4294967295</visibility_flags>
          <material>
            <ambient>0.704261005 0.301687121 0.918424964 1</ambient>
            <diffuse>0.704261005 0.301687121 0.918424964 1</diffuse>
            <specular>0 0 0 1</specular>
            <emissive>0 0 0 1</emissive>
            <render_order>0</render_order>
            <lighting>true</lighting>
            <double_sided>false</double_sided>
            <shader type='pixel'/>
          </material>
        </visual>
      </link>
      <link name='link_1'>
        <pose>-4.5974001839325451 7.300740445463493 4.628167045511673 0 0 0</pose>
        <inertial>
          <pose>0 0 0 0 0 0</pose>
          <mass>1</mass>
          <inertia>
            <ixx>1</ixx>
            <ixy>0</ixy>
            <ixz>0</ixz>
            <iyy>1</iyy>
            <iyz>0</iyz>
            <izz>1</izz>
          </inertia>
        </inertial>
        <enable_wind>false</enable_wind>
        <collision name='collision_1'>
          <pose>0 0 0 0 0 0</pose>
          <geometry>
            <box>
              <size>2.8746971335475138 1.2297841017177686 2.4708931397273091</size>
            </box>
          </geometry>
          <surface>
            <contact>
              <collide_bitmask>255</collide_bitmask>
            </contact>
            <friction>
              <ode>
                <mu>1</mu>
                <mu2>1</mu2>
                <slip1>0</slip1>
                <slip2>0</slip2>
                <fdir1>0 0 0</fdir1>
              </ode>
            </friction>
          </surface>
        </collision>
        <visual name='visual_1'>
          <pose>0 0 0 0 0 0</pose>
          <geometry>
            <box>
              <size>2.8746971335475138 1.2297841017177686 2.4708931397273091</size>
            </box>
          </geometry>
          <cast_shadows>true</cast_shadows>
          <laser_retro>0</laser_retro>
          <transparency>0</transparency>
          <visibility_flags>4294967295</visibility_flags>
          <material>
            <ambient>0.443110019 0.448223263 0.216585815 1</ambient>
            <diffuse>0.443110019 0.448223263 0.216585815 1</diffuse>
            <specular>0 0 0 1</specular>
            <emissive>0 0 0 1</emissive>
            <render_order>0</render_order>
            <lighting>true</lighting>
            <double_sided>false</double_sided>
            <shader type='pixel'/>
          </material>
        </visual>
      </link>
      <link name='link_2'>
        <pose>2.8313485704058436 3.6466973428530185 6.0835239517973463 0 0 0</pose>
        <inertial>
          <pose>0 0 0 0 0 0</pose>
          <mass>1</mass>
          <inertia>
            <ixx>1</ixx>
            <ixy>0</ixy>
            <ixz>0</ixz>
            <iyy>1</iyy>
            <iyz>0</iyz>
            <izz>1</izz>
          </inertia>
        </inertial>
        <enable_wind>false</enable_wind>
        <collision name='collision_2'>
          <pose>0 0 0 0 0 0</pose>
          <geometry>
            <cylinder>
              <radius>2.4787043148304888</radius>
              <length>2.2671231150439839</length>
            </cylinder>
          </geometry>
          <surface>
            <contact>
              <collide_bitmask>255</collide_bitmask>
            </contact>
            <friction>
              <ode>
                <mu>1</mu>
                <mu2>1</mu2>
                <slip1>0</slip1>
                <slip2>0</slip2>
                <fdir1>0 0 0</fdir1>
              </ode>
            </friction>
          </surface>
        </collision>
        <visual name='visual_2'>
          <pose>0 0 0 0 0 0</pose>
          <geometry>
            <cylinder>
              <radius>2.4787043148304888</radius>
              <length>2.2671231150439839</length>
            </cylinder>
          </geometry>
          <cast_shadows>true</cast_shadows>
          <laser_retro>0</laser_retro>
          <transparency>0</transparency>
          <visibility_flags>4294967295</visibility_flags>
          <material>
            <ambient>0.267966539 0.214486539 0.586967528 1</ambient>
            <diffuse>0.267966539 0.214486539 0.586967528 1</diffuse>
            <specular>0 0 0 1</specular>
            <emissive>0 0 0 1</emissive>
            <render_order>0</render_order>
            <lighting>true</lighting>
            <double_sided>false</double_sided>
            <shader type='pixel'/>
          </material>
        </visual>
      </link>
      <joint name='joint_0' type='ball'>
        <pose>0 0 0 0 0 0</pose>
        <parent>link_2</parent>
        <child>link_0</child>
        <axis>
          <xyz>0.027505820455290736 0.86270551832866038 0.50495803636179393</xyz>
          <limit>
            <lower>-inf</lower>
            <upper>inf</upper>
            <effort>inf</effort>
            <velocity>2.3224866223927609</velocity>
            <stiffness>100000000</stiffness>
            <dissipation>1</dissipation>
          </limit>
          <dynamics>
            <spring_reference>0</spring_reference>
            <spring_stiffness>0</spring_stiffness>
            <damping>0</damping>
            <friction>0</friction>
          </dynamics>
        </axis>
        <axis2>
          <xyz>0.34249028016202709 0.54833831810605238 0.76290595546971707</xyz>
          <limit>
            <lower>-inf</lower>
            <upper>inf</upper>
            <effort>inf</effort>
            <velocity>0.63017828380564023</velocity>
            <stiffness>100000000</stiffness>
            <dissipation>1</dissipation>
          </limit>
          <dynamics>
            <spring_reference>0</spring_reference>
            <spring_stiffness>0</spring_stiffness>
            <damping>0</damping>
            <friction>0</friction>
          </dynamics>
        </axis2>
      </joint>
      <joint name='joint_1' type='gearbox'>
        <pose>0 0 0 0 0 0</pose>
        <parent>link_2</parent>
        <child>link_1</child>
        <axis>
          <xyz>0.3503150138008933 0.84678154047150955 0.4003004044744114</xyz>
          <limit>
            <lower>-inf</lower>
            <upper>inf</upper>
            <effort>inf</effort>
            <velocity>6.1117309249699137</velocity>
            <stiffness>100000000</stiffness>
            <dissipation>1</dissipation>
          </limit>
          <dynamics>
            <spring_reference>0</spring_reference>
            <spring_stiffness>0</spring_stiffness>
            <damping>0</damping>
            <friction>0</friction>
          </dynamics>
        </axis>
        <axis2>
          <xyz>0.40762165763630176 0.88023729062956013 0.2429545151071798</xyz>
          <limit>
            <lower>-inf</lower>
            <upper>inf</upper>
            <effort>inf</effort>
            <velocity>2.7980841408009294</velocity>
            <stiffness>100000000</stiffness>
            <dissipation>1</dissipation>
          </limit>
          <dynamics>
            <spring_reference>0</spring_reference>
            <spring_stiffness>0</spring_stiffness>
            <damping>0</damping>
            <friction>0</friction>
          </dynamics>
        </axis2>
      </joint>
      <plugin name='gz::sim::systems::PythonSystemLoader' filename='gz-sim-python-system-loader-system'>
        <module_name>driver</module_name>
        <force>100</force>
      </plugin>
    </model>
    <model name='model_1'>
      <static>false</static>
      <self_collide>false</self_collide>
      <allow_auto_disable>true</allow_auto_disable>
      <enable_wind>false</enable_wind>
      <pose>-0.78831517063099454 -6.8497899376522682 7.1262013835574542 0 0 0</pose>
      <link name='link_3'>
        <pose>1.2008473686690735 3.9169031284079878 3.2258481984316401 0 0 0</pose>
        <inertial>
          <pose>0 0 0 0 0 0</pose>
          <mass>1</mass>
          <inertia>
            <ixx>1</ixx>
            <ixy>0</ixy>
            <ixz>0</ixz>
            <iyy>1</iyy>
            <iyz>0</iyz>
            <izz>1</izz>
          </inertia>
        </inertial>
        <enable_wind>false</enable_wind>
        <collision name='collision_3'>
          <pose>0 0 0 0 0 0</pose>
          <geometry>
            <sphere>
              <radius>1.7597632592988017</radius>
            </sphere>
          </geometry>
          <surface>
            <contact>
              <collide_bitmask>255</collide_bitmask>
            </contact>
            <friction>
              <ode>
                <mu>1</mu>
                <mu2>1</mu2>
                <slip1>0</slip1>
                <slip2>0</slip2>
                <fdir1>0 0 0</fdir1>
              </ode>
            </friction>
          </surface>
        </collision>
        <visual name='visual_3'>
          <pose>0 0 0 0 0 0</pose>
          <geometry>
            <sphere>
              <radius>1.7597632592988017</radius>
            </sphere>
          </geometry>
          <cast_shadows>true</cast_shadows>
          <laser_retro>0</laser_retro>
          <transparency>0</transparency>
          <visibility_flags>4294967295</visibility_flags>
          <material>
            <ambient>0.645227134 0.64094162 0.193734527 1</ambient>
            <diffuse>0.645227134 0.64094162 0.193734527 1</diffuse>
            <specular>0 0 0 1</specular>
            <emissive>0 0 0 1</emissive>
            <render_order>0</render_order>
            <lighting>true</lighting>
            <double_sided>false</double_sided>
            <shader type='pixel'/>
          </material>
        </visual>
      </link>
      <link name='link_4'>
        <pose>-6.4659438738185004 4.4126620600949025 1.7815836803333862 0 0 0</pose>
        <inertial>
          <pose>0 0 0 0 0 0</pose>
          <mass>1</mass>
          <inertia>
            <ixx>1</ixx>
            <ixy>0</ixy>
            <ixz>0</ixz>
            <iyy>1</iyy>
            <iyz>0</iyz>
            <izz>1</izz>
          </inertia>
        </inertial>
        <enable_wind>false</enable_wind>
        <collision name='collision_4'>
          <pose>0 0 0 0 0 0</pose>
          <geometry>
            <cylinder>
              <radius>1.9972091046523641</radius>
              <length>1.2391785228387453</length>
            </cylinder>
          </geometry>
          <surface>
            <contact>
              <collide_bitmask>255</collide_bitmask>
            </contact>
            <friction>
              <ode>
                <mu>1</mu>
                <mu2>1</mu2>
                <slip1>0</slip1>
                <slip2>0</slip2>
                <fdir1>0 0 0</fdir1>
              </ode>
            </friction>
          </surface>
        </collision>
        <visual name='visual_4'>
          <pose>0 0 0 0 0 0</pose>
          <geometry>
            <cylinder>
              <radius>1.9972091046523641</radius>
              <length>1.2391785228387453</length>
            </cylinder>
          </geometry>
          <cast_shadows>true</cast_shadows>
          <laser_retro>0</laser_retro>
          <transparency>0</transparency>
          <visibility_flags>4294967295</visibility_flags>
          <material>
            <ambient>0.199809477 0.344328851 0.307083935 1</ambient>
            <diffuse>0.199809477 0.344328851 0.307083935 1</diffuse>
            <specular>0 0 0 1</specular>
            <emissive>0 0 0 1</emissive>
            <render_order>0</render_order>
            <lighting>true</lighting>
            <double_sided>false</double_sided>
            <shader type='pixel'/>
          </material>
        </visual>
      </link>
      <link name='link_5'>
        <pose>-6.9083473096687609 -5.0097403242943024 1.4746482336867905 0 0 0</pose>
        <inertial>
          <pose>0 0 0 0 0 0</pose>
          <mass>1</mass>
          <inertia>
            <ixx>1</ixx>
            <ixy>0</ixy>
            <ixz>0</ixz>
            <iyy>1</iyy>
            <iyz>0</iyz>
            <izz>1</izz>
          </inertia>
        </inertial>
        <enable_wind>false</enable_wind>
        <collision name='collision_5'>
          <pose>0 0 0 0 0 0</pose>
          <geometry>
            <capsule>
              <radius>2.3175022857709235</radius>
              <length>1.0053213154325524</length>
            </capsule>
          </geometry>
          <surface>
            <contact>
              <collide_bitmask>255</collide_bitmask>
            </contact>
            <friction>
              <ode>
                <mu>1</mu>
                <mu2>1</mu2>
                <slip1>0</slip1>
                <slip2>0</slip2>
                <fdir1>0 0 0</fdir1>
              </ode>
            </friction>
          </surface>
        </collision>
        <visual name='visual_5'>
          <pose>0 0 0 0 0 0</pose>
          <geometry>
            <capsule>
              <radius>2.3175022857709235</radius>
              <length>1.0053213154325524</length>
            </capsule>
          </geometry>
          <cast_shadows>true</cast_shadows>
          <laser_retro>0</laser_retro>
          <transparency>0</transparency>
          <visibility_flags>4294967295</visibility_flags>
          <material>
            <ambient>0.925798953 0.728391469 0.900789022 1</ambient>
            <diffuse>0.925798953 0.728391469 0.900789022 1</diffuse>
            <specular>0 0 0 1</specular>
            <emissive>0 0 0 1</emissive>
            <render_order>0</render_order>
            <lighting>true</lighting>
            <double_sided>false</double_sided>
            <shader type='pixel'/>
          </material>
        </visual>
      </link>
      <joint name='joint_2' type='ball'>
        <pose>0 0 0 0 0 0</pose>
        <parent>link_4</parent>
        <child>link_3</child>
        <axis>
          <xyz>0.74596877281534502 0.66364165255145624 0.055770484874530422</xyz>
          <limit>
            <lower>-inf</lower>
            <upper>inf</upper>
            <effort>inf</effort>
            <velocity>4.6481536504767407</velocity>
            <stiffness>100000000</stiffness>
            <dissipation>1</dissipation>
          </limit>
          <dynamics>
            <spring_reference>0</spring_reference>
            <spring_stiffness>0</spring_stiffness>
            <damping>0</damping>
            <friction>0</friction>
          </dynamics>
        </axis>
        <axis2>
          <xyz>0.045943794202045841 0.83662881178559045 0.54584008561533026</xyz>
          <limit>
            <lower>-inf</lower>
            <upper>inf</upper>
            <effort>inf</effort>
            <velocity>1.8597970284314025</velocity>
            <stiffness>100000000</stiffness>
            <dissipation>1</dissipation>
          </limit>
          <dynamics>
            <spring_reference>0</spring_reference>
            <spring_stiffness>0</spring_stiffness>
            <damping>0</damping>
            <friction>0</friction>
          </dynamics>
        </axis2>
      </joint>
      <joint name='joint_3' type='revolute'>
        <pose>0 0 0 0 0 0</pose>
        <parent>link_3</parent>
        <child>link_4</child>
        <axis>
          <xyz>0.62618838910317365 0.63699252903696846 0.44958716541229193</xyz>
          <limit>
            <lower>-inf</lower>
            <upper>inf</upper>
            <effort>inf</effort>
            <velocity>5.4664809070338887</velocity>
            <stiffness>100000000</stiffness>
            <dissipation>1</dissipation>
          </limit>
          <dynamics>
            <spring_reference>0</spring_reference>
            <spring_stiffness>0</spring_stiffness>
            <damping>0</damping>
            <friction>0</friction>
          </dynamics>
        </axis>
        <axis2>
          <xyz>0.62744127973267738 0.7631469276268934 0.15467452065887655</xyz>
          <limit>
            <lower>-inf</lower>
            <upper>inf</upper>
            <effort>inf</effort>
            <velocity>0.87264887431241944</velocity>
            <stiffness>100000000</stiffness>
            <dissipation>1</dissipation>
          </limit>
          <dynamics>
            <spring_reference>0</spring_reference>
            <spring_stiffness>0</spring_stiffness>
            <damping>0</damping>
            <friction>0</friction>
          </dynamics>
        </axis2>
      </joint>
      <plugin name='gz::sim::systems::PythonSystemLoader' filename='gz-sim-python-system-loader-system'>
        <module_name>driver</module_name>
        <force>100</force>
      </plugin>
    </model>
    <model name='ground_model'>
      <static>true</static>
      <self_collide>false</self_collide>
      <allow_auto_disable>true</allow_auto_disable>
      <enable_wind>false</enable_wind>
      <pose>0 0 0 0 0 0</pose>
      <link name='ground_link'>
        <pose>0 0 0 0 0 0</pose>
        <inertial>
          <pose>0 0 0 0 0 0</pose>
          <mass>1</mass>
          <inertia>
            <ixx>1</ixx>
            <ixy>0</ixy>
            <ixz>0</ixz>
            <iyy>1</iyy>
            <iyz>0</iyz>
            <izz>1</izz>
          </inertia>
        </inertial>
        <enable_wind>false</enable_wind>
        <collision name='ground_collision'>
          <pose>0 0 0 0 0 0</pose>
          <geometry>
            <plane>
              <normal>0 0 1</normal>
              <size>100 100</size>
            </plane>
          </geometry>
          <surface>
            <contact>
              <collide_bitmask>255</collide_bitmask>
            </contact>
            <friction>
              <ode>
                <mu>1</mu>
                <mu2>1</mu2>
                <slip1>0</slip1>
                <slip2>0</slip2>
                <fdir1>0 0 0</fdir1>
              </ode>
            </friction>
          </surface>
        </collision>
      </link>
    </model>
    <model name='ceiling_model'>
      <static>true</static>
      <self_collide>false</self_collide>
      <allow_auto_disable>true</allow_auto_disable>
      <enable_wind>false</enable_wind>
      <pose>0 0 100 0 0 0</pose>
      <link name='ceiling_link'>
        <pose>0 0 0 0 0 0</pose>
        <inertial>
          <pose>0 0 0 0 0 0</pose>
          <mass>1</mass>
          <inertia>
            <ixx>1</ixx>
            <ixy>0</ixy>
            <ixz>0</ixz>
            <iyy>1</iyy>
            <iyz>0</iyz>
            <izz>1</izz>
          </inertia>
        </inertial>
        <enable_wind>false</enable_wind>
        <collision name='ceiling_collision'>
          <pose>0 0 0 0 0 0</pose>
          <geometry>
            <box>
              <size>102 102 3</size>
            </box>
          </geometry>
          <surface>
            <contact>
              <collide_bitmask>255</collide_bitmask>
            </contact>
            <friction>
              <ode>
                <mu>1</mu>
                <mu2>1</mu2>
                <slip1>0</slip1>
                <slip2>0</slip2>
                <fdir1>0 0 0</fdir1>
              </ode>
            </friction>
          </surface>
        </collision>
        <visual name='ceiling_visual'>
          <pose>0 0 0 0 0 0</pose>
          <geometry>
            <box>
              <size>102 102 3</size>
            </box>
          </geometry>
          <cast_shadows>true</cast_shadows>
          <laser_retro>0</laser_retro>
          <transparency>0</transparency>
          <visibility_flags>4294967295</visibility_flags>
          <material>
            <ambient>0.200000003 0.200000003 0.200000003 0.200000003</ambient>
            <diffuse>0.200000003 0.200000003 0.200000003 0.200000003</diffuse>
            <specular>0 0 0 1</specular>
            <emissive>0 0 0 1</emissive>
            <render_order>0</render_order>
            <lighting>true</lighting>
            <double_sided>false</double_sided>
            <shader type='pixel'/>
          </material>
        </visual>
      </link>
    </model>
    <model name='west_model'>
      <static>true</static>
      <self_collide>false</self_collide>
      <allow_auto_disable>true</allow_auto_disable>
      <enable_wind>false</enable_wind>
      <pose>0 50 50 0 0 0</pose>
      <link name='west_link'>
        <pose>0 0 0 0 0 0</pose>
        <inertial>
          <pose>0 0 0 0 0 0</pose>
          <mass>1</mass>
          <inertia>
            <ixx>1</ixx>
            <ixy>0</ixy>
            <ixz>0</ixz>
            <iyy>1</iyy>
            <iyz>0</iyz>
            <izz>1</izz>
          </inertia>
        </inertial>
        <enable_wind>false</enable_wind>
        <collision name='west_collision'>
          <pose>0 0 0 0 0 0</pose>
          <geometry>
            <box>
              <size>102 3 102</size>
            </box>
          </geometry>
          <surface>
            <contact>
              <collide_bitmask>255</collide_bitmask>
            </contact>
            <friction>
              <ode>
                <mu>1</mu>
                <mu2>1</mu2>
                <slip1>0</slip1>
                <slip2>0</slip2>
                <fdir1>0 0 0</fdir1>
              </ode>
            </friction>
          </surface>
        </collision>
        <visual name='west_visual'>
          <pose>0 0 0 0 0 0</pose>
          <geometry>
            <box>
              <size>102 3 102</size>
            </box>
          </geometry>
          <cast_shadows>true</cast_shadows>
          <laser_retro>0</laser_retro>
          <transparency>0</transparency>
          <visibility_flags>4294967295</visibility_flags>
          <material>
            <ambient>0.200000003 0.200000003 0.200000003 0.200000003</ambient>
            <diffuse>0.200000003 0.200000003 0.200000003 0.200000003</diffuse>
            <specular>0 0 0 1</specular>
            <emissive>0 0 0 1</emissive>
            <render_order>0</render_order>
            <lighting>true</lighting>
            <double_sided>false</double_sided>
            <shader type='pixel'/>
          </material>
        </visual>
      </link>
    </model>
    <model name='east_model'>
      <static>true</static>
      <self_collide>false</self_collide>
      <allow_auto_disable>true</allow_auto_disable>
      <enable_wind>false</enable_wind>
      <pose>0 -50 50 0 0 0</pose>
      <link name='east_link'>
        <pose>0 0 0 0 0 0</pose>
        <inertial>
          <pose>0 0 0 0 0 0</pose>
          <mass>1</mass>
          <inertia>
            <ixx>1</ixx>
            <ixy>0</ixy>
            <ixz>0</ixz>
            <iyy>1</iyy>
            <iyz>0</iyz>
            <izz>1</izz>
          </inertia>
        </inertial>
        <enable_wind>false</enable_wind>
        <collision name='east_collision'>
          <pose>0 0 0 0 0 0</pose>
          <geometry>
            <box>
              <size>102 3 102</size>
            </box>
          </geometry>
          <surface>
            <contact>
              <collide_bitmask>255</collide_bitmask>
            </contact>
            <friction>
              <ode>
                <mu>1</mu>
                <mu2>1</mu2>
                <slip1>0</slip1>
                <slip2>0</slip2>
                <fdir1>0 0 0</fdir1>
              </ode>
            </friction>
          </surface>
        </collision>
        <visual name='east_visual'>
          <pose>0 0 0 0 0 0</pose>
          <geometry>
            <box>
              <size>102 3 102</size>
            </box>
          </geometry>
          <cast_shadows>true</cast_shadows>
          <laser_retro>0</laser_retro>
          <transparency>0</transparency>
          <visibility_flags>4294967295</visibility_flags>
          <material>
            <ambient>0.200000003 0.200000003 0.200000003 0.200000003</ambient>
            <diffuse>0.200000003 0.200000003 0.200000003 0.200000003</diffuse>
            <specular>0 0 0 1</specular>
            <emissive>0 0 0 1</emissive>
            <render_order>0</render_order>
            <lighting>true</lighting>
            <double_sided>false</double_sided>
            <shader type='pixel'/>
          </material>
        </visual>
      </link>
    </model>
    <model name='north_model'>
      <static>true</static>
      <self_collide>false</self_collide>
      <allow_auto_disable>true</allow_auto_disable>
      <enable_wind>false</enable_wind>
      <pose>50 0 50 0 0 0</pose>
      <link name='north_link'>
        <pose>0 0 0 0 0 0</pose>
        <inertial>
          <pose>0 0 0 0 0 0</pose>
          <mass>1</mass>
          <inertia>
            <ixx>1</ixx>
            <ixy>0</ixy>
            <ixz>0</ixz>
            <iyy>1</iyy>
            <iyz>0</iyz>
            <izz>1</izz>
          </inertia>
        </inertial>
        <enable_wind>false</enable_wind>
        <collision name='north_collision'>
          <pose>0 0 0 0 0 0</pose>
          <geometry>
            <box>
              <size>3 102 102</size>
            </box>
          </geometry>
          <surface>
            <contact>
              <collide_bitmask>255</collide_bitmask>
            </contact>
            <friction>
              <ode>
                <mu>1</mu>
                <mu2>1</mu2>
                <slip1>0</slip1>
                <slip2>0</slip2>
                <fdir1>0 0 0</fdir1>
              </ode>
            </friction>
          </surface>
        </collision>
        <visual name='north_visual'>
          <pose>0 0 0 0 0 0</pose>
          <geometry>
            <box>
              <size>3 102 102</size>
            </box>
          </geometry>
          <cast_shadows>true</cast_shadows>
          <laser_retro>0</laser_retro>
          <transparency>0</transparency>
          <visibility_flags>4294967295</visibility_flags>
          <material>
            <ambient>0.200000003 0.200000003 0.200000003 0.200000003</ambient>
            <diffuse>0.200000003 0.200000003 0.200000003 0.200000003</diffuse>
            <specular>0 0 0 1</specular>
            <emissive>0 0 0 1</emissive>
            <render_order>0</render_order>
            <lighting>true</lighting>
            <double_sided>false</double_sided>
            <shader type='pixel'/>
          </material>
        </visual>
      </link>
    </model>
    <model name='south_model'>
      <static>true</static>
      <self_collide>false</self_collide>
      <allow_auto_disable>true</allow_auto_disable>
      <enable_wind>false</enable_wind>
      <pose>-50 0 50 0 0 0</pose>
      <link name='south_link'>
        <pose>0 0 0 0 0 0</pose>
        <inertial>
          <pose>0 0 0 0 0 0</pose>
          <mass>1</mass>
          <inertia>
            <ixx>1</ixx>
            <ixy>0</ixy>
            <ixz>0</ixz>
            <iyy>1</iyy>
            <iyz>0</iyz>
            <izz>1</izz>
          </inertia>
        </inertial>
        <enable_wind>false</enable_wind>
        <collision name='south_collision'>
          <pose>0 0 0 0 0 0</pose>
          <geometry>
            <box>
              <size>3 102 102</size>
            </box>
          </geometry>
          <surface>
            <contact>
              <collide_bitmask>255</collide_bitmask>
            </contact>
            <friction>
              <ode>
                <mu>1</mu>
                <mu2>1</mu2>
                <slip1>0</slip1>
                <slip2>0</slip2>
                <fdir1>0 0 0</fdir1>
              </ode>
            </friction>
          </surface>
        </collision>
        <visual name='south_visual'>
          <pose>0 0 0 0 0 0</pose>
          <geometry>
            <box>
              <size>3 102 102</size>
            </box>
          </geometry>
          <cast_shadows>true</cast_shadows>
          <laser_retro>0</laser_retro>
          <transparency>0</transparency>
          <visibility_flags>4294967295</visibility_flags>
          <material>
            <ambient>0.200000003 0.200000003 0.200000003 0.200000003</ambient>
            <diffuse>0.200000003 0.200000003 0.200000003 0.200000003</diffuse>
            <specular>0 0 0 1</specular>
            <emissive>0 0 0 1</emissive>
            <render_order>0</render_order>
            <lighting>true</lighting>
            <double_sided>false</double_sided>
            <shader type='pixel'/>
          </material>
        </visual>
      </link>
    </model>
    <atmosphere type='adiabatic'>
      <temperature>288.14999999999998</temperature>
      <pressure>101325</pressure>
      <temperature_gradient>-0.0064999999999999997</temperature_gradient>
    </atmosphere>
    <scene>
      <ambient>0.400000006 0.400000006 0.400000006 1</ambient>
      <background>0.699999988 0.699999988 0.699999988 1</background>
      <grid>true</grid>
      <origin_visual>true</origin_visual>
      <shadows>true</shadows>
    </scene>
  </world>
</sdf>
