Warning: Ignoring XDG_SESSION_TYPE=wayland on Gnome. Use QT_QPA_PLATFORM=wayland to run on Wayland anyway.
[1;31m[Err] [UserCommands.cc:1145] [0m[1;31mError Code [0m[1;31m30[0m[1;31m: [0m[1;31mMsg: [0m[1;31mError parsing XML from string: Error=XML_ERROR_PARSING_TEXT ErrorID=8 (0x8) Line number=1[0m[1;31m[0m
[1;31m[Err] [UserCommands.cc:1145] [0m[1;31mError Code [0m[1;31m30[0m[1;31m: [0m[1;31mMsg: [0m[1;31mUnable to read SDF string: b"<sdf version="1.11">\n  <model name="model">\n    <static>false</static>\n    <self_collide>false</self_collide>\n    <allow_auto_disable>true</allow_auto_disable>\n    <enable_wind>true</enable_wind>\n    <pose>1.3965102078202172 -1.1420791836904876 4.2957336950664278 0 0 0</pose>\n    <link name="link_4848">\n      <pose>-1.3185938644189577 9.613182638441284 0.83983318736996937 0 0 0</pose>\n      <inertial>\n        <pose>0 0 0 0 0 0</pose>\n        <mass>1</mass>\n        <inertia>\n          <ixx>1</ixx>\n          <ixy>0</ixy>\n          <ixz>0</ixz>\n          <iyy>1</iyy>\n          <iyz>0</iyz>\n          <izz>1</izz>\n        </inertia>\n      </inertial>\n      <enable_wind>false</enable_wind>\n      <collision name="collision_4848">\n        <pose>0 0 0 0 0 0</pose>\n        <geometry>\n          <sphere>\n            <radius>2.4241309193482774</radius>\n          </sphere>\n        </geometry>\n        <surface>\n          <contact>\n            <collide_bitmask>255</collide_bitmask>\n          </contact>\n          <friction>\n            <ode>\n              <mu>1</mu>\n              <mu2>1</mu2>\n              <slip1>0</slip1>\n              <slip2>0</slip2>\n              <fdir1>0 0 0</fdir1>\n            </ode>\n          </friction>\n        </surface>\n      </collision>\n      <visual name="visual_4848">\n        <pose>0 0 0 0 0 0</pose>\n        <geometry>\n          <sphere>\n            <radius>2.4241309193482774</radius>\n          </sphere>\n        </geometry>\n        <cast_shadows>true</cast_shadows>\n        <laser_retro>0</laser_retro>\n        <transparency>0</transparency>\n        <visibility_flags>4294967295</visibility_flags>\n        <material>\n          <ambient>0.957631826 0.23273553 0.401041478 1</ambient>\n          <diffuse>0.957631826 0.23273553 0.401041478 1</diffuse>\n          <specular>0 0 0 1</specular>\n          <emissive>0 0 0 1</emissive>\n          <render_order>0</render_order>\n          <lighting>true</lighting>\n          <double_sided>false</double_sided>\n          <shader type="pixel"/>\n        </material>\n      </visual>\n    </link>\n    <link name="link_4849">\n      <pose>1.2279229825479998 0.026843929107789322 2.6549807662145142 0 0 0</pose>\n      <inertial>\n        <pose>0 0 0 0 0 0</pose>\n        <mass>1</mass>\n        <inertia>\n          <ixx>1</ixx>\n          <ixy>0</ixy>\n          <ixz>0</ixz>\n          <iyy>1</iyy>\n          <iyz>0</iyz>\n          <izz>1</izz>\n        </inertia>\n      </inertial>\n      <enable_wind>false</enable_wind>\n      <collision name="collision_4849">\n        <pose>0 0 0 0 0 0</pose>\n        <geometry>\n          <cylinder>\n            <radius>1.3878813431893546</radius>\n            <length>1.1407277553539463</length>\n          </cylinder>\n        </geometry>\n        <surface>\n          <contact>\n            <collide_bitmask>255</collide_bitmask>\n          </contact>\n          <friction>\n            <ode>\n              <mu>1</mu>\n              <mu2>1</mu2>\n              <slip1>0</slip1>\n              <slip2>0</slip2>\n              <fdir1>0 0 0</fdir1>\n            </ode>\n          </friction>\n        </surface>\n      </collision>\n      <visual name="visual_4849">\n        <pose>0 0 0 0 0 0</pose>\n        <geometry>\n          <cylinder>\n            <radius>1.3878813431893546</radius>\n            <length>1.1407277553539463</length>\n          </cylinder>\n        </geometry>\n        <cast_shadows>true</cast_shadows>\n        <laser_retro>0</laser_retro>\n        <transparency>0</transparency>\n        <visibility_flags>4294967295</visibility_flags>\n        <material>\n          <ambient>0.830266297 0.0639644563 0.684107304 1</ambient>\n          <diffuse>0.830266297 0.0639644563 0.684107304 1</diffuse>\n          <specular>0 0 0 1</specular>\n          <emissive>0 0 0 1</emissive>\n          <render_order>0</render_order>\n          <lighting>true</lighting>\n          <double_sided>false</double_sided>\n          <shader type="pixel"/>\n        </material>\n      </visual>\n    </link>\n    <link name="link_4850">\n      <pose>-8.5706782859087038 8.8762713522966905 8.9721032686730293 0 0 0</pose>\n      <inertial>\n        <pose>0 0 0 0 0 0</pose>\n        <mass>1</mass>\n        <inertia>\n          <ixx>1</ixx>\n          <ixy>0</ixy>\n          <ixz>0</ixz>\n          <iyy>1</iyy>\n          <iyz>0</iyz>\n          <izz>1</izz>\n        </inertia>\n      </inertial>\n      <enable_wind>false</enable_wind>\n      <collision name="collision_4850">\n        <pose>0 0 0 0 0 0</pose>\n        <geometry>\n          <cylinder>\n            <radius>1.4293317620667476</radius>\n            <length>1.7996812512087106</length>\n          </cylinder>\n        </geometry>\n        <surface>\n          <contact>\n            <collide_bitmask>255</collide_bitmask>\n          </contact>\n          <friction>\n            <ode>\n              <mu>1</mu>\n              <mu2>1</mu2>\n              <slip1>0</slip1>\n              <slip2>0</slip2>\n              <fdir1>0 0 0</fdir1>\n            </ode>\n          </friction>\n        </surface>\n      </collision>\n      <visual name="visual_4850">\n        <pose>0 0 0 0 0 0</pose>\n        <geometry>\n          <cylinder>\n            <radius>1.4293317620667476</radius>\n            <length>1.7996812512087106</length>\n          </cylinder>\n        </geometry>\n        <cast_shadows>true</cast_shadows>\n        <laser_retro>0</laser_retro>\n        <transparency>0</transparency>\n        <visibility_flags>4294967295</visibility_flags>\n        <material>\n          <ambient>0.640317202 0.375142604 0.300994992 1</ambient>\n          <diffuse>0.640317202 0.375142604 0.300994992 1</diffuse>\n          <specular>0 0 0 1</specular>\n          <emissive>0 0 0 1</emissive>\n          <render_order>0</render_order>\n          <lighting>true</lighting>\n          <double_sided>false</double_sided>\n          <shader type="pixel"/>\n        </material>\n      </visual>\n    </link>\n    <joint name="joint_3232" type="gearbox">\n      <pose>0 0 0 0 0 0</pose>\n      <parent>link_4849</parent>\n      <child>link_4850</child>\n      <axis>\n        <xyz>0.21007070857153262 0.89476850404818231 0.39402997546332974</xyz>\n        <limit>\n          <lower>-inf</lower>\n          <upper>inf</upper>\n          <effort>inf</effort>\n          <velocity>8.6803300248703419</velocity>\n          <stiffness>100000000</stiffness>\n          <dissipation>1</dissipation>\n        </limit>\n        <dynamics>\n          <spring_reference>0</spring_reference>\n          <spring_stiffness>-492831</spring_stiffness>\n          <damping>0</damping>\n          <friction>0</friction>\n        </dynamics>\n      </axis>\n      <axis2>\n        <xyz>0.084755076567893078 0.77322259385451109 0.62844522223410393</xyz>\n        <limit>\n          <lower>-inf</lower>\n          <upper>inf</upper>\n          <effort>inf</effort>\n          <velocity>7.3581002439206147</velocity>\n          <stiffness>100000000</stiffness>\n          <dissipation>1</dissipation>\n        </limit>\n        <dynamics>\n          <spring_reference>0</spring_reference>\n          <spring_stiffness>0</spring_stiffness>\n          <damping>0</damping>\n          <friction>0</friction>\n        </dynamics>\n      </axis2>\n    </joint>\n    <joint name="joint_3233" type="prismatic">\n      <pose>0 0 0 0 0 0</pose>\n      <parent>link_4848</parent>\n      <child>link_4850</child>\n      <axis>\n        <xyz>0.72058265353715856 0.60402918919194293 0.3404546636858885</xyz>\n        <limit>\n          <lower>-inf</lower>\n          <upper>inf</upper>\n          <effort>inf</effort>\n          <velocity>1.3625949768321732</velocity>\n          <stiffness>100000000</stiffness>\n          <dissipation>1</dissipation>\n        </limit>\n        <dynamics>\n          <spring_reference>0</spring_reference>\n          <spring_stiffness>0</spring_stiffness>\n          <damping>0</damping>\n          <friction>0</friction>\n        </dynamics>\n      </axis>\n      <axis2>\n        <xyz>0.074700891355882856 0.63930145548656647 0.76531916599768635</xyz>\n        <limit>\n          <lower>-inf</lower>\n          <upper>inf</upper>\n          <effort>inf</effort>\n          <velocity>9.1643158424189028</velocity>\n          <stiffness>100000000</stiffness>\n          <dissipation>1</dissipation>\n        </limit>\n        <dynamics>\n          <spring_reference>0</spring_reference>\n          <spring_stiffness>0</spring_stiffness>\n          <damping>0</damping>\n          <friction>0</friction>\n        </dynamics>\n      </axis2>\n    </joint>\n  </model>\n</sdf>\n"[0m[1;31m[0m
Stack trace (most recent call last):
#30   Object "[0xffffffffffffffff]", at 0xffffffffffffffff, in 
#29   Object "gz sim server", at 0x5872d22e31c4, in _start
#28   Object "/lib/x86_64-linux-gnu/libc.so.6", at 0x7ea87c229e3f, in __libc_start_main
#27   Object "/lib/x86_64-linux-gnu/libc.so.6", at 0x7ea87c229d8f, in 
#26   Object "gz sim server", at 0x5872d22e317e, in 
#25   Object "/lib/x86_64-linux-gnu/libruby-3.0.so.3.0", at 0x7ea87c6a8e19, in ruby_run_node
#24   Object "/lib/x86_64-linux-gnu/libruby-3.0.so.3.0", at 0x7ea87c6a5317, in 
#23   Object "/lib/x86_64-linux-gnu/libruby-3.0.so.3.0", at 0x7ea87c83a30c, in rb_vm_exec
#22   Object "/lib/x86_64-linux-gnu/libruby-3.0.so.3.0", at 0x7ea87c834c96, in 
#21   Object "/lib/x86_64-linux-gnu/libruby-3.0.so.3.0", at 0x7ea87c831fc5, in 
#20   Object "/lib/x86_64-linux-gnu/libruby-3.0.so.3.0", at 0x7ea87c82fc34, in 
#19   Object "/lib/x86_64-linux-gnu/libruby-3.0.so.3.0", at 0x7ea87c77ba4e, in 
#18   Object "/lib/x86_64-linux-gnu/libruby-3.0.so.3.0", at 0x7ea87c6a69ac, in rb_protect
#17   Object "/lib/x86_64-linux-gnu/libruby-3.0.so.3.0", at 0x7ea87c83ec61, in rb_yield
#16   Object "/lib/x86_64-linux-gnu/libruby-3.0.so.3.0", at 0x7ea87c83a30c, in rb_vm_exec
#15   Object "/lib/x86_64-linux-gnu/libruby-3.0.so.3.0", at 0x7ea87c834c96, in 
#14   Object "/lib/x86_64-linux-gnu/libruby-3.0.so.3.0", at 0x7ea87c831fc5, in 
#13   Object "/lib/x86_64-linux-gnu/libruby-3.0.so.3.0", at 0x7ea87c82fc34, in 
#12   Object "/usr/lib/x86_64-linux-gnu/ruby/3.0.0/fiddle.so", at 0x7ea87c98344b, in 
#11   Object "/lib/x86_64-linux-gnu/libruby-3.0.so.3.0", at 0x7ea87c7fd088, in rb_nogvl
#10   Object "/usr/lib/x86_64-linux-gnu/ruby/3.0.0/fiddle.so", at 0x7ea87c982d6b, in 
#9    Object "/lib/x86_64-linux-gnu/libffi.so.8", at 0x7ea87c42d492, in 
#8    Object "/lib/x86_64-linux-gnu/libffi.so.8", at 0x7ea87c430e2d, in 
#7    Object "/usr/lib/x86_64-linux-gnu/libgz-sim8-gz.so.8.6.0", at 0x7ea87b7d4605, in runServer
#6    Object "/lib/x86_64-linux-gnu/libgz-sim8.so.8", at 0x7ea876b3d485, in 
#5    Object "/lib/x86_64-linux-gnu/libgz-sim8.so.8", at 0x7ea876b4d8a2, in gz::sim::v8::SimulationRunner::Run(unsigned long)
#4    Object "/lib/x86_64-linux-gnu/libgz-sim8.so.8", at 0x7ea876b4ce60, in gz::sim::v8::SimulationRunner::Step(gz::sim::v8::UpdateInfo const&)
#3    Object "/lib/x86_64-linux-gnu/libgz-sim8.so.8", at 0x7ea876b4c031, in gz::sim::v8::SimulationRunner::UpdateSystems()
#2    Object "/usr/lib/x86_64-linux-gnu/gz-sim-8/plugins/libgz-sim-user-commands-system.so", at 0x7ea8641c1210, in gz::sim::v8::systems::UserCommands::PreUpdate(gz::sim::v8::UpdateInfo const&, gz::sim::v8::EntityComponentManager&)
#1    Object "/usr/lib/x86_64-linux-gnu/gz-sim-8/plugins/libgz-sim-user-commands-system.so", at 0x7ea8641cf535, in gz::sim::v8::systems::EnableCollisionCommand::Execute()
#0    Object "/usr/lib/x86_64-linux-gnu/gz-sim-8/plugins/libgz-sim-user-commands-system.so", at 0x7ea8641c9bd4, in gz::sim::v8::systems::UserCommandsInterface::HasContactSensor(unsigned long)
Segmentation fault (Address not mapped to object [0x8])
