Warning: Ignoring XDG_SESSION_TYPE=wayland on Gnome. Use QT_QPA_PLATFORM=wayland to run on Wayland anyway.
[1;31m[Err] [PythonSystemLoader.cc:107] [0m[1;31mError while loading module [0m[1;31mtest_system[0m[1;31m[0m
[1;31mModuleNotFoundError: No module named 'test_system'[0m[1;31m[0m
[1;31m[Err] [PythonSystemLoader.cc:110] [0m[1;31mSearched in:[0m
[1;31m[Err] [PythonSystemLoader.cc:113] [0m[1;31m  "[0m[1;31m"[0m
[1;31m[Err] [PythonSystemLoader.cc:113] [0m[1;31m  "[0m[1;31m/usr/lib/python310.zip[0m[1;31m"[0m
[1;31m[Err] [PythonSystemLoader.cc:113] [0m[1;31m  "[0m[1;31m/usr/lib/python3.10[0m[1;31m"[0m
[1;31m[Err] [PythonSystemLoader.cc:113] [0m[1;31m  "[0m[1;31m/usr/lib/python3.10/lib-dynload[0m[1;31m"[0m
[1;31m[Err] [PythonSystemLoader.cc:113] [0m[1;31m  "[0m[1;31m/home/liyitao/.local/lib/python3.10/site-packages[0m[1;31m"[0m
[1;31m[Err] [PythonSystemLoader.cc:113] [0m[1;31m  "[0m[1;31m/home/liyitao/.local/lib/python3.10/site-packages/unicorn-2.0.2-py3.10.egg[0m[1;31m"[0m
[1;31m[Err] [PythonSystemLoader.cc:113] [0m[1;31m  "[0m[1;31m/home/liyitao/.local/lib/python3.10/site-packages/unicornafl-2.1.0-py3.10.egg[0m[1;31m"[0m
[1;31m[Err] [PythonSystemLoader.cc:113] [0m[1;31m  "[0m[1;31m/usr/local/lib/python3.10/dist-packages[0m[1;31m"[0m
[1;31m[Err] [PythonSystemLoader.cc:113] [0m[1;31m  "[0m[1;31m/usr/lib/python3/dist-packages[0m[1;31m"[0m
[1;31m[Err] [PythonSystemLoader.cc:113] [0m[1;31m  "[0m[1;31m/home/liyitao/.gz/sim/plugins/[0m[1;31m"[0m
[1;31m[Err] [PythonSystemLoader.cc:113] [0m[1;31m  "[0m[1;31m/usr/lib/x86_64-linux-gnu/gz-sim-8/plugins/[0m[1;31m"[0m
[1;31m[Err] [UserCommands.cc:1145] [0m[1;31mError Code [0m[1;31m30[0m[1;31m: [0m[1;31mMsg: [0m[1;31mError parsing XML from string: Error=XML_ERROR_PARSING_TEXT ErrorID=8 (0x8) Line number=1[0m[1;31m[0m
[1;31m[Err] [UserCommands.cc:1145] [0m[1;31mError Code [0m[1;31m30[0m[1;31m: [0m[1;31mMsg: [0m[1;31mUnable to read SDF string: b"<sdf version="1.11">\n  <model name="model">\n    <static>false</static>\n    <self_collide>true</self_collide>\n    <allow_auto_disable>true</allow_auto_disable>\n    <enable_wind>true</enable_wind>\n    <pose>-3.8052516416363673 7.6617459797508367 6.3625258040874684 0 0 0</pose>\n    <link name="link_711">\n      <pose>1.4116443972463273 4.4375282800180393 5.4916760407149576 0 0 0</pose>\n      <inertial>\n        <pose>0 0 0 0 0 0</pose>\n        <mass>1</mass>\n        <inertia>\n          <ixx>1</ixx>\n          <ixy>0</ixy>\n          <ixz>0</ixz>\n          <iyy>1</iyy>\n          <iyz>0</iyz>\n          <izz>1</izz>\n        </inertia>\n      </inertial>\n      <enable_wind>false</enable_wind>\n      <collision name="collision_711">\n        <pose>0 0 0 0 0 0</pose>\n        <geometry>\n          <sphere>\n            <radius>1.9728060896231117</radius>\n          </sphere>\n        </geometry>\n        <surface>\n          <contact>\n            <collide_bitmask>255</collide_bitmask>\n          </contact>\n          <friction>\n            <ode>\n              <mu>1</mu>\n              <mu2>1</mu2>\n              <slip1>0</slip1>\n              <slip2>0</slip2>\n              <fdir1>0 0 0</fdir1>\n            </ode>\n          </friction>\n        </surface>\n      </collision>\n      <visual name="visual_711">\n        <pose>0 0 0 0 0 0</pose>\n        <geometry>\n          <sphere>\n            <radius>1.9728060896231117</radius>\n          </sphere>\n        </geometry>\n        <cast_shadows>true</cast_shadows>\n        <laser_retro>0</laser_retro>\n        <transparency>0</transparency>\n        <visibility_flags>4294967295</visibility_flags>\n        <material>\n          <ambient>0.299065977 0.22807543 0.844659209 1</ambient>\n          <diffuse>0.299065977 0.22807543 0.844659209 1</diffuse>\n          <specular>0 0 0 1</specular>\n          <emissive>0 0 0 1</emissive>\n          <render_order>0</render_order>\n          <lighting>true</lighting>\n          <double_sided>false</double_sided>\n          <shader type="pixel"/>\n        </material>\n      </visual>\n    </link>\n    <link name="link_712">\n      <pose>-7.1779251028716962 4.3912999689978527 2.3650774225360371 0 0 0</pose>\n      <inertial>\n        <pose>0 0 0 0 0 0</pose>\n        <mass>1</mass>\n        <inertia>\n          <ixx>1</ixx>\n          <ixy>0</ixy>\n          <ixz>0</ixz>\n          <iyy>1</iyy>\n          <iyz>0</iyz>\n          <izz>1</izz>\n        </inertia>\n      </inertial>\n      <enable_wind>false</enable_wind>\n      <collision name="collision_712">\n        <pose>0 0 0 0 0 0</pose>\n        <geometry>\n          <box>\n            <size>1.8727981395327664 2.6943632048186421 1.2847037695104842</size>\n          </box>\n        </geometry>\n        <surface>\n          <contact>\n            <collide_bitmask>255</collide_bitmask>\n          </contact>\n          <friction>\n            <ode>\n              <mu>1</mu>\n              <mu2>1</mu2>\n              <slip1>0</slip1>\n              <slip2>0</slip2>\n              <fdir1>0 0 0</fdir1>\n            </ode>\n          </friction>\n        </surface>\n      </collision>\n      <visual name="visual_712">\n        <pose>0 0 0 0 0 0</pose>\n        <geometry>\n          <box>\n            <size>1.8727981395327664 2.6943632048186421 1.2847037695104842</size>\n          </box>\n        </geometry>\n        <cast_shadows>true</cast_shadows>\n        <laser_retro>0</laser_retro>\n        <transparency>0</transparency>\n        <visibility_flags>4294967295</visibility_flags>\n        <material>\n          <ambient>0.305017471 0.323708594 0.307623267 1</ambient>\n          <diffuse>0.305017471 0.323708594 0.307623267 1</diffuse>\n          <specular>0 0 0 1</specular>\n          <emissive>0 0 0 1</emissive>\n          <render_order>0</render_order>\n          <lighting>true</lighting>\n          <double_sided>false</double_sided>\n          <shader type="pixel"/>\n        </material>\n      </visual>\n    </link>\n    <link name="link_713">\n      <pose>-9.3266027375150529 4.3531076734263792 9.4652337739077961 0 0 0</pose>\n      <inertial>\n        <pose>0 0 0 0 0 0</pose>\n        <mass>1</mass>\n        <inertia>\n          <ixx>1</ixx>\n          <ixy>0</ixy>\n          <ixz>0</ixz>\n          <iyy>1</iyy>\n          <iyz>0</iyz>\n          <izz>1</izz>\n        </inertia>\n      </inertial>\n      <enable_wind>false</enable_wind>\n      <collision name="collision_713">\n        <pose>0 0 0 0 0 0</pose>\n        <geometry>\n          <cylinder>\n            <radius>2.8950756739735599</radius>\n            <length>1.9296073102647937</length>\n          </cylinder>\n        </geometry>\n        <surface>\n          <contact>\n            <collide_bitmask>255</collide_bitmask>\n          </contact>\n          <friction>\n            <ode>\n              <mu>1</mu>\n              <mu2>1</mu2>\n              <slip1>0</slip1>\n              <slip2>0</slip2>\n              <fdir1>0 0 0</fdir1>\n            </ode>\n          </friction>\n        </surface>\n      </collision>\n      <visual name="visual_713">\n        <pose>0 0 0 0 0 0</pose>\n        <geometry>\n          <cylinder>\n            <radius>2.8950756739735599</radius>\n            <length>1.9296073102647937</length>\n          </cylinder>\n        </geometry>\n        <cast_shadows>true</cast_shadows>\n        <laser_retro>0</laser_retro>\n        <transparency>0</transparency>\n        <visibility_flags>4294967295</visibility_flags>\n        <material>\n          <ambient>0.359315604 0.645720959 0.213440731 1</ambient>\n          <diffuse>0.359315604 0.645720959 0.213440731 1</diffuse>\n          <specular>0 0 0 1</specular>\n          <emissive>0 0 0 1</emissive>\n          <render_order>0</render_order>\n          <lighting>true</lighting>\n          <double_sided>false</double_sided>\n          <shader type="pixel"/>\n        </material>\n      </visual>\n    </link>\n    <joint name="joint_474" type="ball">\n      <pose>0 0 0 0 0 0</pose>\n      <parent>link_712</parent>\n      <child>link_711</child>\n      <axis>\n        <xyz>0.51744615012869011 0.59818143970729776 0.61190558659543348</xyz>\n        <limit>\n          <lower>-inf</lower>\n          <upper>inf</upper>\n          <effort>inf</effort>\n          <velocity>7.1210494181187887</velocity>\n          <stiffness>100000000</stiffness>\n          <dissipation>1</dissipation>\n        </limit>\n        <dynamics>\n          <spring_reference>0</spring_reference>\n          <spring_stiffness>493102</spring_stiffness>\n          <damping>0</damping>\n          <friction>0</friction>\n        </dynamics>\n      </axis>\n      <axis2>\n        <xyz>0.31771035544242837 0.53451922843758226 0.78316621765442462</xyz>\n        <limit>\n          <lower>-inf</lower>\n          <upper>inf</upper>\n          <effort>inf</effort>\n          <velocity>7.9034959608406838</velocity>\n          <stiffness>100000000</stiffness>\n          <dissipation>1</dissipation>\n        </limit>\n        <dynamics>\n          <spring_reference>0</spring_reference>\n          <spring_stiffness>0</spring_stiffness>\n          <damping>0</damping>\n          <friction>0</friction>\n        </dynamics>\n      </axis2>\n    </joint>\n    <joint name="joint_475" type="universal">\n      <pose>0 0 0 0 0 0</pose>\n      <parent>link_713</parent>\n      <child>link_712</child>\n      <axis>\n        <xyz>0.21274092322359092 0.31918570445631866 0.92350516276667238</xyz>\n        <limit>\n          <lower>-inf</lower>\n          <upper>inf</upper>\n          <effort>inf</effort>\n          <velocity>6.4741912077814607</velocity>\n          <stiffness>100000000</stiffness>\n          <dissipation>1</dissipation>\n        </limit>\n        <dynamics>\n          <spring_reference>0</spring_reference>\n          <spring_stiffness>0</spring_stiffness>\n          <damping>0</damping>\n          <friction>0</friction>\n        </dynamics>\n      </axis>\n      <axis2>\n        <xyz>0.38086305030699474 0.43408837867693173 0.81640101445826507</xyz>\n        <limit>\n          <lower>-inf</lower>\n          <upper>inf</upper>\n          <effort>inf</effort>\n          <velocity>9.368054611920563</velocity>\n          <stiffness>100000000</stiffness>\n          <dissipation>1</dissipation>\n        </limit>\n        <dynamics>\n          <spring_reference>0</spring_reference>\n          <spring_stiffness>0</spring_stiffness>\n          <damping>0</damping>\n          <friction>0</friction>\n        </dynamics>\n      </axis2>\n    </joint>\n  </model>\n</sdf>\n"[0m[1;31m[0m
gz sim server: ./dart/dynamics/SphereShape.cpp:68: void dart::dynamics::SphereShape::setRadius(double): Assertion `radius > 0.0' failed.
Stack trace (most recent call last):
#31   Object "/lib/x86_64-linux-gnu/libruby-3.0.so.3.0", at 0x78a1a423ec61, in rb_yield
#30   Object "/lib/x86_64-linux-gnu/libruby-3.0.so.3.0", at 0x78a1a423a30c, in rb_vm_exec
#29   Object "/lib/x86_64-linux-gnu/libruby-3.0.so.3.0", at 0x78a1a4234c96, in 
#28   Object "/lib/x86_64-linux-gnu/libruby-3.0.so.3.0", at 0x78a1a4231fc5, in 
#27   Object "/lib/x86_64-linux-gnu/libruby-3.0.so.3.0", at 0x78a1a422fc34, in 
#26   Object "/usr/lib/x86_64-linux-gnu/ruby/3.0.0/fiddle.so", at 0x78a1a438044b, in 
#25   Object "/lib/x86_64-linux-gnu/libruby-3.0.so.3.0", at 0x78a1a41fd088, in rb_nogvl
#24   Object "/usr/lib/x86_64-linux-gnu/ruby/3.0.0/fiddle.so", at 0x78a1a437fd6b, in 
#23   Object "/lib/x86_64-linux-gnu/libffi.so.8", at 0x78a1a3e37492, in 
#22   Object "/lib/x86_64-linux-gnu/libffi.so.8", at 0x78a1a3e3ae2d, in 
#21   Object "/usr/lib/x86_64-linux-gnu/libgz-sim8-gz.so.8.6.0", at 0x78a1a3aa7605, in runServer
#20   Object "/lib/x86_64-linux-gnu/libgz-sim8.so.8", at 0x78a19e53d485, in 
#19   Object "/lib/x86_64-linux-gnu/libgz-sim8.so.8", at 0x78a19e54d8a2, in gz::sim::v8::SimulationRunner::Run(unsigned long)
#18   Object "/lib/x86_64-linux-gnu/libgz-sim8.so.8", at 0x78a19e54ce60, in gz::sim::v8::SimulationRunner::Step(gz::sim::v8::UpdateInfo const&)
#17   Object "/lib/x86_64-linux-gnu/libgz-sim8.so.8", at 0x78a19e54c0a2, in gz::sim::v8::SimulationRunner::UpdateSystems()
#16   Object "/usr/lib/x86_64-linux-gnu/gz-sim-8/plugins/libgz-sim-physics-system.so", at 0x78a19591f585, in gz::sim::v8::systems::Physics::Update(gz::sim::v8::UpdateInfo const&, gz::sim::v8::EntityComponentManager&)
#15   Object "/usr/lib/x86_64-linux-gnu/gz-sim-8/plugins/libgz-sim-physics-system.so", at 0x78a19591f4b2, in gz::sim::v8::systems::PhysicsPrivate::CreatePhysicsEntities(gz::sim::v8::EntityComponentManager const&, bool)
#14   Object "/usr/lib/x86_64-linux-gnu/gz-sim-8/plugins/libgz-sim-physics-system.so", at 0x78a195919544, in gz::sim::v8::systems::PhysicsPrivate::CreateModelEntities(gz::sim::v8::EntityComponentManager const&, bool)
#13   Object "/usr/lib/x86_64-linux-gnu/gz-sim-8/plugins/libgz-sim-physics-system.so", at 0x78a195998f06, in 
#12   Object "/usr/lib/x86_64-linux-gnu/gz-physics-7/engine-plugins/libgz-physics-dartsim-plugin.so", at 0x78a15dff1fb3, in virtual thunk to gz::physics::dartsim::SDFFeatures::ConstructSdfModel(gz::physics::Identity const&, sdf::v14::Model const&)
#11   Object "/usr/lib/x86_64-linux-gnu/gz-physics-7/engine-plugins/libgz-physics-dartsim-plugin.so", at 0x78a15dff13fa, in gz::physics::dartsim::SDFFeatures::ConstructSdfModelImpl(unsigned long, sdf::v14::Model const&)
#10   Object "/usr/lib/x86_64-linux-gnu/gz-physics-7/engine-plugins/libgz-physics-dartsim-plugin.so", at 0x78a15dfed384, in gz::physics::dartsim::SDFFeatures::FindOrConstructLink(std::shared_ptr<dart::dynamics::Skeleton> const&, gz::physics::Identity const&, sdf::v14::Model const&, std::__cxx11::basic_string<char, std::char_traits<char>, std::allocator<char> > const&)
#9    Object "/usr/lib/x86_64-linux-gnu/gz-physics-7/engine-plugins/libgz-physics-dartsim-plugin.so", at 0x78a15dfecdc4, in gz::physics::dartsim::SDFFeatures::ConstructSdfLink(gz::physics::Identity const&, sdf::v14::Link const&)
#8    Object "/usr/lib/x86_64-linux-gnu/gz-physics-7/engine-plugins/libgz-physics-dartsim-plugin.so", at 0x78a15dff3a6e, in gz::physics::dartsim::SDFFeatures::ConstructSdfCollision(gz::physics::Identity const&, sdf::v14::Collision const&)
#7    Object "/usr/lib/x86_64-linux-gnu/gz-physics-7/engine-plugins/libgz-physics-dartsim-plugin.so", at 0x78a15dff32e6, in 
#6    Object "/lib/x86_64-linux-gnu/libdart.so.6.13", at 0x78a15db1b16f, in dart::dynamics::SphereShape::SphereShape(double)
#5    Object "/lib/x86_64-linux-gnu/libdart.so.6.13", at 0x78a15db199a2, in dart::dynamics::SphereShape::setRadius(double)
#4    Object "/lib/x86_64-linux-gnu/libc.so.6", at 0x78a1a3c39e95, in __assert_fail
#3    Object "/lib/x86_64-linux-gnu/libc.so.6", at 0x78a1a3c2871a, in 
#2    Object "/lib/x86_64-linux-gnu/libc.so.6", at 0x78a1a3c287f2, in abort
#1    Object "/lib/x86_64-linux-gnu/libc.so.6", at 0x78a1a3c42475, in raise
#0    Object "/lib/x86_64-linux-gnu/libc.so.6", at 0x78a1a3c969fc, in pthread_kill
Aborted (Signal sent by tkill() 470013 1000)
