Warning: Ignoring XDG_SESSION_TYPE=wayland on Gnome. Use QT_QPA_PLATFORM=wayland to run on Wayland anyway.
[1;31m[Err] [UserCommands.cc:1145] [0m[1;31mError Code [0m[1;31m19[0m[1;31m: [0m[1;31mMsg: [0m[1;31mA link named front_right_flipper has invalid inertia.[0m[1;31m[0m
[1;31m[Err] [UserCommands.cc:1145] [0m[1;31mError Code [0m[1;31m30[0m[1;31m: [0m[1;31mMsg: [0m[1;31mError parsing XML from string: Error=XML_ERROR_PARSING_TEXT ErrorID=8 (0x8) Line number=1[0m[1;31m[0m
[1;31m[Err] [UserCommands.cc:1145] [0m[1;31mError Code [0m[1;31m30[0m[1;31m: [0m[1;31mMsg: [0m[1;31mUnable to read SDF string: b"<sdf version="1.11">\n  <model name="model">\n    <static>true</static>\n    <self_collide>true</self_collide>\n    <allow_auto_disable>true</allow_auto_disable>\n    <enable_wind>false</enable_wind>\n    <pose>-4.7480824553105609 9.3426045483254541 4.2307236818144105 0 0 0</pose>\n    <link name="link_468">\n      <pose>9.3065874189041224 -0.16133641176527291 0.94886094870233029 0 0 0</pose>\n      <inertial>\n        <pose>0 0 0 0 0 0</pose>\n        <mass>1</mass>\n        <inertia>\n          <ixx>1</ixx>\n          <ixy>0</ixy>\n          <ixz>0</ixz>\n          <iyy>1</iyy>\n          <iyz>0</iyz>\n          <izz>1</izz>\n        </inertia>\n      </inertial>\n      <enable_wind>false</enable_wind>\n      <collision name="collision_468">\n        <pose>0 0 0 0 0 0</pose>\n        <geometry>\n          <sphere>\n            <radius>1.2179192801065022</radius>\n          </sphere>\n        </geometry>\n        <surface>\n          <contact>\n            <collide_bitmask>255</collide_bitmask>\n          </contact>\n          <friction>\n            <ode>\n              <mu>1</mu>\n              <mu2>1</mu2>\n              <slip1>0</slip1>\n              <slip2>0</slip2>\n              <fdir1>0 0 0</fdir1>\n            </ode>\n          </friction>\n        </surface>\n      </collision>\n      <visual name="visual_468">\n        <pose>0 0 0 0 0 0</pose>\n        <geometry>\n          <sphere>\n            <radius>1.2179192801065022</radius>\n          </sphere>\n        </geometry>\n        <cast_shadows>true</cast_shadows>\n        <laser_retro>0</laser_retro>\n        <transparency>0</transparency>\n        <visibility_flags>4294967295</visibility_flags>\n        <material>\n          <ambient>0.325586617 0.151721433 0.545202613 1</ambient>\n          <diffuse>0.325586617 0.151721433 0.545202613 1</diffuse>\n          <specular>0 0 0 1</specular>\n          <emissive>0 0 0 1</emissive>\n          <render_order>0</render_order>\n          <lighting>true</lighting>\n          <double_sided>false</double_sided>\n          <shader type="pixel"/>\n        </material>\n      </visual>\n    </link>\n    <link name="link_469">\n      <pose>-9.4159774650552457 -5.2112469883139561 3.0708377442250256 0 0 0</pose>\n      <inertial>\n        <pose>0 0 0 0 0 0</pose>\n        <mass>1</mass>\n        <inertia>\n          <ixx>1</ixx>\n          <ixy>0</ixy>\n          <ixz>0</ixz>\n          <iyy>1</iyy>\n          <iyz>0</iyz>\n          <izz>1</izz>\n        </inertia>\n      </inertial>\n      <enable_wind>false</enable_wind>\n      <collision name="collision_469">\n        <pose>0 0 0 0 0 0</pose>\n        <geometry>\n          <capsule>\n            <radius>2.7933618302826253</radius>\n            <length>1.5845226994037698</length>\n          </capsule>\n        </geometry>\n        <surface>\n          <contact>\n            <collide_bitmask>255</collide_bitmask>\n          </contact>\n          <friction>\n            <ode>\n              <mu>1</mu>\n              <mu2>1</mu2>\n              <slip1>0</slip1>\n              <slip2>0</slip2>\n              <fdir1>0 0 0</fdir1>\n            </ode>\n          </friction>\n        </surface>\n      </collision>\n      <visual name="visual_469">\n        <pose>0 0 0 0 0 0</pose>\n        <geometry>\n          <capsule>\n            <radius>2.7933618302826253</radius>\n            <length>1.5845226994037698</length>\n          </capsule>\n        </geometry>\n        <cast_shadows>true</cast_shadows>\n        <laser_retro>0</laser_retro>\n        <transparency>0</transparency>\n        <visibility_flags>4294967295</visibility_flags>\n        <material>\n          <ambient>0.464231312 0.424654543 0.431198567 1</ambient>\n          <diffuse>0.464231312 0.424654543 0.431198567 1</diffuse>\n          <specular>0 0 0 1</specular>\n          <emissive>0 0 0 1</emissive>\n          <render_order>0</render_order>\n          <lighting>true</lighting>\n          <double_sided>false</double_sided>\n          <shader type="pixel"/>\n        </material>\n      </visual>\n    </link>\n    <link name="link_470">\n      <pose>-4.8568596316937747 2.4798395175287791 3.3114914783065164 0 0 0</pose>\n      <inertial>\n        <pose>0 0 0 0 0 0</pose>\n        <mass>1</mass>\n        <inertia>\n          <ixx>1</ixx>\n          <ixy>0</ixy>\n          <ixz>0</ixz>\n          <iyy>1</iyy>\n          <iyz>0</iyz>\n          <izz>1</izz>\n        </inertia>\n      </inertial>\n      <enable_wind>Tq8Ei</enable_wind>\n      <collision name="collision_470">\n        <pose>0 0 0 0 0 0</pose>\n        <geometry>\n          <box>\n            <size>1.7007584113206216 2.8469008230761776 1.8971147529171577</size>\n          </box>\n        </geometry>\n        <surface>\n          <contact>\n            <collide_bitmask>255</collide_bitmask>\n          </contact>\n          <friction>\n            <ode>\n              <mu>1</mu>\n              <mu2>1</mu2>\n              <slip1>0</slip1>\n              <slip2>0</slip2>\n              <fdir1>0 0 0</fdir1>\n            </ode>\n          </friction>\n        </surface>\n      </collision>\n      <visual name="visual_470">\n        <pose>0 0 0 0 0 0</pose>\n        <geometry>\n          <box>\n            <size>1.7007584113206216 2.8469008230761776 1.8971147529171577</size>\n          </box>\n        </geometry>\n        <cast_shadows>true</cast_shadows>\n        <laser_retro>0</laser_retro>\n        <transparency>0</transparency>\n        <visibility_flags>4294967295</visibility_flags>\n        <material>\n          <ambient>0.896028996 0.721857786 0.936269104 1</ambient>\n          <diffuse>0.896028996 0.721857786 0.936269104 1</diffuse>\n          <specular>0 0 0 1</specular>\n          <emissive>0 0 0 1</emissive>\n          <render_order>0</render_order>\n          <lighting>true</lighting>\n          <double_sided>false</double_sided>\n          <shader type="pixel"/>\n        </material>\n      </visual>\n    </link>\n    <joint name="joint_312" type="revolute">\n      <pose>0 0 0 0 0 0</pose>\n      <parent>link_468</parent>\n      <child>link_470</child>\n      <axis>\n        <xyz>0.45089273717919015 0.75072231269981204 0.48281647525090049</xyz>\n        <limit>\n          <lower>-inf</lower>\n          <upper>inf</upper>\n          <effort>inf</effort>\n          <velocity>8.6145881696656836</velocity>\n          <stiffness>100000000</stiffness>\n          <dissipation>1</dissipation>\n        </limit>\n        <dynamics>\n          <spring_reference>0</spring_reference>\n          <spring_stiffness>0</spring_stiffness>\n          <damping>0</damping>\n          <friction>0</friction>\n        </dynamics>\n      </axis>\n      <axis2>\n        <xyz>0.64450798809521415 0.69348539716587132 0.32200536827691678</xyz>\n        <limit>\n          <lower>-inf</lower>\n          <upper>inf</upper>\n          <effort>inf</effort>\n          <velocity>1.0146477247467955</velocity>\n          <stiffness>100000000</stiffness>\n          <dissipation>1</dissipation>\n        </limit>\n        <dynamics>\n          <spring_reference>0</spring_reference>\n          <spring_stiffness>0</spring_stiffness>\n          <damping>0</damping>\n          <friction>0</friction>\n        </dynamics>\n      </axis2>\n    </joint>\n    <joint name="joint_313" type="gearbox">\n      <pose>0 0 0 0 0 0</pose>\n      <parent>link_468</parent>\n      <child>link_469</child>\n      <axis>\n        <xyz>0.62270635632050675 0.44850402843307241 0.64115593288789252</xyz>\n        <limit>\n          <lower>-inf</lower>\n          <upper>inf</upper>\n          <effort>inf</effort>\n          <velocity>0.46564929799794097</velocity>\n          <stiffness>100000000</stiffness>\n          <dissipation>1</dissipation>\n        </limit>\n        <dynamics>\n          <spring_reference>0</spring_reference>\n          <spring_stiffness>0</spring_stiffness>\n          <damping>0</damping>\n          <friction>0</friction>\n        </dynamics>\n      </axis>\n      <axis2>\n        <xyz>0.66931279590574 0.35912173042117496 0.65042444909162356</xyz>\n        <limit>\n          <lower>-inf</lower>\n          <upper>inf</upper>\n          <effort>inf</effort>\n          <velocity>7.7672655563866222</velocity>\n          <stiffness>100000000</stiffness>\n          <dissipation>1</dissipation>\n        </limit>\n        <dynamics>\n          <spring_reference>0</spring_reference>\n          <spring_stiffness>0</spring_stiffness>\n          <damping>0</damping>\n          <friction>0</friction>\n        </dynamics>\n      </axis2>\n    </joint>\n  </model>\n</sdf>\n"[0m[1;31m[0m
[1;36mDbg[0m ODE Heightfield AABB: min = {-128, -128, -0.05} max = {128, 128, 50}
gz sim server: ./dart/constraint/JointConstraint.cpp:207: virtual void dart::constraint::JointConstraint::update(): Assertion `positionLowerLimits[i] <= positionUpperLimits[i]' failed.
Stack trace (most recent call last):
#31   Object "/lib/x86_64-linux-gnu/libruby-3.0.so.3.0", at 0x78e710634c96, in 
#30   Object "/lib/x86_64-linux-gnu/libruby-3.0.so.3.0", at 0x78e710631fc5, in 
#29   Object "/lib/x86_64-linux-gnu/libruby-3.0.so.3.0", at 0x78e71062fc34, in 
#28   Object "/lib/x86_64-linux-gnu/libruby-3.0.so.3.0", at 0x78e71057ba4e, in 
#27   Object "/lib/x86_64-linux-gnu/libruby-3.0.so.3.0", at 0x78e7104a69ac, in rb_protect
#26   Object "/lib/x86_64-linux-gnu/libruby-3.0.so.3.0", at 0x78e71063ec61, in rb_yield
#25   Object "/lib/x86_64-linux-gnu/libruby-3.0.so.3.0", at 0x78e71063a30c, in rb_vm_exec
#24   Object "/lib/x86_64-linux-gnu/libruby-3.0.so.3.0", at 0x78e710634c96, in 
#23   Object "/lib/x86_64-linux-gnu/libruby-3.0.so.3.0", at 0x78e710631fc5, in 
#22   Object "/lib/x86_64-linux-gnu/libruby-3.0.so.3.0", at 0x78e71062fc34, in 
#21   Object "/usr/lib/x86_64-linux-gnu/ruby/3.0.0/fiddle.so", at 0x78e71027544b, in 
#20   Object "/lib/x86_64-linux-gnu/libruby-3.0.so.3.0", at 0x78e7105fd088, in rb_nogvl
#19   Object "/usr/lib/x86_64-linux-gnu/ruby/3.0.0/fiddle.so", at 0x78e710274d6b, in 
#18   Object "/lib/x86_64-linux-gnu/libffi.so.8", at 0x78e710266492, in 
#17   Object "/lib/x86_64-linux-gnu/libffi.so.8", at 0x78e710269e2d, in 
#16   Object "/usr/lib/x86_64-linux-gnu/libgz-sim8-gz.so.8.6.0", at 0x78e70f5d4605, in runServer
#15   Object "/lib/x86_64-linux-gnu/libgz-sim8.so.8", at 0x78e70a93d485, in 
#14   Object "/lib/x86_64-linux-gnu/libgz-sim8.so.8", at 0x78e70a94d8a2, in gz::sim::v8::SimulationRunner::Run(unsigned long)
#13   Object "/lib/x86_64-linux-gnu/libgz-sim8.so.8", at 0x78e70a94ce60, in gz::sim::v8::SimulationRunner::Step(gz::sim::v8::UpdateInfo const&)
#12   Object "/lib/x86_64-linux-gnu/libgz-sim8.so.8", at 0x78e70a94c0a2, in gz::sim::v8::SimulationRunner::UpdateSystems()
#11   Object "/usr/lib/x86_64-linux-gnu/gz-sim-8/plugins/libgz-sim-physics-system.so", at 0x78e701d1f5b6, in gz::sim::v8::systems::Physics::Update(gz::sim::v8::UpdateInfo const&, gz::sim::v8::EntityComponentManager&)
#10   Object "/usr/lib/x86_64-linux-gnu/gz-sim-8/plugins/libgz-sim-physics-system.so", at 0x78e701d1fc31, in gz::sim::v8::systems::PhysicsPrivate::Step(std::chrono::duration<long, std::ratio<1l, 1000000000l> > const&)
#9    Object "/usr/lib/x86_64-linux-gnu/gz-physics-7/engine-plugins/libgz-physics-dartsim-plugin.so", at 0x78e6cac0900b, in gz::physics::dartsim::SimulationFeatures::WorldForwardStep(gz::physics::Identity const&, gz::physics::SpecifyData<gz::physics::RequireData<gz::physics::WorldPoses>, gz::physics::ExpectData<gz::physics::ChangedWorldPoses, gz::physics::Contacts, gz::physics::JointPositions> >&, gz::physics::CompositeData&, gz::physics::ExpectData<gz::physics::ApplyExternalForceTorques, gz::physics::ApplyGeneralizedForces, gz::physics::VelocityControlCommands, gz::physics::ServoControlCommands, std::chrono::duration<long, std::ratio<1l, 1000000000l> > > const&)
#8    Object "/lib/x86_64-linux-gnu/libdart.so.6.13", at 0x78e6ca7936d3, in dart::simulation::World::step(bool)
#7    Object "/lib/x86_64-linux-gnu/libdart.so.6.13", at 0x78e6ca778ca5, in dart::constraint::ConstraintSolver::solve()
#6    Object "/lib/x86_64-linux-gnu/libdart.so.6.13", at 0x78e6ca777d33, in dart::constraint::ConstraintSolver::updateConstraints()
#5    Object "/lib/x86_64-linux-gnu/libdart.so.6.13", at 0x78e6ca786256, in dart::constraint::JointConstraint::update()
#4    Object "/lib/x86_64-linux-gnu/libc.so.6", at 0x78e710039e95, in __assert_fail
#3    Object "/lib/x86_64-linux-gnu/libc.so.6", at 0x78e71002871a, in 
#2    Object "/lib/x86_64-linux-gnu/libc.so.6", at 0x78e7100287f2, in abort
#1    Object "/lib/x86_64-linux-gnu/libc.so.6", at 0x78e710042475, in raise
#0    Object "/lib/x86_64-linux-gnu/libc.so.6", at 0x78e7100969fc, in pthread_kill
Aborted (Signal sent by tkill() 469354 1000)
