<sdf version='1.11'>
  <world name='world_0'>
    <gravity>0 0 -9.8066499999999994</gravity>
    <magnetic_field>5.5644999999999998e-06 2.2875799999999999e-05 -4.2388400000000002e-05</magnetic_field>
    <wind>
      <linear_velocity>0 7 8</linear_velocity>
    </wind>
    <physics default='false' type='ode'>
      <max_step_size>0.001</max_step_size>
      <real_time_factor>1</real_time_factor>
      <max_contacts>20</max_contacts>
    </physics>
    <model name='model_0'>
      <static>false</static>
      <self_collide>true</self_collide>
      <allow_auto_disable>true</allow_auto_disable>
      <enable_wind>true</enable_wind>
      <pose>5.1693003482068782 2.5483238558992909 9.9675994579515983 0 0 0</pose>
      <link name='link_0'>
        <pose>-5.8634470174872488 -8.8492132090231035 0.85623220690957291 0 0 0</pose>
        <inertial>
          <pose>0 0 0 0 0 0</pose>
          <mass>1</mass>
          <inertia>
            <ixx>1</ixx>
            <ixy>0</ixy>
            <ixz>0</ixz>
            <iyy>1</iyy>
            <iyz>0</iyz>
            <izz>1</izz>
          </inertia>
        </inertial>
        <enable_wind>false</enable_wind>
        <collision name='collision_0'>
          <pose>0 0 0 0 0 0</pose>
          <geometry>
            <capsule>
              <radius>2.1624745348537431</radius>
              <length>2.3341286426499535</length>
            </capsule>
          </geometry>
          <surface>
            <contact>
              <collide_bitmask>255</collide_bitmask>
            </contact>
            <friction>
              <ode>
                <mu>1</mu>
                <mu2>1</mu2>
                <slip1>0</slip1>
                <slip2>0</slip2>
                <fdir1>0 0 0</fdir1>
              </ode>
            </friction>
          </surface>
        </collision>
        <visual name='visual_0'>
          <pose>0 0 0 0 0 0</pose>
          <geometry>
            <capsule>
              <radius>2.1624745348537431</radius>
              <length>2.3341286426499535</length>
            </capsule>
          </geometry>
          <cast_shadows>true</cast_shadows>
          <laser_retro>0</laser_retro>
          <transparency>0</transparency>
          <visibility_flags>4294967295</visibility_flags>
          <material>
            <ambient>0.126252428 0.51676023 0.590813816 1</ambient>
            <diffuse>0.126252428 0.51676023 0.590813816 1</diffuse>
            <specular>0 0 0 1</specular>
            <emissive>0 0 0 1</emissive>
            <render_order>0</render_order>
            <lighting>true</lighting>
            <double_sided>false</double_sided>
            <shader type='pixel'/>
          </material>
        </visual>
      </link>
      <link name='link_1'>
        <pose>-6.0367234599534925 -3.9013751458092401 6.2250899599472245 0 0 0</pose>
        <inertial>
          <pose>0 0 0 0 0 0</pose>
          <mass>1</mass>
          <inertia>
            <ixx>1</ixx>
            <ixy>0</ixy>
            <ixz>0</ixz>
            <iyy>1</iyy>
            <iyz>0</iyz>
            <izz>1</izz>
          </inertia>
        </inertial>
        <enable_wind>false</enable_wind>
        <collision name='collision_1'>
          <pose>0 0 0 0 0 0</pose>
          <geometry>
            <cylinder>
              <radius>1.1432077729556824</radius>
              <length>2.3604322370406106</length>
            </cylinder>
          </geometry>
          <surface>
            <contact>
              <collide_bitmask>255</collide_bitmask>
            </contact>
            <friction>
              <ode>
                <mu>1</mu>
                <mu2>1</mu2>
                <slip1>0</slip1>
                <slip2>0</slip2>
                <fdir1>0 0 0</fdir1>
              </ode>
            </friction>
          </surface>
        </collision>
        <visual name='visual_1'>
          <pose>0 0 0 0 0 0</pose>
          <geometry>
            <cylinder>
              <radius>1.1432077729556824</radius>
              <length>2.3604322370406106</length>
            </cylinder>
          </geometry>
          <cast_shadows>true</cast_shadows>
          <laser_retro>0</laser_retro>
          <transparency>0</transparency>
          <visibility_flags>4294967295</visibility_flags>
          <material>
            <ambient>0.857561529 0.468259364 0.978208125 1</ambient>
            <diffuse>0.857561529 0.468259364 0.978208125 1</diffuse>
            <specular>0 0 0 1</specular>
            <emissive>0 0 0 1</emissive>
            <render_order>0</render_order>
            <lighting>true</lighting>
            <double_sided>false</double_sided>
            <shader type='pixel'/>
          </material>
        </visual>
      </link>
      <link name='link_2'>
        <pose>3.3395352105933007 -6.1394568520489141 5.6635149278006374 0 0 0</pose>
        <inertial>
          <pose>0 0 0 0 0 0</pose>
          <mass>1</mass>
          <inertia>
            <ixx>1</ixx>
            <ixy>0</ixy>
            <ixz>0</ixz>
            <iyy>1</iyy>
            <iyz>0</iyz>
            <izz>1</izz>
          </inertia>
        </inertial>
        <enable_wind>false</enable_wind>
        <collision name='collision_2'>
          <pose>0 0 0 0 0 0</pose>
          <geometry>
            <cylinder>
              <radius>2.7195044653571676</radius>
              <length>2.8099977085838335</length>
            </cylinder>
          </geometry>
          <surface>
            <contact>
              <collide_bitmask>255</collide_bitmask>
            </contact>
            <friction>
              <ode>
                <mu>1</mu>
                <mu2>1</mu2>
                <slip1>0</slip1>
                <slip2>0</slip2>
                <fdir1>0 0 0</fdir1>
              </ode>
            </friction>
          </surface>
        </collision>
        <visual name='visual_2'>
          <pose>0 0 0 0 0 0</pose>
          <geometry>
            <cylinder>
              <radius>2.7195044653571676</radius>
              <length>2.8099977085838335</length>
            </cylinder>
          </geometry>
          <cast_shadows>true</cast_shadows>
          <laser_retro>0</laser_retro>
          <transparency>0</transparency>
          <visibility_flags>4294967295</visibility_flags>
          <material>
            <ambient>0.0419732407 0.98512584 0.661702514 1</ambient>
            <diffuse>0.0419732407 0.98512584 0.661702514 1</diffuse>
            <specular>0 0 0 1</specular>
            <emissive>0 0 0 1</emissive>
            <render_order>0</render_order>
            <lighting>true</lighting>
            <double_sided>false</double_sided>
            <shader type='pixel'/>
          </material>
        </visual>
      </link>
      <joint name='joint_0' type='ball'>
        <pose>0 0 0 0 0 0</pose>
        <parent>link_1</parent>
        <child>link_2</child>
        <axis>
          <xyz>0.92457824067738337 0.26031905498567759 0.27818890430295434</xyz>
          <limit>
            <lower>-inf</lower>
            <upper>inf</upper>
            <effort>inf</effort>
            <velocity>1.3620375290305065</velocity>
            <stiffness>100000000</stiffness>
            <dissipation>1</dissipation>
          </limit>
          <dynamics>
            <spring_reference>0</spring_reference>
            <spring_stiffness>0</spring_stiffness>
            <damping>0</damping>
            <friction>0</friction>
          </dynamics>
        </axis>
        <axis2>
          <xyz>0.22553633581513366 0.89206700906264635 0.39159904566930148</xyz>
          <limit>
            <lower>-inf</lower>
            <upper>inf</upper>
            <effort>inf</effort>
            <velocity>4.4461058154636763</velocity>
            <stiffness>100000000</stiffness>
            <dissipation>1</dissipation>
          </limit>
          <dynamics>
            <spring_reference>0</spring_reference>
            <spring_stiffness>0</spring_stiffness>
            <damping>0</damping>
            <friction>0</friction>
          </dynamics>
        </axis2>
      </joint>
      <joint name='joint_1' type='continuous'>
        <pose>0 0 0 0 0 0</pose>
        <parent>link_0</parent>
        <child>link_1</child>
        <axis>
          <xyz>0.28944443379309764 0.18599163555083284 0.93895102707825995</xyz>
          <limit>
            <lower>-inf</lower>
            <upper>inf</upper>
            <effort>inf</effort>
            <velocity>3.5693301860591733</velocity>
            <stiffness>100000000</stiffness>
            <dissipation>1</dissipation>
          </limit>
          <dynamics>
            <spring_reference>0</spring_reference>
            <spring_stiffness>0</spring_stiffness>
            <damping>0</damping>
            <friction>0</friction>
          </dynamics>
        </axis>
        <axis2>
          <xyz>0.21116718671273249 0.1099573198812059 0.97124549268471361</xyz>
          <limit>
            <lower>-inf</lower>
            <upper>inf</upper>
            <effort>inf</effort>
            <velocity>4.6183770818646339</velocity>
            <stiffness>100000000</stiffness>
            <dissipation>1</dissipation>
          </limit>
          <dynamics>
            <spring_reference>0</spring_reference>
            <spring_stiffness>0</spring_stiffness>
            <damping>0</damping>
            <friction>0</friction>
          </dynamics>
        </axis2>
      </joint>
      <plugin name='gz::sim::systems::PythonSystemLoader' filename='gz-sim-python-system-loader-system'>
        <module_name>driver</module_name>
        <force>100</force>
      </plugin>
    </model>
    <model name='model_1'>
      <static>false</static>
      <self_collide>true</self_collide>
      <allow_auto_disable>true</allow_auto_disable>
      <enable_wind>true</enable_wind>
      <pose>-6.7986870405984279 0.91068719818141375 4.1393706076663763 0 0 0</pose>
      <link name='link_3'>
        <pose>-1.8395125450715746 -7.1894275947829929 4.639722341479688 0 0 0</pose>
        <inertial>
          <pose>0 0 0 0 0 0</pose>
          <mass>1</mass>
          <inertia>
            <ixx>1</ixx>
            <ixy>0</ixy>
            <ixz>0</ixz>
            <iyy>1</iyy>
            <iyz>0</iyz>
            <izz>1</izz>
          </inertia>
        </inertial>
        <enable_wind>false</enable_wind>
        <collision name='collision_3'>
          <pose>0 0 0 0 0 0</pose>
          <geometry>
            <cylinder>
              <radius>1.9383386040612565</radius>
              <length>2.7925592090643168</length>
            </cylinder>
          </geometry>
          <surface>
            <contact>
              <collide_bitmask>255</collide_bitmask>
            </contact>
            <friction>
              <ode>
                <mu>1</mu>
                <mu2>1</mu2>
                <slip1>0</slip1>
                <slip2>0</slip2>
                <fdir1>0 0 0</fdir1>
              </ode>
            </friction>
          </surface>
        </collision>
        <visual name='visual_3'>
          <pose>0 0 0 0 0 0</pose>
          <geometry>
            <cylinder>
              <radius>1.9383386040612565</radius>
              <length>2.7925592090643168</length>
            </cylinder>
          </geometry>
          <cast_shadows>true</cast_shadows>
          <laser_retro>0</laser_retro>
          <transparency>0</transparency>
          <visibility_flags>4294967295</visibility_flags>
          <material>
            <ambient>0.392457426 0.808268428 0.0679671615 1</ambient>
            <diffuse>0.392457426 0.808268428 0.0679671615 1</diffuse>
            <specular>0 0 0 1</specular>
            <emissive>0 0 0 1</emissive>
            <render_order>0</render_order>
            <lighting>true</lighting>
            <double_sided>false</double_sided>
            <shader type='pixel'/>
          </material>
        </visual>
      </link>
      <link name='link_4'>
        <pose>-6.1784275098585422 1.8731126475448168 7.8685745329873225 0 0 0</pose>
        <inertial>
          <pose>0 0 0 0 0 0</pose>
          <mass>1</mass>
          <inertia>
            <ixx>1</ixx>
            <ixy>0</ixy>
            <ixz>0</ixz>
            <iyy>1</iyy>
            <iyz>0</iyz>
            <izz>1</izz>
          </inertia>
        </inertial>
        <enable_wind>false</enable_wind>
        <collision name='collision_4'>
          <pose>0 0 0 0 0 0</pose>
          <geometry>
            <capsule>
              <radius>1.2125518210527211</radius>
              <length>1.0063030216823603</length>
            </capsule>
          </geometry>
          <surface>
            <contact>
              <collide_bitmask>255</collide_bitmask>
            </contact>
            <friction>
              <ode>
                <mu>1</mu>
                <mu2>1</mu2>
                <slip1>0</slip1>
                <slip2>0</slip2>
                <fdir1>0 0 0</fdir1>
              </ode>
            </friction>
          </surface>
        </collision>
        <visual name='visual_4'>
          <pose>0 0 0 0 0 0</pose>
          <geometry>
            <capsule>
              <radius>1.2125518210527211</radius>
              <length>1.0063030216823603</length>
            </capsule>
          </geometry>
          <cast_shadows>true</cast_shadows>
          <laser_retro>0</laser_retro>
          <transparency>0</transparency>
          <visibility_flags>4294967295</visibility_flags>
          <material>
            <ambient>0.0167415217 0.958585262 0.403738528 1</ambient>
            <diffuse>0.0167415217 0.958585262 0.403738528 1</diffuse>
            <specular>0 0 0 1</specular>
            <emissive>0 0 0 1</emissive>
            <render_order>0</render_order>
            <lighting>true</lighting>
            <double_sided>false</double_sided>
            <shader type='pixel'/>
          </material>
        </visual>
      </link>
      <link name='link_5'>
        <pose>-2.8950809427168096 9.5028523351765664 6.774055671041018 0 0 0</pose>
        <inertial>
          <pose>0 0 0 0 0 0</pose>
          <mass>1</mass>
          <inertia>
            <ixx>1</ixx>
            <ixy>0</ixy>
            <ixz>0</ixz>
            <iyy>1</iyy>
            <iyz>0</iyz>
            <izz>1</izz>
          </inertia>
        </inertial>
        <enable_wind>false</enable_wind>
        <collision name='collision_5'>
          <pose>0 0 0 0 0 0</pose>
          <geometry>
            <cylinder>
              <radius>1.8616544629320859</radius>
              <length>1.4615280216415731</length>
            </cylinder>
          </geometry>
          <surface>
            <contact>
              <collide_bitmask>255</collide_bitmask>
            </contact>
            <friction>
              <ode>
                <mu>1</mu>
                <mu2>1</mu2>
                <slip1>0</slip1>
                <slip2>0</slip2>
                <fdir1>0 0 0</fdir1>
              </ode>
            </friction>
          </surface>
        </collision>
        <visual name='visual_5'>
          <pose>0 0 0 0 0 0</pose>
          <geometry>
            <cylinder>
              <radius>1.8616544629320859</radius>
              <length>1.4615280216415731</length>
            </cylinder>
          </geometry>
          <cast_shadows>true</cast_shadows>
          <laser_retro>0</laser_retro>
          <transparency>0</transparency>
          <visibility_flags>4294967295</visibility_flags>
          <material>
            <ambient>0.973186731 0.998858392 0.395507634 1</ambient>
            <diffuse>0.973186731 0.998858392 0.395507634 1</diffuse>
            <specular>0 0 0 1</specular>
            <emissive>0 0 0 1</emissive>
            <render_order>0</render_order>
            <lighting>true</lighting>
            <double_sided>false</double_sided>
            <shader type='pixel'/>
          </material>
        </visual>
      </link>
      <joint name='joint_2' type='universal'>
        <pose>0 0 0 0 0 0</pose>
        <parent>link_5</parent>
        <child>link_4</child>
        <axis>
          <xyz>0.67975834961828319 0.17176132492378604 0.71304041497284953</xyz>
          <limit>
            <lower>-inf</lower>
            <upper>inf</upper>
            <effort>inf</effort>
            <velocity>4.9695018849946537</velocity>
            <stiffness>100000000</stiffness>
            <dissipation>1</dissipation>
          </limit>
          <dynamics>
            <spring_reference>0</spring_reference>
            <spring_stiffness>0</spring_stiffness>
            <damping>0</damping>
            <friction>0</friction>
          </dynamics>
        </axis>
        <axis2>
          <xyz>0.8511255161199619 0.29813669722378439 0.43208779846001416</xyz>
          <limit>
            <lower>-inf</lower>
            <upper>inf</upper>
            <effort>inf</effort>
            <velocity>0.94076390081674677</velocity>
            <stiffness>100000000</stiffness>
            <dissipation>1</dissipation>
          </limit>
          <dynamics>
            <spring_reference>0</spring_reference>
            <spring_stiffness>0</spring_stiffness>
            <damping>0</damping>
            <friction>0</friction>
          </dynamics>
        </axis2>
      </joint>
      <joint name='joint_3' type='revolute'>
        <pose>0 0 0 0 0 0</pose>
        <parent>link_3</parent>
        <child>link_5</child>
        <axis>
          <xyz>0.4500693376251772 0.57600994132276384 0.68238562325636687</xyz>
          <limit>
            <lower>-inf</lower>
            <upper>inf</upper>
            <effort>inf</effort>
            <velocity>0.16954037143473988</velocity>
            <stiffness>100000000</stiffness>
            <dissipation>1</dissipation>
          </limit>
          <dynamics>
            <spring_reference>0</spring_reference>
            <spring_stiffness>0</spring_stiffness>
            <damping>0</damping>
            <friction>0</friction>
          </dynamics>
        </axis>
        <axis2>
          <xyz>0.53632051291003668 0.019822612370314002 0.84378158990981278</xyz>
          <limit>
            <lower>-inf</lower>
            <upper>inf</upper>
            <effort>inf</effort>
            <velocity>4.5137514198918316</velocity>
            <stiffness>100000000</stiffness>
            <dissipation>1</dissipation>
          </limit>
          <dynamics>
            <spring_reference>0</spring_reference>
            <spring_stiffness>0</spring_stiffness>
            <damping>0</damping>
            <friction>0</friction>
          </dynamics>
        </axis2>
      </joint>
      <plugin name='gz::sim::systems::PythonSystemLoader' filename='gz-sim-python-system-loader-system'>
        <module_name>driver</module_name>
        <force>100</force>
      </plugin>
    </model>
    <model name='ground_model'>
      <static>true</static>
      <self_collide>false</self_collide>
      <allow_auto_disable>true</allow_auto_disable>
      <enable_wind>false</enable_wind>
      <pose>0 0 0 0 0 0</pose>
      <link name='ground_link'>
        <pose>0 0 0 0 0 0</pose>
        <inertial>
          <pose>0 0 0 0 0 0</pose>
          <mass>1</mass>
          <inertia>
            <ixx>1</ixx>
            <ixy>0</ixy>
            <ixz>0</ixz>
            <iyy>1</iyy>
            <iyz>0</iyz>
            <izz>1</izz>
          </inertia>
        </inertial>
        <enable_wind>false</enable_wind>
        <collision name='ground_collision'>
          <pose>0 0 0 0 0 0</pose>
          <geometry>
            <plane>
              <normal>0 0 1</normal>
              <size>100 100</size>
            </plane>
          </geometry>
          <surface>
            <contact>
              <collide_bitmask>255</collide_bitmask>
            </contact>
            <friction>
              <ode>
                <mu>1</mu>
                <mu2>1</mu2>
                <slip1>0</slip1>
                <slip2>0</slip2>
                <fdir1>0 0 0</fdir1>
              </ode>
            </friction>
          </surface>
        </collision>
      </link>
    </model>
    <model name='ceiling_model'>
      <static>true</static>
      <self_collide>false</self_collide>
      <allow_auto_disable>true</allow_auto_disable>
      <enable_wind>false</enable_wind>
      <pose>0 0 100 0 0 0</pose>
      <link name='ceiling_link'>
        <pose>0 0 0 0 0 0</pose>
        <inertial>
          <pose>0 0 0 0 0 0</pose>
          <mass>1</mass>
          <inertia>
            <ixx>1</ixx>
            <ixy>0</ixy>
            <ixz>0</ixz>
            <iyy>1</iyy>
            <iyz>0</iyz>
            <izz>1</izz>
          </inertia>
        </inertial>
        <enable_wind>false</enable_wind>
        <collision name='ceiling_collision'>
          <pose>0 0 0 0 0 0</pose>
          <geometry>
            <box>
              <size>102 102 3</size>
            </box>
          </geometry>
          <surface>
            <contact>
              <collide_bitmask>255</collide_bitmask>
            </contact>
            <friction>
              <ode>
                <mu>1</mu>
                <mu2>1</mu2>
                <slip1>0</slip1>
                <slip2>0</slip2>
                <fdir1>0 0 0</fdir1>
              </ode>
            </friction>
          </surface>
        </collision>
        <visual name='ceiling_visual'>
          <pose>0 0 0 0 0 0</pose>
          <geometry>
            <box>
              <size>102 102 3</size>
            </box>
          </geometry>
          <cast_shadows>true</cast_shadows>
          <laser_retro>0</laser_retro>
          <transparency>0</transparency>
          <visibility_flags>4294967295</visibility_flags>
          <material>
            <ambient>0.200000003 0.200000003 0.200000003 0.200000003</ambient>
            <diffuse>0.200000003 0.200000003 0.200000003 0.200000003</diffuse>
            <specular>0 0 0 1</specular>
            <emissive>0 0 0 1</emissive>
            <render_order>0</render_order>
            <lighting>true</lighting>
            <double_sided>false</double_sided>
            <shader type='pixel'/>
          </material>
        </visual>
      </link>
    </model>
    <model name='west_model'>
      <static>true</static>
      <self_collide>false</self_collide>
      <allow_auto_disable>true</allow_auto_disable>
      <enable_wind>false</enable_wind>
      <pose>0 50 50 0 0 0</pose>
      <link name='west_link'>
        <pose>0 0 0 0 0 0</pose>
        <inertial>
          <pose>0 0 0 0 0 0</pose>
          <mass>1</mass>
          <inertia>
            <ixx>1</ixx>
            <ixy>0</ixy>
            <ixz>0</ixz>
            <iyy>1</iyy>
            <iyz>0</iyz>
            <izz>1</izz>
          </inertia>
        </inertial>
        <enable_wind>false</enable_wind>
        <collision name='west_collision'>
          <pose>0 0 0 0 0 0</pose>
          <geometry>
            <box>
              <size>102 3 102</size>
            </box>
          </geometry>
          <surface>
            <contact>
              <collide_bitmask>255</collide_bitmask>
            </contact>
            <friction>
              <ode>
                <mu>1</mu>
                <mu2>1</mu2>
                <slip1>0</slip1>
                <slip2>0</slip2>
                <fdir1>0 0 0</fdir1>
              </ode>
            </friction>
          </surface>
        </collision>
        <visual name='west_visual'>
          <pose>0 0 0 0 0 0</pose>
          <geometry>
            <box>
              <size>102 3 102</size>
            </box>
          </geometry>
          <cast_shadows>true</cast_shadows>
          <laser_retro>0</laser_retro>
          <transparency>0</transparency>
          <visibility_flags>4294967295</visibility_flags>
          <material>
            <ambient>0.200000003 0.200000003 0.200000003 0.200000003</ambient>
            <diffuse>0.200000003 0.200000003 0.200000003 0.200000003</diffuse>
            <specular>0 0 0 1</specular>
            <emissive>0 0 0 1</emissive>
            <render_order>0</render_order>
            <lighting>true</lighting>
            <double_sided>false</double_sided>
            <shader type='pixel'/>
          </material>
        </visual>
      </link>
    </model>
    <model name='east_model'>
      <static>true</static>
      <self_collide>false</self_collide>
      <allow_auto_disable>true</allow_auto_disable>
      <enable_wind>false</enable_wind>
      <pose>0 -50 50 0 0 0</pose>
      <link name='east_link'>
        <pose>0 0 0 0 0 0</pose>
        <inertial>
          <pose>0 0 0 0 0 0</pose>
          <mass>1</mass>
          <inertia>
            <ixx>1</ixx>
            <ixy>0</ixy>
            <ixz>0</ixz>
            <iyy>1</iyy>
            <iyz>0</iyz>
            <izz>1</izz>
          </inertia>
        </inertial>
        <enable_wind>false</enable_wind>
        <collision name='east_collision'>
          <pose>0 0 0 0 0 0</pose>
          <geometry>
            <box>
              <size>102 3 102</size>
            </box>
          </geometry>
          <surface>
            <contact>
              <collide_bitmask>255</collide_bitmask>
            </contact>
            <friction>
              <ode>
                <mu>1</mu>
                <mu2>1</mu2>
                <slip1>0</slip1>
                <slip2>0</slip2>
                <fdir1>0 0 0</fdir1>
              </ode>
            </friction>
          </surface>
        </collision>
        <visual name='east_visual'>
          <pose>0 0 0 0 0 0</pose>
          <geometry>
            <box>
              <size>102 3 102</size>
            </box>
          </geometry>
          <cast_shadows>true</cast_shadows>
          <laser_retro>0</laser_retro>
          <transparency>0</transparency>
          <visibility_flags>4294967295</visibility_flags>
          <material>
            <ambient>0.200000003 0.200000003 0.200000003 0.200000003</ambient>
            <diffuse>0.200000003 0.200000003 0.200000003 0.200000003</diffuse>
            <specular>0 0 0 1</specular>
            <emissive>0 0 0 1</emissive>
            <render_order>0</render_order>
            <lighting>true</lighting>
            <double_sided>false</double_sided>
            <shader type='pixel'/>
          </material>
        </visual>
      </link>
    </model>
    <model name='north_model'>
      <static>true</static>
      <self_collide>false</self_collide>
      <allow_auto_disable>true</allow_auto_disable>
      <enable_wind>false</enable_wind>
      <pose>50 0 50 0 0 0</pose>
      <link name='north_link'>
        <pose>0 0 0 0 0 0</pose>
        <inertial>
          <pose>0 0 0 0 0 0</pose>
          <mass>1</mass>
          <inertia>
            <ixx>1</ixx>
            <ixy>0</ixy>
            <ixz>0</ixz>
            <iyy>1</iyy>
            <iyz>0</iyz>
            <izz>1</izz>
          </inertia>
        </inertial>
        <enable_wind>false</enable_wind>
        <collision name='north_collision'>
          <pose>0 0 0 0 0 0</pose>
          <geometry>
            <box>
              <size>3 102 102</size>
            </box>
          </geometry>
          <surface>
            <contact>
              <collide_bitmask>255</collide_bitmask>
            </contact>
            <friction>
              <ode>
                <mu>1</mu>
                <mu2>1</mu2>
                <slip1>0</slip1>
                <slip2>0</slip2>
                <fdir1>0 0 0</fdir1>
              </ode>
            </friction>
          </surface>
        </collision>
        <visual name='north_visual'>
          <pose>0 0 0 0 0 0</pose>
          <geometry>
            <box>
              <size>3 102 102</size>
            </box>
          </geometry>
          <cast_shadows>true</cast_shadows>
          <laser_retro>0</laser_retro>
          <transparency>0</transparency>
          <visibility_flags>4294967295</visibility_flags>
          <material>
            <ambient>0.200000003 0.200000003 0.200000003 0.200000003</ambient>
            <diffuse>0.200000003 0.200000003 0.200000003 0.200000003</diffuse>
            <specular>0 0 0 1</specular>
            <emissive>0 0 0 1</emissive>
            <render_order>0</render_order>
            <lighting>true</lighting>
            <double_sided>false</double_sided>
            <shader type='pixel'/>
          </material>
        </visual>
      </link>
    </model>
    <model name='south_model'>
      <static>true</static>
      <self_collide>false</self_collide>
      <allow_auto_disable>true</allow_auto_disable>
      <enable_wind>false</enable_wind>
      <pose>-50 0 50 0 0 0</pose>
      <link name='south_link'>
        <pose>0 0 0 0 0 0</pose>
        <inertial>
          <pose>0 0 0 0 0 0</pose>
          <mass>1</mass>
          <inertia>
            <ixx>1</ixx>
            <ixy>0</ixy>
            <ixz>0</ixz>
            <iyy>1</iyy>
            <iyz>0</iyz>
            <izz>1</izz>
          </inertia>
        </inertial>
        <enable_wind>false</enable_wind>
        <collision name='south_collision'>
          <pose>0 0 0 0 0 0</pose>
          <geometry>
            <box>
              <size>3 102 102</size>
            </box>
          </geometry>
          <surface>
            <contact>
              <collide_bitmask>255</collide_bitmask>
            </contact>
            <friction>
              <ode>
                <mu>1</mu>
                <mu2>1</mu2>
                <slip1>0</slip1>
                <slip2>0</slip2>
                <fdir1>0 0 0</fdir1>
              </ode>
            </friction>
          </surface>
        </collision>
        <visual name='south_visual'>
          <pose>0 0 0 0 0 0</pose>
          <geometry>
            <box>
              <size>3 102 102</size>
            </box>
          </geometry>
          <cast_shadows>true</cast_shadows>
          <laser_retro>0</laser_retro>
          <transparency>0</transparency>
          <visibility_flags>4294967295</visibility_flags>
          <material>
            <ambient>0.200000003 0.200000003 0.200000003 0.200000003</ambient>
            <diffuse>0.200000003 0.200000003 0.200000003 0.200000003</diffuse>
            <specular>0 0 0 1</specular>
            <emissive>0 0 0 1</emissive>
            <render_order>0</render_order>
            <lighting>true</lighting>
            <double_sided>false</double_sided>
            <shader type='pixel'/>
          </material>
        </visual>
      </link>
    </model>
    <atmosphere type='adiabatic'>
      <temperature>288.14999999999998</temperature>
      <pressure>101325</pressure>
      <temperature_gradient>-0.0064999999999999997</temperature_gradient>
    </atmosphere>
    <scene>
      <ambient>0.400000006 0.400000006 0.400000006 1</ambient>
      <background>0.699999988 0.699999988 0.699999988 1</background>
      <grid>true</grid>
      <origin_visual>true</origin_visual>
      <shadows>true</shadows>
    </scene>
  </world>
</sdf>
