Warning: Ignoring XDG_SESSION_TYPE=wayland on Gnome. Use QT_QPA_PLATFORM=wayland to run on Wayland anyway.
[1;31m[Err] [UserCommands.cc:1145] [0m[1;31mError Code [0m[1;31m30[0m[1;31m: [0m[1;31mMsg: [0m[1;31mError parsing XML from string: Error=XML_ERROR_PARSING_TEXT ErrorID=8 (0x8) Line number=1[0m[1;31m[0m
[1;31m[Err] [UserCommands.cc:1145] [0m[1;31mError Code [0m[1;31m30[0m[1;31m: [0m[1;31mMsg: [0m[1;31mUnable to read SDF string: b"<sdf version="1.11">\n  <model name="model">\n    <static>true</static>\n    <self_collide>true</self_collide>\n    <allow_auto_disable>true</allow_auto_disable>\n    <enable_wind>false</enable_wind>\n    <pose>0.42984490068707082 -1.0737695862819034 1.5264407961475868 0 0 0</pose>\n    <link name="link_3219">\n      <pose>3.0297126628287714 2.5993799821173162 5.6867532402441343 0 0 0</pose>\n      <inertial>\n        <pose>0 0 0 0 0 0</pose>\n        <mass>1</mass>\n        <inertia>\n          <ixx>1</ixx>\n          <ixy>0</ixy>\n          <ixz>0</ixz>\n          <iyy>1</iyy>\n          <iyz>0</iyz>\n          <izz>1</izz>\n        </inertia>\n      </inertial>\n      <enable_wind>false</enable_wind>\n      <collision name="collision_3219">\n        <pose>0 0 0 0 0 0</pose>\n        <geometry>\n          <capsule>\n            <radius>2.139773440333177</radius>\n            <length>2.2717414373106548</length>\n          </capsule>\n        </geometry>\n        <surface>\n          <contact>\n            <collide_bitmask>255</collide_bitmask>\n          </contact>\n          <friction>\n            <ode>\n              <mu>1</mu>\n              <mu2>1</mu2>\n              <slip1>0</slip1>\n              <slip2>0</slip2>\n              <fdir1>0 0 0</fdir1>\n            </ode>\n          </friction>\n        </surface>\n      </collision>\n      <visual name="visual_3219">\n        <pose>0 0 0 0 0 0</pose>\n        <geometry>\n          <capsule>\n            <radius>2.139773440333177</radius>\n            <length>2.2717414373106548</length>\n          </capsule>\n        </geometry>\n        <cast_shadows>true</cast_shadows>\n        <laser_retro>0</laser_retro>\n        <transparency>0</transparency>\n        <visibility_flags>4294967295</visibility_flags>\n        <material>\n          <ambient>0.709159732 0.532067418 0.801800311 1</ambient>\n          <diffuse>0.709159732 0.532067418 0.801800311 1</diffuse>\n          <specular>0 0 0 1</specular>\n          <emissive>0 0 0 1</emissive>\n          <render_order>0</render_order>\n          <lighting>true</lighting>\n          <double_sided>false</double_sided>\n          <shader type="pixel"/>\n        </material>\n      </visual>\n    </link>\n    <link name="link_3220">\n      <pose>4.0192639706123874 -5.2594091748813732 6.9352733974742078 0 0 0</pose>\n      <inertial>\n        <pose>0 0 0 0 0 0</pose>\n        <mass>1</mass>\n        <inertia>\n          <ixx>1</ixx>\n          <ixy>0</ixy>\n          <ixz>0</ixz>\n          <iyy>1</iyy>\n          <iyz>0</iyz>\n          <izz>1</izz>\n        </inertia>\n      </inertial>\n      <enable_wind>false</enable_wind>\n      <collision name="collision_3220">\n        <pose>0 0 0 0 0 0</pose>\n        <geometry>\n          <sphere>\n            <radius>2.4652390200143075</radius>\n          </sphere>\n        </geometry>\n        <surface>\n          <contact>\n            <collide_bitmask>255</collide_bitmask>\n          </contact>\n          <friction>\n            <ode>\n              <mu>1</mu>\n              <mu2>1</mu2>\n              <slip1>0</slip1>\n              <slip2>0</slip2>\n              <fdir1>0 0 0</fdir1>\n            </ode>\n          </friction>\n        </surface>\n      </collision>\n      <visual name="visual_3220">\n        <pose>0 0 0 0 0 0</pose>\n        <geometry>\n          <sphere>\n            <radius>2.4652390200143075</radius>\n          </sphere>\n        </geometry>\n        <cast_shadows>true</cast_shadows>\n        <laser_retro>0</laser_retro>\n        <transparency>0</transparency>\n        <visibility_flags>4294967295</visibility_flags>\n        <material>\n          <ambient>0.997849405 0.948769212 0.830705464 1</ambient>\n          <diffuse>0.997849405 0.948769212 0.830705464 1</diffuse>\n          <specular>0 0 0 1</specular>\n          <emissive>0 0 0 1</emissive>\n          <render_order>0</render_order>\n          <lighting>true</lighting>\n          <double_sided>false</double_sided>\n          <shader type="pixel"/>\n        </material>\n      </visual>\n    </link>\n    <link name="link_3221">\n      <pose>-4.2596511633144534 -8.3034630691983775 8.9219855290668804 0 0 0</pose>\n      <inertial>\n        <pose>0 0 0 0 0 0</pose>\n        <mass>1</mass>\n        <inertia>\n          <ixx>1</ixx>\n          <ixy>0</ixy>\n          <ixz>0</ixz>\n          <iyy>1</iyy>\n          <iyz>0</iyz>\n          <izz>1</izz>\n        </inertia>\n      </inertial>\n      <enable_wind>false</enable_wind>\n      <collision name="collision_3221">\n        <pose>0 0 0 0 0 0</pose>\n        <geometry>\n          <cylinder>\n            <radius>1.7318462873022435</radius>\n            <length>2.8127969059442544</length>\n          </cylinder>\n        </geometry>\n        <surface>\n          <contact>\n            <collide_bitmask>255</collide_bitmask>\n          </contact>\n          <friction>\n            <ode>\n              <mu>1</mu>\n              <mu2>1</mu2>\n              <slip1>0</slip1>\n              <slip2>0</slip2>\n              <fdir1>0 0 0</fdir1>\n            </ode>\n          </friction>\n        </surface>\n      </collision>\n      <visual name="visual_3221">\n        <pose>0 0 0 0 0 0</pose>\n        <geometry>\n          <cylinder>\n            <radius>1.7318462873022435</radius>\n            <length>2.8127969059442544</length>\n          </cylinder>\n        </geometry>\n        <cast_shadows>true</cast_shadows>\n        <laser_retro>0</laser_retro>\n        <transparency>0</transparency>\n        <visibility_flags>4294967295</visibility_flags>\n        <material>\n          <ambient>0.660402358 0.894145429 0.130888045 1</ambient>\n          <diffuse>-6818.680010457 -0.894145429 584865.885442874 0.1</diffuse>\n          <specular>0 0 0 1</specular>\n          <emissive>0 0 0 1</emissive>\n          <render_order>0</render_order>\n          <lighting>true</lighting>\n          <double_sided>false</double_sided>\n          <shader type="pixel"/>\n        </material>\n      </visual>\n    </link>\n    <joint name="joint_2146" type="screw">\n      <pose>0 0 0 0 0 0</pose>\n      <parent>link_3219</parent>\n      <child>link_3220</child>\n      <axis>\n        <xyz>0.18015298243523342 0.2957348857621428 0.93812887188431793</xyz>\n        <limit>\n          <lower>-inf</lower>\n          <upper>inf</upper>\n          <effort>inf</effort>\n          <velocity>1.5248822215801683</velocity>\n          <stiffness>100000000</stiffness>\n          <dissipation>1</dissipation>\n        </limit>\n        <dynamics>\n          <spring_reference>0</spring_reference>\n          <spring_stiffness>0</spring_stiffness>\n          <damping>0</damping>\n          <friction>0</friction>\n        </dynamics>\n      </axis>\n      <axis2>\n        <xyz>0.69038122829698367 0.053620288324559187 0.72145590599505072</xyz>\n        <limit>\n          <lower>-inf</lower>\n          <upper>inf</upper>\n          <effort>inf</effort>\n          <velocity>1.5415914225128002</velocity>\n          <stiffness>100000000</stiffness>\n          <dissipation>1</dissipation>\n        </limit>\n        <dynamics>\n          <spring_reference>0</spring_reference>\n          <spring_stiffness>0</spring_stiffness>\n          <damping>0</damping>\n          <friction>0</friction>\n        </dynamics>\n      </axis2>\n      <thread_pitch>-6.2831853071795862</thread_pitch>\n    </joint>\n    <joint name="joint_2147" type="gearbox">\n      <pose>0 0 0 0 0 0</pose>\n      <parent>link_3220</parent>\n      <child>link_3219</child>\n      <axis>\n        <xyz>0.3837247724738721 0.70577095905230858 0.59551880939921598</xyz>\n        <limit>\n          <lower>-inf</lower>\n          <upper>inf</upper>\n          <effort>inf</effort>\n          <velocity>6.1226009142620539</velocity>\n          <stiffness>100000000</stiffness>\n          <dissipation>1</dissipation>\n        </limit>\n        <dynamics>\n          <spring_reference>0</spring_reference>\n          <spring_stiffness>0</spring_stiffness>\n          <damping>0</damping>\n          <friction>0</friction>\n        </dynamics>\n      </axis>\n      <axis2>\n        <xyz>0.32204143022655002 0.075221937188155327 0.94373247129856641</xyz>\n        <limit>\n          <lower>-inf</lower>\n          <upper>inf</upper>\n          <effort>inf</effort>\n          <velocity>9.5459035115821624</velocity>\n          <stiffness>100000000</stiffness>\n          <dissipation>1</dissipation>\n        </limit>\n        <dynamics>\n          <spring_reference>0</spring_reference>\n          <spring_stiffness>0</spring_stiffness>\n          <damping>0</damping>\n          <friction>0</friction>\n        </dynamics>\n      </axis2>\n    </joint>\n  </model>\n</sdf>\n"[0m[1;31m[0m
gz sim server: ./dart/dynamics/detail/GenericJoint.hpp:1495: void dart::dynamics::GenericJoint<ConfigSpaceT>::setDampingCoefficient(size_t, double) [with ConfigSpaceT = dart::math::RealVectorSpace<1>; size_t = long unsigned int]: Assertion `d >= 0.0' failed.
Stack trace (most recent call last):
#31   Object "/lib/x86_64-linux-gnu/libruby-3.0.so.3.0", at 0x7bf972a3a30c, in rb_vm_exec
#30   Object "/lib/x86_64-linux-gnu/libruby-3.0.so.3.0", at 0x7bf972a34c96, in 
#29   Object "/lib/x86_64-linux-gnu/libruby-3.0.so.3.0", at 0x7bf972a31fc5, in 
#28   Object "/lib/x86_64-linux-gnu/libruby-3.0.so.3.0", at 0x7bf972a2fc34, in 
#27   Object "/usr/lib/x86_64-linux-gnu/ruby/3.0.0/fiddle.so", at 0x7bf97265444b, in 
#26   Object "/lib/x86_64-linux-gnu/libruby-3.0.so.3.0", at 0x7bf9729fd088, in rb_nogvl
#25   Object "/usr/lib/x86_64-linux-gnu/ruby/3.0.0/fiddle.so", at 0x7bf972653d6b, in 
#24   Object "/lib/x86_64-linux-gnu/libffi.so.8", at 0x7bf9722f6492, in 
#23   Object "/lib/x86_64-linux-gnu/libffi.so.8", at 0x7bf9722f9e2d, in 
#22   Object "/usr/lib/x86_64-linux-gnu/libgz-sim8-gz.so.8.6.0", at 0x7bf9719d4605, in runServer
#21   Object "/lib/x86_64-linux-gnu/libgz-sim8.so.8", at 0x7bf96cd3d485, in 
#20   Object "/lib/x86_64-linux-gnu/libgz-sim8.so.8", at 0x7bf96cd4d8a2, in gz::sim::v8::SimulationRunner::Run(unsigned long)
#19   Object "/lib/x86_64-linux-gnu/libgz-sim8.so.8", at 0x7bf96cd4ce60, in gz::sim::v8::SimulationRunner::Step(gz::sim::v8::UpdateInfo const&)
#18   Object "/lib/x86_64-linux-gnu/libgz-sim8.so.8", at 0x7bf96cd4c0a2, in gz::sim::v8::SimulationRunner::UpdateSystems()
#17   Object "/usr/lib/x86_64-linux-gnu/gz-sim-8/plugins/libgz-sim-physics-system.so", at 0x7bf96411f585, in gz::sim::v8::systems::Physics::Update(gz::sim::v8::UpdateInfo const&, gz::sim::v8::EntityComponentManager&)
#16   Object "/usr/lib/x86_64-linux-gnu/gz-sim-8/plugins/libgz-sim-physics-system.so", at 0x7bf96411f4b2, in gz::sim::v8::systems::PhysicsPrivate::CreatePhysicsEntities(gz::sim::v8::EntityComponentManager const&, bool)
#15   Object "/usr/lib/x86_64-linux-gnu/gz-sim-8/plugins/libgz-sim-physics-system.so", at 0x7bf964119544, in gz::sim::v8::systems::PhysicsPrivate::CreateModelEntities(gz::sim::v8::EntityComponentManager const&, bool)
#14   Object "/usr/lib/x86_64-linux-gnu/gz-sim-8/plugins/libgz-sim-physics-system.so", at 0x7bf964199a1d, in 
#13   Object "/usr/lib/x86_64-linux-gnu/gz-physics-7/engine-plugins/libgz-physics-dartsim-plugin.so", at 0x7bf92cbf1f43, in virtual thunk to gz::physics::dartsim::SDFFeatures::ConstructSdfNestedModel(gz::physics::Identity const&, sdf::v14::Model const&)
#12   Object "/usr/lib/x86_64-linux-gnu/gz-physics-7/engine-plugins/libgz-physics-dartsim-plugin.so", at 0x7bf92cbf1503, in gz::physics::dartsim::SDFFeatures::ConstructSdfModelImpl(unsigned long, sdf::v14::Model const&)
#11   Object "/usr/lib/x86_64-linux-gnu/gz-physics-7/engine-plugins/libgz-physics-dartsim-plugin.so", at 0x7bf92cbf0879, in gz::physics::dartsim::SDFFeatures::ConstructSdfJoint(gz::physics::Identity const&, sdf::v14::Joint const&, dart::dynamics::BodyNode*, dart::dynamics::BodyNode*)
#10   Object "/usr/lib/x86_64-linux-gnu/gz-physics-7/engine-plugins/libgz-physics-dartsim-plugin.so", at 0x7bf92cbe1d38, in dart::dynamics::RevoluteJoint* dart::dynamics::BodyNode::moveTo<dart::dynamics::RevoluteJoint>(dart::dynamics::BodyNode*, dart::dynamics::RevoluteJoint::Properties const&)
#9    Object "/usr/lib/x86_64-linux-gnu/gz-physics-7/engine-plugins/libgz-physics-dartsim-plugin.so", at 0x7bf92cbe1b88, in dart::dynamics::RevoluteJoint* dart::dynamics::Skeleton::moveBodyNodeTree<dart::dynamics::RevoluteJoint>(dart::dynamics::BodyNode*, std::shared_ptr<dart::dynamics::Skeleton> const&, dart::dynamics::BodyNode*, dart::dynamics::RevoluteJoint::Properties const&)
#8    Object "/lib/x86_64-linux-gnu/libdart.so.6.13", at 0x7bf92c6ce97d, in dart::dynamics::RevoluteJoint::RevoluteJoint(dart::dynamics::detail::RevoluteJointProperties const&)
#7    Object "/lib/x86_64-linux-gnu/libdart.so.6.13", at 0x7bf92c6bffe2, in 
#6    Object "/lib/x86_64-linux-gnu/libdart.so.6.13", at 0x7bf92c6af089, in 
#5    Object "/lib/x86_64-linux-gnu/libdart.so.6.13", at 0x7bf92c6b41d3, in 
#4    Object "/lib/x86_64-linux-gnu/libc.so.6", at 0x7bf972439e95, in __assert_fail
#3    Object "/lib/x86_64-linux-gnu/libc.so.6", at 0x7bf97242871a, in 
#2    Object "/lib/x86_64-linux-gnu/libc.so.6", at 0x7bf9724287f2, in abort
#1    Object "/lib/x86_64-linux-gnu/libc.so.6", at 0x7bf972442475, in raise
#0    Object "/lib/x86_64-linux-gnu/libc.so.6", at 0x7bf9724969fc, in pthread_kill
Aborted (Signal sent by tkill() 475521 1000)
